2022-09-29 23:34:11,414 -  nornir.core -     INFO -        run() - Running task 'get_with_pygnmi' with args {'path': ['openconfig-interfaces:interfaces']} on 1 hosts
2022-09-29 23:34:16,502 - nornir.core.task -    ERROR -      start() - Host 'R1': task 'get_with_pygnmi' failed with traceback:
Traceback (most recent call last):
  File "/home/majid/.local/lib/python3.10/site-packages/nornir/core/task.py", line 99, in start
    r = self.task(self, **self.params)
  File "/home/majid/devnet/pyhton_nornir/15.gNMI/15.1.gNMI_get_with_pygnmi.py", line 11, in get_with_pygnmi
    with gNMIclient(
  File "/home/majid/.local/lib/python3.10/site-packages/pygnmi/client.py", line 103, in __enter__
    return self.connect()
  File "/home/majid/.local/lib/python3.10/site-packages/pygnmi/client.py", line 225, in connect
    self.wait_for_connect(timeout)
  File "/home/majid/.local/lib/python3.10/site-packages/pygnmi/client.py", line 237, in wait_for_connect
    grpc.channel_ready_future(self.__channel).result(timeout=timeout)
  File "/home/majid/.local/lib/python3.10/site-packages/grpc/_utilities.py", line 139, in result
    self._block(timeout)
  File "/home/majid/.local/lib/python3.10/site-packages/grpc/_utilities.py", line 85, in _block
    raise grpc.FutureTimeoutError()
grpc.FutureTimeoutError

2022-09-29 22:13:49,897 -  nornir.core -     INFO -        run() - Running task 'get_with_pygnmi' with args {'path': ['openconfig-interfaces:interfaces']} on 1 hosts
2022-09-29 22:14:17,321 -  nornir.core -     INFO -        run() - Running task 'get_with_pygnmi' with args {'path': ['openconfig-interfaces:interfaces']} on 1 hosts
2022-09-29 22:14:17,530 - nornir.core.task -    ERROR -      start() - Host 'R1': task 'get_with_pygnmi' failed with traceback:
Traceback (most recent call last):
  File "/home/majid/.local/lib/python3.10/site-packages/nornir/core/task.py", line 99, in start
    r = self.task(self, **self.params)
  File "/home/majid/15.gNMI/15.1.gNMI_get_with_pygnmi.py", line 18, in get_with_pygnmi
    rprint (response.result)
AttributeError: 'dict' object has no attribute 'result'

2022-09-29 22:14:38,064 -  nornir.core -     INFO -        run() - Running task 'get_with_pygnmi' with args {'path': ['openconfig-interfaces:interfaces']} on 1 hosts
2022-09-29 22:14:38,273 - nornir.core.task -    ERROR -      start() - Host 'R1': task 'get_with_pygnmi' failed with traceback:
Traceback (most recent call last):
  File "/home/majid/.local/lib/python3.10/site-packages/nornir/core/task.py", line 99, in start
    r = self.task(self, **self.params)
  File "/home/majid/15.gNMI/15.1.gNMI_get_with_pygnmi.py", line 18, in get_with_pygnmi
    rprint (response.response)
AttributeError: 'dict' object has no attribute 'response'

2022-09-29 22:16:42,972 -  nornir.core -     INFO -        run() - Running task 'get_with_pygnmi' with args {'path': ['openconfig-interfaces:interfaces']} on 1 hosts
2022-09-29 22:16:43,183 - nornir.core.task -    ERROR -      start() - Host 'R1': task 'get_with_pygnmi' failed with traceback:
Traceback (most recent call last):
  File "/home/majid/.local/lib/python3.10/site-packages/nornir/core/task.py", line 99, in start
    r = self.task(self, **self.params)
  File "/home/majid/15.gNMI/15.1.gNMI_get_with_pygnmi.py", line 18, in get_with_pygnmi
    rprint (response.contecnt())
AttributeError: 'dict' object has no attribute 'contecnt'

2022-09-29 22:18:25,223 -  nornir.core -     INFO -        run() - Running task 'get_with_pygnmi' with args {'path': ['openconfig-interfaces:interfaces']} on 1 hosts
2022-09-29 22:18:57,758 -  nornir.core -     INFO -        run() - Running task 'get_with_pygnmi' with args {'path': ['openconfig-interfaces:interfaces']} on 1 hosts
2022-09-29 22:18:57,971 - nornir.core.task -    ERROR -      start() - Host 'R1': task 'get_with_pygnmi' failed with traceback:
Traceback (most recent call last):
  File "/home/majid/.local/lib/python3.10/site-packages/nornir/core/task.py", line 99, in start
    r = self.task(self, **self.params)
  File "/home/majid/15.gNMI/15.1.gNMI_get_with_pygnmi.py", line 19, in get_with_pygnmi
    rprint(response.json())
AttributeError: 'dict' object has no attribute 'json'

2022-09-29 22:19:14,274 -  nornir.core -     INFO -        run() - Running task 'get_with_pygnmi' with args {'path': ['openconfig-interfaces:interfaces']} on 1 hosts
2022-09-29 22:19:14,482 - nornir.core.task -    ERROR -      start() - Host 'R1': task 'get_with_pygnmi' failed with traceback:
Traceback (most recent call last):
  File "/home/majid/.local/lib/python3.10/site-packages/nornir/core/task.py", line 99, in start
    r = self.task(self, **self.params)
  File "/home/majid/15.gNMI/15.1.gNMI_get_with_pygnmi.py", line 19, in get_with_pygnmi
    rprint(response.json())
AttributeError: 'dict' object has no attribute 'json'

2022-09-29 22:20:14,515 -  nornir.core -     INFO -        run() - Running task 'get_with_pygnmi' with args {'path': ['openconfig-interfaces:interfaces']} on 1 hosts
2022-09-29 22:20:24,517 -  nornir.core -     INFO -        run() - Running task 'get_with_pygnmi' with args {'path': ['openconfig-interfaces:interfaces']} on 1 hosts
2022-09-29 22:20:34,079 -  nornir.core -     INFO -        run() - Running task 'get_with_pygnmi' with args {'path': ['openconfig-interfaces:interfaces']} on 1 hosts
2022-09-29 22:21:25,873 -  nornir.core -     INFO -        run() - Running task 'get_with_pygnmi' with args {'path': ['openconfig-interfaces:interfaces']} on 1 hosts
2022-09-29 22:21:57,153 -  nornir.core -     INFO -        run() - Running task 'get_with_pygnmi' with args {'path': ['openconfig-interfaces:interfaces']} on 1 hosts
2022-09-29 22:22:18,663 -  nornir.core -     INFO -        run() - Running task 'get_with_pygnmi' with args {'path': ['openconfig-interfaces:interfaces']} on 1 hosts
2022-09-29 22:22:51,116 -  nornir.core -     INFO -        run() - Running task 'get_with_pygnmi' with args {'path': ['openconfig-interfaces:interfaces']} on 1 hosts
2022-09-29 22:22:51,330 - nornir.core.task -    ERROR -      start() - Host 'R1': task 'get_with_pygnmi' failed with traceback:
Traceback (most recent call last):
  File "/home/majid/.local/lib/python3.10/site-packages/nornir/core/task.py", line 99, in start
    r = self.task(self, **self.params)
  File "/home/majid/15.gNMI/15.1.gNMI_get_with_pygnmi.py", line 18, in get_with_pygnmi
    rprint(respone.result)
NameError: name 'respone' is not defined

2022-09-29 22:23:02,899 -  nornir.core -     INFO -        run() - Running task 'get_with_pygnmi' with args {'path': ['openconfig-interfaces:interfaces']} on 1 hosts
2022-09-29 22:23:03,112 - nornir.core.task -    ERROR -      start() - Host 'R1': task 'get_with_pygnmi' failed with traceback:
Traceback (most recent call last):
  File "/home/majid/.local/lib/python3.10/site-packages/nornir/core/task.py", line 99, in start
    r = self.task(self, **self.params)
  File "/home/majid/15.gNMI/15.1.gNMI_get_with_pygnmi.py", line 18, in get_with_pygnmi
    rprint(respone.response)
NameError: name 'respone' is not defined

2022-09-29 22:23:16,032 -  nornir.core -     INFO -        run() - Running task 'get_with_pygnmi' with args {'path': ['openconfig-interfaces:interfaces']} on 1 hosts
2022-09-29 22:23:16,246 - nornir.core.task -    ERROR -      start() - Host 'R1': task 'get_with_pygnmi' failed with traceback:
Traceback (most recent call last):
  File "/home/majid/.local/lib/python3.10/site-packages/nornir/core/task.py", line 99, in start
    r = self.task(self, **self.params)
  File "/home/majid/15.gNMI/15.1.gNMI_get_with_pygnmi.py", line 18, in get_with_pygnmi
    rprint(respone)
NameError: name 'respone' is not defined

2022-09-29 22:23:35,732 -  nornir.core -     INFO -        run() - Running task 'get_with_pygnmi' with args {'path': ['openconfig-interfaces:interfaces']} on 1 hosts
2022-09-29 22:23:35,941 - nornir.core.task -    ERROR -      start() - Host 'R1': task 'get_with_pygnmi' failed with traceback:
Traceback (most recent call last):
  File "/home/majid/.local/lib/python3.10/site-packages/nornir/core/task.py", line 99, in start
    r = self.task(self, **self.params)
  File "/home/majid/15.gNMI/15.1.gNMI_get_with_pygnmi.py", line 18, in get_with_pygnmi
    print(respone)
NameError: name 'respone' is not defined

2022-09-29 22:26:08,285 -  nornir.core -     INFO -        run() - Running task 'get_with_pygnmi' with args {'path': ['openconfig-interfaces:interfaces/interface[name=Ethernet1]/config/enabled']} on 1 hosts
2022-09-29 22:26:08,493 - nornir.core.task -    ERROR -      start() - Host 'R1': task 'get_with_pygnmi' failed with traceback:
Traceback (most recent call last):
  File "/home/majid/.local/lib/python3.10/site-packages/nornir/core/task.py", line 99, in start
    r = self.task(self, **self.params)
  File "/home/majid/15.gNMI/15.1.gNMI_get_with_pygnmi.py", line 18, in get_with_pygnmi
    print(respone)
NameError: name 'respone' is not defined

2022-09-29 22:26:55,138 -  nornir.core -     INFO -        run() - Running task 'get_with_pygnmi' with args {'path': ['openconfig-interfaces:interfaces']} on 1 hosts
2022-09-29 22:26:55,351 - nornir.core.task -    ERROR -      start() - Host 'R1': task 'get_with_pygnmi' failed with traceback:
Traceback (most recent call last):
  File "/home/majid/.local/lib/python3.10/site-packages/nornir/core/task.py", line 99, in start
    r = self.task(self, **self.params)
  File "/home/majid/15.gNMI/15.1.gNMI_get_with_pygnmi.py", line 19, in get_with_pygnmi
    print(respone)
NameError: name 'respone' is not defined

2022-09-29 22:27:10,034 -  nornir.core -     INFO -        run() - Running task 'get_with_pygnmi' with args {'path': ['openconfig-interfaces:interfaces']} on 1 hosts
2022-09-29 22:27:31,525 -  nornir.core -     INFO -        run() - Running task 'get_with_pygnmi' with args {'path': ['openconfig-interfaces:interfaces/interface[name=Ethernet1]/config']} on 1 hosts
2022-09-29 22:28:10,108 -  nornir.core -     INFO -        run() - Running task 'get_with_pygnmi' with args {'path': ['openconfig-interfaces:interfaces/interface[name=Ethernet1]/state']} on 1 hosts
2022-09-29 22:28:32,335 -  nornir.core -     INFO -        run() - Running task 'get_with_pygnmi' with args {'path': ['openconfig-interfaces:interfaces/interface[name=Ethernet1]/state/counters']} on 1 hosts
2022-09-29 22:28:39,638 -  nornir.core -     INFO -        run() - Running task 'get_with_pygnmi' with args {'path': ['openconfig-interfaces:interfaces/interface[name=Ethernet1]/state/counters']} on 1 hosts
2022-09-29 22:29:12,814 -  nornir.core -     INFO -        run() - Running task 'get_with_pygnmi' with args {'path': ['openconfig-interfaces:interfaces/interface[name=Ethernet1]/state/counters']} on 1 hosts
2022-09-29 22:39:32,383 -  nornir.core -     INFO -        run() - Running task 'get_with_pygnmi' with args {'path': ['openconfig-interfaces:interfaces/interface[name=Ethernet1]/state/counters/in-octets']} on 1 hosts
2022-09-29 22:49:47,742 -  nornir.core -     INFO -        run() - Running task 'subscribe_with_pygnmi' with args {} on 1 hosts
2022-09-29 22:49:47,959 - nornir.core.task -    ERROR -      start() - Host 'R1': task 'subscribe_with_pygnmi' failed with traceback:
Traceback (most recent call last):
  File "/home/majid/.local/lib/python3.10/site-packages/nornir/core/task.py", line 99, in start
    r = self.task(self, **self.params)
  File "/home/majid/15.gNMI/15.2.gNMI_subscribe_with_pygnmi.py", line 27, in subscribe_with_pygnmi
    for response1 in response:
  File "/home/majid/.local/lib/python3.10/site-packages/grpc/_channel.py", line 426, in __next__
    return self._next()
  File "/home/majid/.local/lib/python3.10/site-packages/grpc/_channel.py", line 826, in _next
    raise self
grpc._channel._MultiThreadedRendezvous: <_MultiThreadedRendezvous of RPC that terminated with:
	status = StatusCode.INVALID_ARGUMENT
	details = "subscribe request contains unknown origin"
	debug_error_string = "{"created":"@1664484587.845850948","description":"Error received from peer ipv4:192.168.2.61:6030","file":"src/core/lib/surface/call.cc","file_line":966,"grpc_message":"subscribe request contains unknown origin","grpc_status":3}"
>

2022-09-29 22:50:41,330 -  nornir.core -     INFO -        run() - Running task 'subscribe_with_pygnmi' with args {} on 1 hosts
2022-09-29 22:50:41,545 - nornir.core.task -    ERROR -      start() - Host 'R1': task 'subscribe_with_pygnmi' failed with traceback:
Traceback (most recent call last):
  File "/home/majid/.local/lib/python3.10/site-packages/nornir/core/task.py", line 99, in start
    r = self.task(self, **self.params)
  File "/home/majid/15.gNMI/15.2.gNMI_subscribe_with_pygnmi.py", line 26, in subscribe_with_pygnmi
    for response1 in response:
  File "/home/majid/.local/lib/python3.10/site-packages/grpc/_channel.py", line 426, in __next__
    return self._next()
  File "/home/majid/.local/lib/python3.10/site-packages/grpc/_channel.py", line 826, in _next
    raise self
grpc._channel._MultiThreadedRendezvous: <_MultiThreadedRendezvous of RPC that terminated with:
	status = StatusCode.INVALID_ARGUMENT
	details = "subscribe request contains unknown origin"
	debug_error_string = "{"created":"@1664484641.458928898","description":"Error received from peer ipv4:192.168.2.61:6030","file":"src/core/lib/surface/call.cc","file_line":966,"grpc_message":"subscribe request contains unknown origin","grpc_status":3}"
>

2022-09-29 22:55:20,630 -  nornir.core -     INFO -        run() - Running task 'test' with args {} on 1 hosts
2022-09-29 22:55:20,847 - nornir.core.task -    ERROR -      start() - Host 'R1': task 'test' failed with traceback:
Traceback (most recent call last):
  File "/home/majid/.local/lib/python3.10/site-packages/nornir/core/task.py", line 99, in start
    r = self.task(self, **self.params)
  File "/home/majid/15.gNMI/test.py", line 27, in test
    for rsp in response:
  File "/home/majid/.local/lib/python3.10/site-packages/grpc/_channel.py", line 426, in __next__
    return self._next()
  File "/home/majid/.local/lib/python3.10/site-packages/grpc/_channel.py", line 826, in _next
    raise self
grpc._channel._MultiThreadedRendezvous: <_MultiThreadedRendezvous of RPC that terminated with:
	status = StatusCode.INVALID_ARGUMENT
	details = "subscribe request contains unknown origin"
	debug_error_string = "{"created":"@1664484920.730087472","description":"Error received from peer ipv4:192.168.2.61:6030","file":"src/core/lib/surface/call.cc","file_line":966,"grpc_message":"subscribe request contains unknown origin","grpc_status":3}"
>

2022-09-29 23:29:32,369 -  nornir.core -     INFO -        run() - Running task 'subscribe_with_pygnmi' with args {} on 1 hosts
2022-09-29 23:36:28,919 -  nornir.core -     INFO -        run() - Running task 'capabilities_with_pygnmi' with args {} on 1 hosts
2022-09-29 23:36:28,920 - nornir.core.task -    ERROR -      start() - Host 'R1': task 'capabilities_with_pygnmi' failed with traceback:
Traceback (most recent call last):
  File "/home/majid/.local/lib/python3.10/site-packages/nornir/core/task.py", line 99, in start
    r = self.task(self, **self.params)
TypeError: capabilities_with_pygnmi() missing 1 required positional argument: 'path'

2022-09-29 23:37:34,917 -  nornir.core -     INFO -        run() - Running task 'capabilities_with_pygnmi' with args {} on 1 hosts
2022-09-29 23:37:34,917 - nornir.core.task -    ERROR -      start() - Host 'R1': task 'capabilities_with_pygnmi' failed with traceback:
Traceback (most recent call last):
  File "/home/majid/.local/lib/python3.10/site-packages/nornir/core/task.py", line 99, in start
    r = self.task(self, **self.params)
TypeError: capabilities_with_pygnmi() missing 1 required positional argument: 'path'

2022-09-29 23:37:44,640 -  nornir.core -     INFO -        run() - Running task 'capabilities_with_pygnmi' with args {} on 1 hosts
2022-09-29 23:37:44,640 - nornir.core.task -    ERROR -      start() - Host 'R1': task 'capabilities_with_pygnmi' failed with traceback:
Traceback (most recent call last):
  File "/home/majid/.local/lib/python3.10/site-packages/nornir/core/task.py", line 99, in start
    r = self.task(self, **self.params)
TypeError: capabilities_with_pygnmi() missing 1 required positional argument: 'path'

2022-09-29 23:38:00,789 -  nornir.core -     INFO -        run() - Running task 'capabilities_with_pygnmi' with args {} on 1 hosts
2022-09-29 23:38:00,790 - nornir.core.task -    ERROR -      start() - Host 'R1': task 'capabilities_with_pygnmi' failed with traceback:
Traceback (most recent call last):
  File "/home/majid/.local/lib/python3.10/site-packages/nornir/core/task.py", line 99, in start
    r = self.task(self, **self.params)
TypeError: capabilities_with_pygnmi() missing 1 required positional argument: 'path'

2022-09-29 23:41:05,535 -  nornir.core -     INFO -        run() - Running task 'capabilities_with_pygnmi' with args {} on 1 hosts
2022-09-29 23:41:05,536 - nornir.core.task -    ERROR -      start() - Host 'R1': task 'capabilities_with_pygnmi' failed with traceback:
Traceback (most recent call last):
  File "/home/majid/.local/lib/python3.10/site-packages/nornir/core/task.py", line 99, in start
    r = self.task(self, **self.params)
TypeError: capabilities_with_pygnmi() missing 1 required positional argument: 'path'

2022-09-29 23:44:04,881 -  nornir.core -     INFO -        run() - Running task 'capabilities_with_pygnmi' with args {} on 1 hosts
2022-09-29 23:44:56,573 -  nornir.core -     INFO -        run() - Running task 'capabilities_with_pygnmi' with args {} on 1 hosts
2022-09-29 23:47:42,829 -  nornir.core -     INFO -        run() - Running task 'capabilities_with_pygnmi' with args {} on 1 hosts
2022-09-29 23:48:07,945 -  nornir.core -     INFO -        run() - Running task 'capabilities_with_pygnmi' with args {} on 1 hosts
2022-09-29 23:48:25,302 -  nornir.core -     INFO -        run() - Running task 'capabilities_with_pygnmi' with args {} on 1 hosts
2022-09-29 23:53:50,412 -  nornir.core -     INFO -        run() - Running task 'delete_with_pygnmi' with args {'path': ['openconfig-interfaces:interfaces/interface[name=Ethernet1]/config/description']} on 1 hosts
2022-09-29 23:53:50,623 - nornir.core.task -    ERROR -      start() - Host 'R1': task 'delete_with_pygnmi' failed with traceback:
Traceback (most recent call last):
  File "/home/majid/.local/lib/python3.10/site-packages/pygnmi/client.py", line 563, in set
    gnmi_message_response = self.__stub.Set(gnmi_message_request, metadata=self.__metadata)
  File "/home/majid/.local/lib/python3.10/site-packages/grpc/_channel.py", line 946, in __call__
    return _end_unary_response_blocking(state, call, False, None)
  File "/home/majid/.local/lib/python3.10/site-packages/grpc/_channel.py", line 849, in _end_unary_response_blocking
    raise _InactiveRpcError(state)
grpc._channel._InactiveRpcError: <_InactiveRpcError of RPC that terminated with:
	status = StatusCode.INVALID_ARGUMENT
	details = "delete requests with an origin of "openconfig-interfaces" are not supported"
	debug_error_string = "{"created":"@1664488430.538299959","description":"Error received from peer ipv4:192.168.2.61:6030","file":"src/core/lib/surface/call.cc","file_line":966,"grpc_message":"delete requests with an origin of "openconfig-interfaces" are not supported","grpc_status":3}"
>

During handling of the above exception, another exception occurred:

Traceback (most recent call last):
  File "/home/majid/.local/lib/python3.10/site-packages/nornir/core/task.py", line 99, in start
    r = self.task(self, **self.params)
  File "/home/majid/15.gNMI/15.3.gNMI_delete_with_pygnmi.py", line 17, in delete_with_pygnmi
    response = client.set(delete=path)
  File "/home/majid/.local/lib/python3.10/site-packages/pygnmi/client.py", line 621, in set
    raise gNMIException(f"GRPC ERROR Host: {self.__target_path}, Error: {err.details()}", err)
pygnmi.client.gNMIException: GRPC ERROR Host: 192.168.2.61:6030, Error: delete requests with an origin of "openconfig-interfaces" are not supported

2022-09-29 23:58:37,779 -  nornir.core -     INFO -        run() - Running task 'delete_with_pygnmi' with args {'path': ['/interfaces/interface[name=Ethernet1]/config/description']} on 1 hosts
2022-09-29 23:58:38,038 - nornir.core.task -    ERROR -      start() - Host 'R1': task 'delete_with_pygnmi' failed with traceback:
Traceback (most recent call last):
  File "/home/majid/.local/lib/python3.10/site-packages/nornir/core/task.py", line 99, in start
    r = self.task(self, **self.params)
  File "/home/majid/15.gNMI/15.3.gNMI_delete_with_pygnmi.py", line 18, in delete_with_pygnmi
    print(respone)
NameError: name 'respone' is not defined

2022-09-29 23:58:58,798 -  nornir.core -     INFO -        run() - Running task 'delete_with_pygnmi' with args {'path': ['/interfaces/interface[name=Ethernet1]/config/description']} on 1 hosts
2022-09-29 23:58:59,097 - nornir.core.task -    ERROR -      start() - Host 'R1': task 'delete_with_pygnmi' failed with traceback:
Traceback (most recent call last):
  File "/home/majid/.local/lib/python3.10/site-packages/nornir/core/task.py", line 99, in start
    r = self.task(self, **self.params)
  File "/home/majid/15.gNMI/15.3.gNMI_delete_with_pygnmi.py", line 18, in delete_with_pygnmi
    print(respone)
NameError: name 'respone' is not defined

2022-09-30 00:07:07,905 -  nornir.core -     INFO -        run() - Running task 'get_with_pygnmi' with args {'path': ['openconfig-interfaces:interfaces/interface[name=Ethernet1]/state/counters/in-octets']} on 1 hosts
2022-09-30 00:07:08,114 - nornir.core.task -    ERROR -      start() - Host 'R1': task 'get_with_pygnmi' failed with traceback:
Traceback (most recent call last):
  File "/home/majid/.local/lib/python3.10/site-packages/nornir/core/task.py", line 99, in start
    r = self.task(self, **self.params)
  File "/home/majid/15.gNMI/15.2.gNMI_get_with_pygnmi.py", line 21, in get_with_pygnmi
    pp(result)
NameError: name 'pp' is not defined

2022-09-30 00:07:38,933 -  nornir.core -     INFO -        run() - Running task 'get_with_pygnmi' with args {'path': ['openconfig-interfaces:interfaces/interface[name=Ethernet1]/state/counters/in-octets']} on 1 hosts
2022-09-30 00:08:04,899 -  nornir.core -     INFO -        run() - Running task 'get_with_pygnmi' with args {'path': ['openconfig-interfaces:interfaces/interface[name=Ethernet1]/state/counters/in-octets']} on 1 hosts
2022-09-30 00:15:05,093 -  nornir.core -     INFO -        run() - Running task 'set_with_pygnmi' with args {'config': [('openconfig:/interfaces/interface[name=Ethernet1]', {'config': {'name': 'Ethernet1', 'enabled': True, 'description': 'Test'}})]} on 1 hosts
2022-09-30 00:15:20,612 -  nornir.core -     INFO -        run() - Running task 'set_with_pygnmi' with args {'config': [('openconfig:/interfaces/interface[name=Ethernet1]', {'config': {'name': 'Ethernet1', 'enabled': True, 'description': 'TestTEST'}})]} on 1 hosts
2022-09-30 00:16:43,089 -  nornir.core -     INFO -        run() - Running task 'set_with_pygnmi' with args {'config': [('openconfig:/interfaces/interface[name=Ethernet1]', {'config': {'name': 'Ethernet1', 'enabled': True, 'description': 'TestTEST'}})]} on 1 hosts
2022-09-30 00:16:50,819 -  nornir.core -     INFO -        run() - Running task 'get_with_pygnmi' with args {'path': ['openconfig-interfaces:interfaces/interface[name=Ethernet1]/state/counters/in-octets']} on 1 hosts
2022-09-30 00:16:51,029 - nornir.core.task -    ERROR -      start() - Host 'R1': task 'get_with_pygnmi' failed with traceback:
Traceback (most recent call last):
  File "/home/majid/.local/lib/python3.10/site-packages/nornir/core/task.py", line 99, in start
    r = self.task(self, **self.params)
  File "/home/majid/15.gNMI/15.2.gNMI_get_with_pygnmi.py", line 22, in get_with_pygnmi
    raw_data = gc.get(path=path, encoding="json_ietf")
NameError: name 'gc' is not defined

2022-09-30 00:17:17,083 -  nornir.core -     INFO -        run() - Running task 'get_with_pygnmi' with args {'path': ['openconfig-interfaces:interfaces/interface[name=Ethernet1]/state/counters/in-octets']} on 1 hosts
2022-09-30 00:17:17,292 - nornir.core.task -    ERROR -      start() - Host 'R1': task 'get_with_pygnmi' failed with traceback:
Traceback (most recent call last):
  File "/home/majid/.local/lib/python3.10/site-packages/nornir/core/task.py", line 99, in start
    r = self.task(self, **self.params)
  File "/home/majid/15.gNMI/15.2.gNMI_get_with_pygnmi.py", line 22, in get_with_pygnmi
    raw_data = gc.get(path=path, encoding="json_ietf")
NameError: name 'gc' is not defined

2022-09-30 00:18:01,724 -  nornir.core -     INFO -        run() - Running task 'get_with_pygnmi' with args {'path': ['openconfig-interfaces:interfaces/interface[name=Ethernet1]/state/counters/in-octets']} on 1 hosts
2022-09-30 00:18:01,937 - nornir.core.task -    ERROR -      start() - Host 'R1': task 'get_with_pygnmi' failed with traceback:
Traceback (most recent call last):
  File "/home/majid/.local/lib/python3.10/site-packages/nornir/core/task.py", line 99, in start
    r = self.task(self, **self.params)
  File "/home/majid/15.gNMI/15.2.gNMI_get_with_pygnmi.py", line 23, in get_with_pygnmi
    raw_data = gc.get(path=path, encoding="json_ietf")
NameError: name 'gc' is not defined

2022-09-30 00:18:17,238 -  nornir.core -     INFO -        run() - Running task 'get_with_pygnmi' with args {'path': ['openconfig-interfaces:interfaces/interface[name=Ethernet1]/state/counters/in-octets']} on 1 hosts
2022-09-30 00:18:48,368 -  nornir.core -     INFO -        run() - Running task 'get_with_pygnmi' with args {'path': ['openconfig-interfaces:interfaces/interface[name=Ethernet1]/state/counters/in-octets']} on 1 hosts
2022-09-30 00:19:18,161 -  nornir.core -     INFO -        run() - Running task 'get_with_pygnmi' with args {'path': ['openconfig-interfaces:interfaces/interface[name=Ethernet1]/state/counters/in-octets']} on 1 hosts
2022-09-30 00:19:37,884 -  nornir.core -     INFO -        run() - Running task 'get_with_pygnmi' with args {'path': ['openconfig-interfaces:interfaces/interface[name=Ethernet1]/state/counters/in-octets']} on 1 hosts
2022-09-30 00:51:49,825 -  nornir.core -     INFO -        run() - Running task 'capabilities_with_pygnmi' with args {} on 1 hosts
2022-09-30 00:54:10,003 -  nornir.core -     INFO -        run() - Running task 'get_with_pygnmi' with args {'path': ['openconfig-interfaces:interfaces']} on 1 hosts
2022-09-30 00:54:26,903 -  nornir.core -     INFO -        run() - Running task 'get_with_pygnmi' with args {'path': ['openconfig-interfaces:interfaces']} on 1 hosts
2022-09-30 00:54:50,018 -  nornir.core -     INFO -        run() - Running task 'get_with_pygnmi' with args {'path': ['openconfig-interfaces:interfaces/interface[name=Ethernet1]/config']} on 1 hosts
2022-09-30 00:55:12,046 -  nornir.core -     INFO -        run() - Running task 'get_with_pygnmi' with args {'path': ['openconfig-interfaces:interfaces/interface[name=Ethernet1]/state/counters']} on 1 hosts
2022-09-30 00:55:31,630 -  nornir.core -     INFO -        run() - Running task 'get_with_pygnmi' with args {'path': ['openconfig-interfaces:interfaces/interface[name=Ethernet1]/state/counters/in-octets']} on 1 hosts
2023-05-28 13:52:02,350 -  nornir.core -     INFO -        run() - Running task 'capabilities_with_pygnmi' with args {} on 1 hosts
2023-05-28 13:52:30,435 -  nornir.core -     INFO -        run() - Running task 'capabilities_with_pygnmi' with args {} on 1 hosts
2023-05-28 13:52:42,912 -  nornir.core -     INFO -        run() - Running task 'capabilities_with_pygnmi' with args {} on 1 hosts
2023-05-28 13:52:48,119 -  nornir.core -     INFO -        run() - Running task 'capabilities_with_pygnmi' with args {} on 1 hosts
2023-05-28 13:53:13,664 -  nornir.core -     INFO -        run() - Running task 'get_with_pygnmi' with args {'path': ['openconfig-interfaces:interfaces/interface[name=Ethernet1]/state/counters/in-octets']} on 1 hosts
2023-05-28 13:53:13,892 - nornir.core.task -    ERROR -      start() - Host 'R1': task 'get_with_pygnmi' failed with traceback:
Traceback (most recent call last):
  File "/home/majid/.local/lib/python3.10/site-packages/pygnmi/client.py", line 432, in get
    gnmi_message_response = self.__stub.Get(gnmi_message_request, metadata=self.__metadata)
  File "/home/majid/.local/lib/python3.10/site-packages/grpc/_channel.py", line 1030, in __call__
    return _end_unary_response_blocking(state, call, False, None)
  File "/home/majid/.local/lib/python3.10/site-packages/grpc/_channel.py", line 910, in _end_unary_response_blocking
    raise _InactiveRpcError(state)  # pytype: disable=not-instantiable
grpc._channel._InactiveRpcError: <_InactiveRpcError of RPC that terminated with:
	status = StatusCode.INVALID_ARGUMENT
	details = "Get request contains unknown origin "openconfig-interfaces""
	debug_error_string = "UNKNOWN:Error received from peer  {created_time:"2023-05-28T13:53:13.81114643+02:00", grpc_status:3, grpc_message:"Get request contains unknown origin \"openconfig-interfaces\""}"
>

During handling of the above exception, another exception occurred:

Traceback (most recent call last):
  File "/home/majid/.local/lib/python3.10/site-packages/nornir/core/task.py", line 99, in start
    r = self.task(self, **self.params)
  File "/home/majid/devnet/pyhton_nornir/2023/14.gNMI/14.4.gNMI_get_with_pygnmi.py", line 21, in get_with_pygnmi
    result = client.get(path=path, encoding="json_ietf")
  File "/home/majid/.local/lib/python3.10/site-packages/pygnmi/client.py", line 520, in get
    raise gNMIException(f"GRPC ERROR Host: {self.__target_path}, Error: {err.details()}", err)
pygnmi.client.gNMIException: GRPC ERROR Host: 192.168.2.91:6030, Error: Get request contains unknown origin "openconfig-interfaces"

2023-05-28 13:53:39,316 -  nornir.core -     INFO -        run() - Running task 'get_with_pygnmi' with args {'path': ['openconfig-interfaces:interfaces']} on 1 hosts
2023-05-28 13:53:39,534 - nornir.core.task -    ERROR -      start() - Host 'R1': task 'get_with_pygnmi' failed with traceback:
Traceback (most recent call last):
  File "/home/majid/.local/lib/python3.10/site-packages/pygnmi/client.py", line 432, in get
    gnmi_message_response = self.__stub.Get(gnmi_message_request, metadata=self.__metadata)
  File "/home/majid/.local/lib/python3.10/site-packages/grpc/_channel.py", line 1030, in __call__
    return _end_unary_response_blocking(state, call, False, None)
  File "/home/majid/.local/lib/python3.10/site-packages/grpc/_channel.py", line 910, in _end_unary_response_blocking
    raise _InactiveRpcError(state)  # pytype: disable=not-instantiable
grpc._channel._InactiveRpcError: <_InactiveRpcError of RPC that terminated with:
	status = StatusCode.INVALID_ARGUMENT
	details = "Get request contains unknown origin "openconfig-interfaces""
	debug_error_string = "UNKNOWN:Error received from peer  {created_time:"2023-05-28T13:53:39.43461075+02:00", grpc_status:3, grpc_message:"Get request contains unknown origin \"openconfig-interfaces\""}"
>

During handling of the above exception, another exception occurred:

Traceback (most recent call last):
  File "/home/majid/.local/lib/python3.10/site-packages/nornir/core/task.py", line 99, in start
    r = self.task(self, **self.params)
  File "/home/majid/devnet/pyhton_nornir/2023/14.gNMI/14.4.gNMI_get_with_pygnmi.py", line 21, in get_with_pygnmi
    result = client.get(path=path, encoding="json_ietf")
  File "/home/majid/.local/lib/python3.10/site-packages/pygnmi/client.py", line 520, in get
    raise gNMIException(f"GRPC ERROR Host: {self.__target_path}, Error: {err.details()}", err)
pygnmi.client.gNMIException: GRPC ERROR Host: 192.168.2.91:6030, Error: Get request contains unknown origin "openconfig-interfaces"

2023-05-28 13:55:11,155 -  nornir.core -     INFO -        run() - Running task 'get_with_pygnmi' with args {'path': ['interfaces:interfaces/interface[name=Ethernet1]/state/counters/in-octets']} on 1 hosts
2023-05-28 13:55:11,375 - nornir.core.task -    ERROR -      start() - Host 'R1': task 'get_with_pygnmi' failed with traceback:
Traceback (most recent call last):
  File "/home/majid/.local/lib/python3.10/site-packages/pygnmi/client.py", line 432, in get
    gnmi_message_response = self.__stub.Get(gnmi_message_request, metadata=self.__metadata)
  File "/home/majid/.local/lib/python3.10/site-packages/grpc/_channel.py", line 1030, in __call__
    return _end_unary_response_blocking(state, call, False, None)
  File "/home/majid/.local/lib/python3.10/site-packages/grpc/_channel.py", line 910, in _end_unary_response_blocking
    raise _InactiveRpcError(state)  # pytype: disable=not-instantiable
grpc._channel._InactiveRpcError: <_InactiveRpcError of RPC that terminated with:
	status = StatusCode.INVALID_ARGUMENT
	details = "Get request contains unknown origin "interfaces""
	debug_error_string = "UNKNOWN:Error received from peer  {created_time:"2023-05-28T13:55:11.271911487+02:00", grpc_status:3, grpc_message:"Get request contains unknown origin \"interfaces\""}"
>

During handling of the above exception, another exception occurred:

Traceback (most recent call last):
  File "/home/majid/.local/lib/python3.10/site-packages/nornir/core/task.py", line 99, in start
    r = self.task(self, **self.params)
  File "/home/majid/devnet/pyhton_nornir/2023/14.gNMI/14.4.gNMI_get_with_pygnmi.py", line 21, in get_with_pygnmi
    result = client.get(path=path, encoding="json_ietf")
  File "/home/majid/.local/lib/python3.10/site-packages/pygnmi/client.py", line 520, in get
    raise gNMIException(f"GRPC ERROR Host: {self.__target_path}, Error: {err.details()}", err)
pygnmi.client.gNMIException: GRPC ERROR Host: 192.168.2.91:6030, Error: Get request contains unknown origin "interfaces"

2023-05-28 13:55:40,810 -  nornir.core -     INFO -        run() - Running task 'get_with_pygnmi' with args {'path': ['/interfaces:interfaces/interface[name=Ethernet1]/state/counters/in-octets']} on 1 hosts
2023-05-28 13:55:41,029 - nornir.core.task -    ERROR -      start() - Host 'R1': task 'get_with_pygnmi' failed with traceback:
Traceback (most recent call last):
  File "/home/majid/.local/lib/python3.10/site-packages/pygnmi/client.py", line 432, in get
    gnmi_message_response = self.__stub.Get(gnmi_message_request, metadata=self.__metadata)
  File "/home/majid/.local/lib/python3.10/site-packages/grpc/_channel.py", line 1030, in __call__
    return _end_unary_response_blocking(state, call, False, None)
  File "/home/majid/.local/lib/python3.10/site-packages/grpc/_channel.py", line 910, in _end_unary_response_blocking
    raise _InactiveRpcError(state)  # pytype: disable=not-instantiable
grpc._channel._InactiveRpcError: <_InactiveRpcError of RPC that terminated with:
	status = StatusCode.INVALID_ARGUMENT
	details = "Get request contains unknown origin "interfaces""
	debug_error_string = "UNKNOWN:Error received from peer  {created_time:"2023-05-28T13:55:40.934988602+02:00", grpc_status:3, grpc_message:"Get request contains unknown origin \"interfaces\""}"
>

During handling of the above exception, another exception occurred:

Traceback (most recent call last):
  File "/home/majid/.local/lib/python3.10/site-packages/nornir/core/task.py", line 99, in start
    r = self.task(self, **self.params)
  File "/home/majid/devnet/pyhton_nornir/2023/14.gNMI/14.4.gNMI_get_with_pygnmi.py", line 21, in get_with_pygnmi
    result = client.get(path=path, encoding="json_ietf")
  File "/home/majid/.local/lib/python3.10/site-packages/pygnmi/client.py", line 520, in get
    raise gNMIException(f"GRPC ERROR Host: {self.__target_path}, Error: {err.details()}", err)
pygnmi.client.gNMIException: GRPC ERROR Host: 192.168.2.91:6030, Error: Get request contains unknown origin "interfaces"

2023-05-28 13:55:58,070 -  nornir.core -     INFO -        run() - Running task 'get_with_pygnmi' with args {'path': ['/interfaces/interface[name=Ethernet1]']} on 1 hosts
2023-05-28 13:56:22,845 -  nornir.core -     INFO -        run() - Running task 'get_with_pygnmi' with args {'path': ['/interfaces/interface[name=Ethernet1]/state/counters/in-octets']} on 1 hosts
2023-05-28 13:56:59,122 -  nornir.core -     INFO -        run() - Running task 'get_with_pygnmi' with args {'path': ['/interfaces/interface[name=Ethernet1]/state/counters/in-octets']} on 1 hosts
2023-05-30 23:16:48,968 -  nornir.core -     INFO -        run() - Running task 'capabilities_with_pygnmi' with args {} on 1 hosts
2023-05-30 23:36:07,372 -  nornir.core -     INFO -        run() - Running task 'capabilities_with_pygnmi' with args {} on 1 hosts
2023-05-30 23:38:20,203 -  nornir.core -     INFO -        run() - Running task 'get_with_pygnmi' with args {'path': ['/interfaces/interface[name=Ethernet1]/state/counters/in-octets']} on 1 hosts
2023-05-30 23:38:30,224 -  nornir.core -     INFO -        run() - Running task 'get_with_pygnmi' with args {'path': ['/interfaces/interface[name=Ethernet1]/state/counters/in-octets']} on 1 hosts
2023-05-30 23:38:42,927 -  nornir.core -     INFO -        run() - Running task 'get_with_pygnmi' with args {'path': ['/interfaces/interface[name=Ethernet1]/state/counters/in-octets']} on 1 hosts
2023-06-02 00:13:31,185 -  nornir.core -     INFO -        run() - Running task 'set_with_pygnmi' with args {'config': [('openconfig:/interfaces/interface[name=Ethernet1]', {'config': {'name': 'Ethernet1', 'enabled': True, 'description': 'TestTEST'}})]} on 1 hosts
2023-06-02 00:13:41,910 -  nornir.core -     INFO -        run() - Running task 'delete_with_pygnmi' with args {'path': ['/interfaces/interface[name=Ethernet1]/config/description']} on 1 hosts
2023-06-02 00:13:43,057 - nornir.core.task -    ERROR -      start() - Host 'R1': task 'delete_with_pygnmi' failed with traceback:
Traceback (most recent call last):
  File "/home/majid/.local/lib/python3.10/site-packages/nornir/core/task.py", line 99, in start
    r = self.task(self, **self.params)
  File "/home/majid/devnet/pyhton_nornir/2023/14.gNMI/14.6.gNMI_delete_with_pygnmi.py", line 18, in delete_with_pygnmi
    print(respone)
NameError: name 'respone' is not defined

2023-06-02 00:13:56,544 -  nornir.core -     INFO -        run() - Running task 'set_with_pygnmi' with args {'config': [('openconfig:/interfaces/interface[name=Ethernet1]', {'config': {'name': 'Ethernet1', 'enabled': True, 'description': 'TestTEST'}})]} on 1 hosts
2023-06-02 00:15:52,581 -  nornir.core -     INFO -        run() - Running task 'subscribe_with_pygnmi' with args {} on 1 hosts
2023-06-02 00:16:08,778 -  nornir.core -     INFO -        run() - Running task 'subscribe_with_pygnmi' with args {} on 1 hosts
2023-06-02 00:18:07,068 -  nornir.core -     INFO -        run() - Running task 'set_with_pygnmi' with args {'config': [('openconfig:/interfaces/interface[name=Ethernet1]', {'config': {'name': 'Ethernet1', 'enabled': True, 'description': 'TestTEST'}})]} on 1 hosts
2023-06-02 00:18:50,277 -  nornir.core -     INFO -        run() - Running task 'delete_with_pygnmi' with args {'path': ['/interfaces/interface[name=Ethernet1]/config/description']} on 1 hosts
2023-06-02 00:18:51,212 - nornir.core.task -    ERROR -      start() - Host 'R1': task 'delete_with_pygnmi' failed with traceback:
Traceback (most recent call last):
  File "/home/majid/.local/lib/python3.10/site-packages/nornir/core/task.py", line 99, in start
    r = self.task(self, **self.params)
  File "/home/majid/devnet/pyhton_nornir/2023/14.gNMI/14.6.gNMI_delete_with_pygnmi.py", line 18, in delete_with_pygnmi
    print(respone)
NameError: name 'respone' is not defined

2023-06-02 00:19:30,160 -  nornir.core -     INFO -        run() - Running task 'set_with_pygnmi' with args {'config': [('openconfig:/interfaces/interface[name=Ethernet1]', {'config': {'name': 'Ethernet1', 'enabled': True, 'description': 'TestTEST'}})]} on 1 hosts
2023-06-02 00:21:18,046 -  nornir.core -     INFO -        run() - Running task 'subscribe_with_pygnmi' with args {} on 1 hosts
