2023-01-18 01:01:10,074 -  nornir.core -     INFO -        run() - Running task 'nornir_basic_filtering_using_filter_method_example' with args {} on 1 hosts
2023-01-18 01:01:13,157 - nornir.core.task -    ERROR -      start() - Host 'R1': task 'netmiko_send_command' failed with traceback:
Traceback (most recent call last):
  File "/home/majid/.local/lib/python3.10/site-packages/netmiko/base_connection.py", line 935, in establish_connection
    self.remote_conn_pre.connect(**ssh_connect_params)
  File "/home/majid/.local/lib/python3.10/site-packages/paramiko/client.py", line 368, in connect
    raise NoValidConnectionsError(errors)
paramiko.ssh_exception.NoValidConnectionsError: [Errno None] Unable to connect to port 22 on 192.168.2.91

During handling of the above exception, another exception occurred:

Traceback (most recent call last):
  File "/home/majid/.local/lib/python3.10/site-packages/nornir/core/task.py", line 99, in start
    r = self.task(self, **self.params)
  File "/home/majid/.local/lib/python3.10/site-packages/nornir_netmiko/tasks/netmiko_send_command.py", line 26, in netmiko_send_command
    net_connect = task.host.get_connection(CONNECTION_NAME, task.nornir.config)
  File "/home/majid/.local/lib/python3.10/site-packages/nornir/core/inventory.py", line 494, in get_connection
    self.open_connection(
  File "/home/majid/.local/lib/python3.10/site-packages/nornir/core/inventory.py", line 546, in open_connection
    conn_obj.open(
  File "/home/majid/.local/lib/python3.10/site-packages/nornir_netmiko/connections/netmiko.py", line 59, in open
    connection = ConnectHandler(**parameters)
  File "/home/majid/.local/lib/python3.10/site-packages/netmiko/ssh_dispatcher.py", line 326, in ConnectHandler
    return ConnectionClass(*args, **kwargs)
  File "/home/majid/.local/lib/python3.10/site-packages/netmiko/cisco/cisco_ios.py", line 17, in __init__
    return super().__init__(*args, **kwargs)
  File "/home/majid/.local/lib/python3.10/site-packages/netmiko/base_connection.py", line 350, in __init__
    self._open()
  File "/home/majid/.local/lib/python3.10/site-packages/netmiko/base_connection.py", line 355, in _open
    self.establish_connection()
  File "/home/majid/.local/lib/python3.10/site-packages/netmiko/base_connection.py", line 957, in establish_connection
    raise NetmikoTimeoutException(msg)
netmiko.ssh_exception.NetmikoTimeoutException: TCP connection to device failed.

Common causes of this problem are:
1. Incorrect hostname or IP address.
2. Wrong TCP port.
3. Intermediate firewall blocking access.

Device settings: cisco_ios 192.168.2.91:22



2023-01-18 01:01:13,158 - nornir.core.task -    ERROR -      start() - Host 'R1': task 'nornir_basic_filtering_using_filter_method_example' failed with traceback:
Traceback (most recent call last):
  File "/home/majid/.local/lib/python3.10/site-packages/nornir/core/task.py", line 99, in start
    r = self.task(self, **self.params)
  File "/home/majid/devnet/pyhton_nornir/2023/7.nornir_filter_inventory/8.1.nornir_basic_filtering_using_filter_method.py", line 8, in nornir_basic_filtering_using_filter_method_example
    task.run(task=netmiko_send_command, command_string="show ip int brief | exc unass")
  File "/home/majid/.local/lib/python3.10/site-packages/nornir/core/task.py", line 174, in run
    raise NornirSubTaskError(task=run_task, result=r)
nornir.core.exceptions.NornirSubTaskError: Subtask: netmiko_send_command (failed)


2023-01-18 01:02:50,096 -  nornir.core -     INFO -        run() - Running task 'nornir_basic_filtering_using_filter_method_example' with args {} on 1 hosts
2023-01-18 01:02:53,164 - nornir.core.task -    ERROR -      start() - Host 'R1': task 'netmiko_send_command' failed with traceback:
Traceback (most recent call last):
  File "/home/majid/.local/lib/python3.10/site-packages/netmiko/base_connection.py", line 935, in establish_connection
    self.remote_conn_pre.connect(**ssh_connect_params)
  File "/home/majid/.local/lib/python3.10/site-packages/paramiko/client.py", line 368, in connect
    raise NoValidConnectionsError(errors)
paramiko.ssh_exception.NoValidConnectionsError: [Errno None] Unable to connect to port 22 on 192.168.2.91

During handling of the above exception, another exception occurred:

Traceback (most recent call last):
  File "/home/majid/.local/lib/python3.10/site-packages/nornir/core/task.py", line 99, in start
    r = self.task(self, **self.params)
  File "/home/majid/.local/lib/python3.10/site-packages/nornir_netmiko/tasks/netmiko_send_command.py", line 26, in netmiko_send_command
    net_connect = task.host.get_connection(CONNECTION_NAME, task.nornir.config)
  File "/home/majid/.local/lib/python3.10/site-packages/nornir/core/inventory.py", line 494, in get_connection
    self.open_connection(
  File "/home/majid/.local/lib/python3.10/site-packages/nornir/core/inventory.py", line 546, in open_connection
    conn_obj.open(
  File "/home/majid/.local/lib/python3.10/site-packages/nornir_netmiko/connections/netmiko.py", line 59, in open
    connection = ConnectHandler(**parameters)
  File "/home/majid/.local/lib/python3.10/site-packages/netmiko/ssh_dispatcher.py", line 326, in ConnectHandler
    return ConnectionClass(*args, **kwargs)
  File "/home/majid/.local/lib/python3.10/site-packages/netmiko/cisco/cisco_ios.py", line 17, in __init__
    return super().__init__(*args, **kwargs)
  File "/home/majid/.local/lib/python3.10/site-packages/netmiko/base_connection.py", line 350, in __init__
    self._open()
  File "/home/majid/.local/lib/python3.10/site-packages/netmiko/base_connection.py", line 355, in _open
    self.establish_connection()
  File "/home/majid/.local/lib/python3.10/site-packages/netmiko/base_connection.py", line 957, in establish_connection
    raise NetmikoTimeoutException(msg)
netmiko.ssh_exception.NetmikoTimeoutException: TCP connection to device failed.

Common causes of this problem are:
1. Incorrect hostname or IP address.
2. Wrong TCP port.
3. Intermediate firewall blocking access.

Device settings: cisco_ios 192.168.2.91:22



2023-01-18 01:02:53,165 - nornir.core.task -    ERROR -      start() - Host 'R1': task 'nornir_basic_filtering_using_filter_method_example' failed with traceback:
Traceback (most recent call last):
  File "/home/majid/.local/lib/python3.10/site-packages/nornir/core/task.py", line 99, in start
    r = self.task(self, **self.params)
  File "/home/majid/devnet/pyhton_nornir/2023/7.nornir_filter_inventory/8.1.nornir_basic_filtering_using_filter_method.py", line 8, in nornir_basic_filtering_using_filter_method_example
    task.run(task=netmiko_send_command, command_string="show ip int brief | exc unass")
  File "/home/majid/.local/lib/python3.10/site-packages/nornir/core/task.py", line 174, in run
    raise NornirSubTaskError(task=run_task, result=r)
nornir.core.exceptions.NornirSubTaskError: Subtask: netmiko_send_command (failed)


2023-01-18 01:04:15,820 -  nornir.core -     INFO -        run() - Running task 'nornir_basic_filtering_using_filter_method_example' with args {} on 1 hosts
2023-01-18 01:04:26,455 -  nornir.core -     INFO -        run() - Running task 'nornir_advanced_filtering_using_F_object_example' with args {} on 1 hosts
2023-01-18 01:05:41,874 -  nornir.core -     INFO -        run() - Running task 'nornir_basic_filtering_using_filter_method_example' with args {} on 1 hosts
2023-01-18 01:05:46,210 -  nornir.core -     INFO -        run() - Running task 'nornir_advanced_filtering_using_F_object_example' with args {} on 1 hosts
2023-01-18 13:08:09,386 -  nornir.core -     INFO -        run() - Running task 'nornir_basic_filtering_using_filter_method_example' with args {} on 1 hosts
2023-01-18 13:08:32,454 -  nornir.core -     INFO -        run() - Running task 'nornir_advanced_filtering_using_F_object_example' with args {} on 1 hosts
2023-01-18 14:02:17,711 -  nornir.core -     INFO -        run() - Running task 'nornir_basic_filtering_using_filter_method_example' with args {} on 1 hosts
2023-01-18 14:02:42,861 -  nornir.core -  WARNING -        run() - Task 'nornir_basic_filtering_using_filter_method_example' has not been run – 0 hosts selected
2023-01-18 14:03:11,386 -  nornir.core -  WARNING -        run() - Task 'nornir_basic_filtering_using_filter_method_example' has not been run – 0 hosts selected
2023-01-18 14:03:54,263 -  nornir.core -  WARNING -        run() - Task 'nornir_basic_filtering_using_filter_method_example' has not been run – 0 hosts selected
2023-01-18 22:23:58,535 -  nornir.core -     INFO -        run() - Running task 'nornir_basic_filtering_using_filter_method_example' with args {} on 1 hosts
2023-01-18 22:26:38,763 -  nornir.core -     INFO -        run() - Running task 'nornir_advanced_filtering_using_F_object_example' with args {} on 1 hosts
