2022-07-22 15:42:15,359 -  nornir.core -     INFO -        run() - Running task 'get_device_config' with args {} on 1 hosts
2022-07-22 15:42:25,595 - nornir.core.task -    ERROR -      start() - Host 'R1': task 'netconf_get_config' failed with traceback:
Traceback (most recent call last):
  File "/home/majid/.local/lib/python3.10/site-packages/nornir/core/task.py", line 99, in start
    r = self.task(self, **self.params)
  File "/home/majid/.local/lib/python3.10/site-packages/nornir_scrapli/tasks/netconf/get_config.py", line 31, in netconf_get_config
    scrapli_conn = task.host.get_connection("scrapli_netconf", task.nornir.config)
  File "/home/majid/.local/lib/python3.10/site-packages/nornir/core/inventory.py", line 494, in get_connection
    self.open_connection(
  File "/home/majid/.local/lib/python3.10/site-packages/nornir/core/inventory.py", line 546, in open_connection
    conn_obj.open(
  File "/home/majid/.local/lib/python3.10/site-packages/nornir_scrapli/connection.py", line 280, in open
    connection.open()
  File "/home/majid/.local/lib/python3.10/site-packages/scrapli_netconf/driver/sync_driver.py", line 117, in open
    self.channel.channel_authenticate_netconf(
  File "/home/majid/.local/lib/python3.10/site-packages/scrapli/decorators.py", line 280, in decorate
    return self._multiprocessing_timeout(
  File "/home/majid/.local/lib/python3.10/site-packages/scrapli/decorators.py", line 341, in _multiprocessing_timeout
    return future.result()
  File "/usr/lib/python3.10/concurrent/futures/_base.py", line 439, in result
    return self.__get_result()
  File "/usr/lib/python3.10/concurrent/futures/_base.py", line 391, in __get_result
    raise self._exception
  File "/usr/lib/python3.10/concurrent/futures/thread.py", line 58, in run
    result = self.fn(*self.args, **self.kwargs)
  File "/home/majid/.local/lib/python3.10/site-packages/scrapli_netconf/channel/sync_channel.py", line 100, in channel_authenticate_netconf
    buf = self.read()
  File "/home/majid/.local/lib/python3.10/site-packages/scrapli/channel/sync_channel.py", line 69, in read
    buf = self.transport.read()
  File "/home/majid/.local/lib/python3.10/site-packages/scrapli/decorators.py", line 99, in decorate
    return self._multiprocessing_timeout(
  File "/home/majid/.local/lib/python3.10/site-packages/scrapli/decorators.py", line 176, in _multiprocessing_timeout
    self._handle_timeout()
  File "/home/majid/.local/lib/python3.10/site-packages/scrapli/decorators.py", line 152, in _handle_timeout
    raise ScrapliTimeout(self.message)
scrapli.exceptions.ScrapliTimeout: timed out reading from transport

2022-07-22 15:42:25,596 - nornir.core.task -    ERROR -      start() - Host 'R1': task 'get_device_config' failed with traceback:
Traceback (most recent call last):
  File "/home/majid/.local/lib/python3.10/site-packages/nornir/core/task.py", line 99, in start
    r = self.task(self, **self.params)
  File "/home/majid/devnet/pyhton_nornir/13.netconf/13.netconf.py", line 8, in get_device_config
    task.run(task=netconf_get_config, source="running")
  File "/home/majid/.local/lib/python3.10/site-packages/nornir/core/task.py", line 174, in run
    raise NornirSubTaskError(task=run_task, result=r)
nornir.core.exceptions.NornirSubTaskError: Subtask: netconf_get_config (failed)


2022-07-22 15:50:32,703 -  nornir.core -     INFO -        run() - Running task 'get_device_config' with args {} on 1 hosts
2022-07-22 15:50:54,962 -  nornir.core -     INFO -        run() - Running task 'get_device_config' with args {} on 1 hosts
2022-07-22 15:51:52,954 -  nornir.core -     INFO -        run() - Running task 'get_device_config' with args {} on 1 hosts
2022-07-22 15:53:23,150 -  nornir.core -     INFO -        run() - Running task 'get_device_config' with args {} on 1 hosts
2022-07-22 15:53:23,151 - nornir.core.task -    ERROR -      start() - Host 'R1': task 'netconf_get_config' failed with traceback:
Traceback (most recent call last):
  File "/home/majid/.local/lib/python3.10/site-packages/nornir/core/task.py", line 99, in start
    r = self.task(self, **self.params)
TypeError: netconf_get_config() got an unexpected keyword argument 'filters'

2022-07-22 15:53:23,152 - nornir.core.task -    ERROR -      start() - Host 'R1': task 'get_device_config' failed with traceback:
Traceback (most recent call last):
  File "/home/majid/.local/lib/python3.10/site-packages/nornir/core/task.py", line 99, in start
    r = self.task(self, **self.params)
  File "/home/majid/devnet/pyhton_nornir/13.netconf/13.netconf.py", line 9, in get_device_config
    task.run(task=netconf_get_config, source="running", filter_type="xpath", filters="/native")
  File "/home/majid/.local/lib/python3.10/site-packages/nornir/core/task.py", line 174, in run
    raise NornirSubTaskError(task=run_task, result=r)
nornir.core.exceptions.NornirSubTaskError: Subtask: netconf_get_config (failed)


2022-07-22 15:55:05,135 -  nornir.core -     INFO -        run() - Running task 'get_device_config' with args {} on 1 hosts
2022-07-22 15:55:05,136 - nornir.core.task -    ERROR -      start() - Host 'R1': task 'netconf_get_config' failed with traceback:
Traceback (most recent call last):
  File "/home/majid/.local/lib/python3.10/site-packages/nornir/core/task.py", line 99, in start
    r = self.task(self, **self.params)
TypeError: netconf_get_config() got an unexpected keyword argument 'filters'

2022-07-22 15:55:05,136 - nornir.core.task -    ERROR -      start() - Host 'R1': task 'get_device_config' failed with traceback:
Traceback (most recent call last):
  File "/home/majid/.local/lib/python3.10/site-packages/nornir/core/task.py", line 99, in start
    r = self.task(self, **self.params)
  File "/home/majid/devnet/pyhton_nornir/13.netconf/13.netconf.py", line 9, in get_device_config
    task.run(task=netconf_get_config, source="running", filter_type="xpath", filters="/native")
  File "/home/majid/.local/lib/python3.10/site-packages/nornir/core/task.py", line 174, in run
    raise NornirSubTaskError(task=run_task, result=r)
nornir.core.exceptions.NornirSubTaskError: Subtask: netconf_get_config (failed)


2022-07-22 15:55:29,438 -  nornir.core -     INFO -        run() - Running task 'get_device_config' with args {} on 1 hosts
2022-07-22 15:55:29,440 - nornir.core.task -    ERROR -      start() - Host 'R1': task 'netconf_get_config' failed with traceback:
Traceback (most recent call last):
  File "/home/majid/.local/lib/python3.10/site-packages/nornir/core/task.py", line 99, in start
    r = self.task(self, **self.params)
TypeError: netconf_get_config() got an unexpected keyword argument 'filter'

2022-07-22 15:55:29,441 - nornir.core.task -    ERROR -      start() - Host 'R1': task 'get_device_config' failed with traceback:
Traceback (most recent call last):
  File "/home/majid/.local/lib/python3.10/site-packages/nornir/core/task.py", line 99, in start
    r = self.task(self, **self.params)
  File "/home/majid/devnet/pyhton_nornir/13.netconf/13.netconf.py", line 9, in get_device_config
    task.run(task=netconf_get_config, source="running", filter_type="xpath", filter="/native")
  File "/home/majid/.local/lib/python3.10/site-packages/nornir/core/task.py", line 174, in run
    raise NornirSubTaskError(task=run_task, result=r)
nornir.core.exceptions.NornirSubTaskError: Subtask: netconf_get_config (failed)


2022-07-22 15:56:23,423 -  nornir.core -     INFO -        run() - Running task 'get_device_config' with args {} on 1 hosts
2022-07-22 15:57:04,959 -  nornir.core -     INFO -        run() - Running task 'get_device_config' with args {} on 1 hosts
2022-07-22 15:57:55,446 -  nornir.core -     INFO -        run() - Running task 'get_device_config' with args {} on 1 hosts
2022-07-24 20:21:54,018 -  nornir.core -     INFO -        run() - Running task 'get_device_config' with args {} on 1 hosts
2022-07-24 20:37:08,900 -  nornir.core -     INFO -        run() - Running task 'get_device_config' with args {} on 1 hosts
2022-07-24 20:37:09,841 - nornir.core.task -    ERROR -      start() - Host 'R1': task 'get_device_config' failed with traceback:
Traceback (most recent call last):
  File "/home/majid/.local/lib/python3.10/site-packages/nornir/core/task.py", line 99, in start
    r = self.task(self, **self.params)
  File "/home/majid/devnet/pyhton_nornir/13.netconf/13.netconf.py", line 12, in get_device_config
    task.run(task=netconf_get_config, source="running", filter_type="xpath", filter_="/ios:native")
  File "/home/majid/.local/lib/python3.10/site-packages/nornir/core/task.py", line 174, in run
    raise NornirSubTaskError(task=run_task, result=r)
nornir.core.exceptions.NornirSubTaskError: Subtask: netconf_get_config (failed)


2022-07-24 20:38:48,627 -  nornir.core -     INFO -        run() - Running task 'get_device_config' with args {} on 1 hosts
2022-07-24 20:38:49,444 - nornir.core.task -    ERROR -      start() - Host 'R1': task 'get_device_config' failed with traceback:
Traceback (most recent call last):
  File "/home/majid/.local/lib/python3.10/site-packages/nornir/core/task.py", line 99, in start
    r = self.task(self, **self.params)
  File "/home/majid/devnet/pyhton_nornir/13.netconf/13.netconf.py", line 12, in get_device_config
    task.run(task=netconf_get_config, source="running", filter_type="xpath", filter_="/ios:native/ios:ntp:")
  File "/home/majid/.local/lib/python3.10/site-packages/nornir/core/task.py", line 174, in run
    raise NornirSubTaskError(task=run_task, result=r)
nornir.core.exceptions.NornirSubTaskError: Subtask: netconf_get_config (failed)


2022-07-24 20:39:26,296 -  nornir.core -     INFO -        run() - Running task 'get_device_config' with args {} on 1 hosts
2022-07-24 20:39:26,982 - nornir.core.task -    ERROR -      start() - Host 'R1': task 'get_device_config' failed with traceback:
Traceback (most recent call last):
  File "/home/majid/.local/lib/python3.10/site-packages/nornir/core/task.py", line 99, in start
    r = self.task(self, **self.params)
  File "/home/majid/devnet/pyhton_nornir/13.netconf/13.netconf.py", line 12, in get_device_config
    task.run(task=netconf_get_config, source="running", filter_type="xpath", filter_="/ios:native/ios:ntp")
  File "/home/majid/.local/lib/python3.10/site-packages/nornir/core/task.py", line 174, in run
    raise NornirSubTaskError(task=run_task, result=r)
nornir.core.exceptions.NornirSubTaskError: Subtask: netconf_get_config (failed)


2022-07-24 20:39:47,264 -  nornir.core -     INFO -        run() - Running task 'get_device_config' with args {} on 1 hosts
2022-07-25 00:32:00,287 -  nornir.core -     INFO -        run() - Running task 'get_device_config' with args {} on 1 hosts
2022-07-25 00:33:00,328 -  nornir.core -     INFO -        run() - Running task 'get_device_config' with args {} on 1 hosts
2022-07-25 00:33:43,274 -  nornir.core -     INFO -        run() - Running task 'get_device_config' with args {} on 1 hosts
2022-07-25 00:38:02,416 -  nornir.core -     INFO -        run() - Running task 'get_device_config' with args {} on 1 hosts
2022-07-25 00:38:35,503 -  nornir.core -     INFO -        run() - Running task 'get_device_config' with args {} on 1 hosts
2022-07-25 00:38:35,504 - nornir.core.task -    ERROR -      start() - Host 'R1': task 'get_device_config' failed with traceback:
Traceback (most recent call last):
  File "/home/majid/.local/lib/python3.10/site-packages/nornir/core/task.py", line 99, in start
    r = self.task(self, **self.params)
  File "/home/majid/devnet/pyhton_nornir/13.netconf/13.netconf.py", line 12, in get_device_config
    task.run(task=netconf_get, source="running", filter_type="xpath", filter_="//ntp-date-and-time")
NameError: name 'netconf_get' is not defined

2022-07-25 00:39:11,178 -  nornir.core -     INFO -        run() - Running task 'get_device_config' with args {} on 1 hosts
2022-07-25 00:39:11,179 - nornir.core.task -    ERROR -      start() - Host 'R1': task 'netconf_get' failed with traceback:
Traceback (most recent call last):
  File "/home/majid/.local/lib/python3.10/site-packages/nornir/core/task.py", line 99, in start
    r = self.task(self, **self.params)
TypeError: netconf_get() got an unexpected keyword argument 'source'

2022-07-25 00:39:11,179 - nornir.core.task -    ERROR -      start() - Host 'R1': task 'get_device_config' failed with traceback:
Traceback (most recent call last):
  File "/home/majid/.local/lib/python3.10/site-packages/nornir/core/task.py", line 99, in start
    r = self.task(self, **self.params)
  File "/home/majid/devnet/pyhton_nornir/13.netconf/13.netconf.py", line 14, in get_device_config
    task.run(task=netconf_get, source="running", filter_type="xpath", filter_="//ntp-date-and-time")
  File "/home/majid/.local/lib/python3.10/site-packages/nornir/core/task.py", line 174, in run
    raise NornirSubTaskError(task=run_task, result=r)
nornir.core.exceptions.NornirSubTaskError: Subtask: netconf_get (failed)


2022-07-25 00:39:31,383 -  nornir.core -     INFO -        run() - Running task 'get_device_config' with args {} on 1 hosts
2022-07-25 00:40:28,951 -  nornir.core -     INFO -        run() - Running task 'get_device_config' with args {} on 1 hosts
2022-07-25 00:44:22,297 -  nornir.core -     INFO -        run() - Running task 'get_device_config' with args {} on 1 hosts
2022-07-25 00:46:52,902 -  nornir.core -     INFO -        run() - Running task 'get_device_config' with args {} on 1 hosts
2022-07-25 00:47:58,264 -  nornir.core -     INFO -        run() - Running task 'get_device_config' with args {} on 1 hosts
2022-07-25 00:47:59,074 - nornir.core.task -    ERROR -      start() - Host 'R1': task 'get_device_config' failed with traceback:
Traceback (most recent call last):
  File "/home/majid/.local/lib/python3.10/site-packages/nornir/core/task.py", line 99, in start
    r = self.task(self, **self.params)
  File "/home/majid/devnet/pyhton_nornir/13.netconf/13.netconf.py", line 14, in get_device_config
    task.run(task=netconf_get_config, source="running", filter_type="xpath", filter_="/native/interface/GigabitEthernet/ip/ios-ospf:router-ospf/ios-ospf:ospf/ios-ospf:process-id/ios-ospf:area/ios-ospf:area-id")
  File "/home/majid/.local/lib/python3.10/site-packages/nornir/core/task.py", line 174, in run
    raise NornirSubTaskError(task=run_task, result=r)
nornir.core.exceptions.NornirSubTaskError: Subtask: netconf_get_config (failed)


2022-07-25 00:48:47,070 -  nornir.core -     INFO -        run() - Running task 'get_device_config' with args {} on 1 hosts
2022-07-25 00:56:01,462 -  nornir.core -     INFO -        run() - Running task 'get_device_config' with args {} on 1 hosts
2022-08-06 20:59:54,420 -  nornir.core -     INFO -        run() - Running task 'get_device_config' with args {} on 1 hosts
2022-08-06 21:07:37,165 -  nornir.core -     INFO -        run() - Running task 'get_device_config' with args {} on 1 hosts
2022-08-06 23:19:38,286 -  nornir.core -     INFO -        run() - Running task 'get_device_config' with args {} on 1 hosts
2022-08-07 00:00:52,437 -  nornir.core -     INFO -        run() - Running task 'get_config' with args {} on 1 hosts
2022-08-07 00:17:06,297 -  nornir.core -     INFO -        run() - Running task 'get_config' with args {} on 1 hosts
2022-08-07 00:17:30,576 -  nornir.core -     INFO -        run() - Running task 'get_config' with args {} on 1 hosts
2022-08-07 00:17:31,262 - nornir.core.task -    ERROR -      start() - Host 'R1': task 'get_config' failed with traceback:
Traceback (most recent call last):
  File "/home/majid/.local/lib/python3.10/site-packages/nornir/core/task.py", line 99, in start
    r = self.task(self, **self.params)
  File "/home/majid/devnet/pyhton_nornir/13.netconf/13.1.netconf_get_config.py", line 8, in get_config
    task.run(task=netconf_get_config, source="startup")
  File "/home/majid/.local/lib/python3.10/site-packages/nornir/core/task.py", line 174, in run
    raise NornirSubTaskError(task=run_task, result=r)
nornir.core.exceptions.NornirSubTaskError: Subtask: netconf_get_config (failed)


2022-08-07 00:17:55,177 -  nornir.core -     INFO -        run() - Running task 'get_config' with args {} on 1 hosts
2022-08-07 00:22:40,066 -  nornir.core -     INFO -        run() - Running task 'get_config' with args {} on 1 hosts
2022-08-09 20:13:18,539 -  nornir.core -     INFO -        run() - Running task 'get_config' with args {} on 1 hosts
2022-08-09 20:13:18,551 - nornir.core.task -    ERROR -      start() - Host 'R1': task 'netconf_get_config' failed with traceback:
Traceback (most recent call last):
  File "/home/majid/.local/lib/python3.10/site-packages/nornir/core/task.py", line 99, in start
    r = self.task(self, **self.params)
  File "/home/majid/.local/lib/python3.10/site-packages/nornir_netconf/plugins/tasks/retrieval/netconf_get_config.py", line 49, in netconf_get_config
    manager = task.host.get_connection(CONNECTION_NAME, task.nornir.config)
  File "/home/majid/.local/lib/python3.10/site-packages/nornir/core/inventory.py", line 494, in get_connection
    self.open_connection(
  File "/home/majid/.local/lib/python3.10/site-packages/nornir/core/inventory.py", line 546, in open_connection
    conn_obj.open(
  File "/home/majid/.local/lib/python3.10/site-packages/nornir_netconf/plugins/connections/netconf.py", line 116, in open
    self.connection = manager.connect_ssh(**parameters)  # pylint: disable=W0201
  File "/home/majid/.local/lib/python3.10/site-packages/ncclient/manager.py", line 135, in connect_ssh
    device_handler = make_device_handler(device_params)
  File "/home/majid/.local/lib/python3.10/site-packages/ncclient/manager.py", line 83, in make_device_handler
    dev_module_obj      = __import__(devices_module_name)
ModuleNotFoundError: No module named 'ncclient.devices.ios'

2022-08-09 20:13:18,551 - nornir.core.task -    ERROR -      start() - Host 'R1': task 'get_config' failed with traceback:
Traceback (most recent call last):
  File "/home/majid/.local/lib/python3.10/site-packages/nornir/core/task.py", line 99, in start
    r = self.task(self, **self.params)
  File "/home/majid/devnet/pyhton_nornir/13.netconf/13.1.netconf_get_config.py", line 9, in get_config
    task.run(task=netconf_get_config, source="running")
  File "/home/majid/.local/lib/python3.10/site-packages/nornir/core/task.py", line 174, in run
    raise NornirSubTaskError(task=run_task, result=r)
nornir.core.exceptions.NornirSubTaskError: Subtask: netconf_get_config (failed)


2022-08-09 20:18:04,288 -  nornir.core -     INFO -        run() - Running task 'get_config' with args {} on 1 hosts
2022-08-09 20:18:04,290 - nornir.core.task -    ERROR -      start() - Host 'R1': task 'netconf_get_config' failed with traceback:
Traceback (most recent call last):
  File "/home/majid/.local/lib/python3.10/site-packages/nornir/core/task.py", line 99, in start
    r = self.task(self, **self.params)
  File "/home/majid/.local/lib/python3.10/site-packages/nornir_netconf/plugins/tasks/retrieval/netconf_get_config.py", line 49, in netconf_get_config
    manager = task.host.get_connection(CONNECTION_NAME, task.nornir.config)
  File "/home/majid/.local/lib/python3.10/site-packages/nornir/core/inventory.py", line 494, in get_connection
    self.open_connection(
  File "/home/majid/.local/lib/python3.10/site-packages/nornir/core/inventory.py", line 546, in open_connection
    conn_obj.open(
  File "/home/majid/.local/lib/python3.10/site-packages/nornir_netconf/plugins/connections/netconf.py", line 116, in open
    self.connection = manager.connect_ssh(**parameters)  # pylint: disable=W0201
  File "/home/majid/.local/lib/python3.10/site-packages/ncclient/manager.py", line 135, in connect_ssh
    device_handler = make_device_handler(device_params)
  File "/home/majid/.local/lib/python3.10/site-packages/ncclient/manager.py", line 83, in make_device_handler
    dev_module_obj      = __import__(devices_module_name)
ModuleNotFoundError: No module named 'ncclient.devices.ios'

2022-08-09 20:18:04,291 - nornir.core.task -    ERROR -      start() - Host 'R1': task 'get_config' failed with traceback:
Traceback (most recent call last):
  File "/home/majid/.local/lib/python3.10/site-packages/nornir/core/task.py", line 99, in start
    r = self.task(self, **self.params)
  File "/home/majid/devnet/pyhton_nornir/13.netconf/13.1.netconf_get_config.py", line 10, in get_config
    task.run(task=netconf_get_config)
  File "/home/majid/.local/lib/python3.10/site-packages/nornir/core/task.py", line 174, in run
    raise NornirSubTaskError(task=run_task, result=r)
nornir.core.exceptions.NornirSubTaskError: Subtask: netconf_get_config (failed)


2022-08-09 20:28:51,001 -  nornir.core -     INFO -        run() - Running task 'get_config' with args {} on 1 hosts
2022-08-09 20:29:54,784 -  nornir.core -     INFO -        run() - Running task 'get_config' with args {} on 1 hosts
2022-08-09 20:31:09,181 -  nornir.core -     INFO -        run() - Running task 'get_config' with args {} on 1 hosts
2022-08-09 20:32:04,271 -  nornir.core -     INFO -        run() - Running task 'get_config' with args {} on 1 hosts
2022-08-09 20:33:27,743 -  nornir.core -     INFO -        run() - Running task 'get_config' with args {} on 1 hosts
2022-08-09 20:34:10,157 -  nornir.core -     INFO -        run() - Running task 'get_config' with args {} on 1 hosts
2022-08-09 20:34:29,499 -  nornir.core -     INFO -        run() - Running task 'get_config' with args {} on 1 hosts
2022-08-09 20:36:34,872 -  nornir.core -     INFO -        run() - Running task 'get_config' with args {} on 1 hosts
2022-08-09 20:37:07,986 -  nornir.core -     INFO -        run() - Running task 'get_config' with args {} on 1 hosts
2022-08-09 20:37:22,513 -  nornir.core -     INFO -        run() - Running task 'get_config' with args {} on 1 hosts
2022-08-09 20:38:35,685 -  nornir.core -     INFO -        run() - Running task 'get_config' with args {} on 1 hosts
2022-08-09 20:38:52,218 -  nornir.core -     INFO -        run() - Running task 'get_config' with args {} on 1 hosts
2022-08-09 20:43:27,281 -  nornir.core -     INFO -        run() - Running task 'get_config' with args {} on 1 hosts
2022-08-09 20:48:01,848 -  nornir.core -     INFO -        run() - Running task 'get_config' with args {} on 1 hosts
2022-08-09 20:48:44,488 -  nornir.core -     INFO -        run() - Running task 'get_config' with args {} on 1 hosts
2022-08-09 21:12:35,241 -  nornir.core -     INFO -        run() - Running task 'get_config' with args {} on 1 hosts
2022-08-09 21:23:48,584 -  nornir.core -     INFO -        run() - Running task 'get_config' with args {} on 1 hosts
2022-08-09 21:24:32,911 -  nornir.core -     INFO -        run() - Running task 'get_config' with args {} on 1 hosts
2022-08-09 21:24:33,617 - nornir.core.task -    ERROR -      start() - Host 'R1': task 'get_config' failed with traceback:
Traceback (most recent call last):
  File "/home/majid/.local/lib/python3.10/site-packages/nornir/core/task.py", line 99, in start
    r = self.task(self, **self.params)
  File "/home/majid/devnet/pyhton_nornir/13.netconf/13.2.netconf_xpath_filter.py", line 9, in get_config
    task.run(task=netconf_get_config, filter_type="xpath", filter_="/native/router/ios-ospf:router-ospf/")
  File "/home/majid/.local/lib/python3.10/site-packages/nornir/core/task.py", line 174, in run
    raise NornirSubTaskError(task=run_task, result=r)
nornir.core.exceptions.NornirSubTaskError: Subtask: netconf_get_config (failed)


2022-08-09 21:24:53,312 -  nornir.core -     INFO -        run() - Running task 'get_config' with args {} on 1 hosts
2022-08-09 21:24:53,979 - nornir.core.task -    ERROR -      start() - Host 'R1': task 'get_config' failed with traceback:
Traceback (most recent call last):
  File "/home/majid/.local/lib/python3.10/site-packages/nornir/core/task.py", line 99, in start
    r = self.task(self, **self.params)
  File "/home/majid/devnet/pyhton_nornir/13.netconf/13.2.netconf_xpath_filter.py", line 9, in get_config
    task.run(task=netconf_get_config, filter_type="xpath", filter_="/native/router/router-ospf/")
  File "/home/majid/.local/lib/python3.10/site-packages/nornir/core/task.py", line 174, in run
    raise NornirSubTaskError(task=run_task, result=r)
nornir.core.exceptions.NornirSubTaskError: Subtask: netconf_get_config (failed)


2022-08-09 21:25:13,703 -  nornir.core -     INFO -        run() - Running task 'get_config' with args {} on 1 hosts
2022-08-09 21:25:35,779 -  nornir.core -     INFO -        run() - Running task 'get_config' with args {} on 1 hosts
2022-08-09 21:28:46,796 -  nornir.core -     INFO -        run() - Running task 'get_config' with args {} on 1 hosts
2022-08-09 21:29:07,498 -  nornir.core -     INFO -        run() - Running task 'get_config' with args {} on 1 hosts
2022-08-09 21:29:22,877 -  nornir.core -     INFO -        run() - Running task 'get_config' with args {} on 1 hosts
2022-08-09 21:29:35,467 -  nornir.core -     INFO -        run() - Running task 'get_config' with args {} on 1 hosts
2022-08-09 21:33:46,242 -  nornir.core -     INFO -        run() - Running task 'get_config' with args {} on 1 hosts
2022-08-09 21:33:46,243 - nornir.core.task -    ERROR -      start() - Host 'R1': task 'netconf_get_config' failed with traceback:
Traceback (most recent call last):
  File "/home/majid/.local/lib/python3.10/site-packages/nornir/core/task.py", line 99, in start
    r = self.task(self, **self.params)
TypeError: netconf_get_config() got an unexpected keyword argument 'filter_'

2022-08-09 21:33:46,244 - nornir.core.task -    ERROR -      start() - Host 'R1': task 'get_config' failed with traceback:
Traceback (most recent call last):
  File "/home/majid/.local/lib/python3.10/site-packages/nornir/core/task.py", line 99, in start
    r = self.task(self, **self.params)
  File "/home/majid/devnet/pyhton_nornir/13.netconf/13.2.netconf_xpath_filter.py", line 14, in get_config
    task.run(task=netconf_get_config, source="running", xmldict="false", filter_type="xpath", filter_="/native")
  File "/home/majid/.local/lib/python3.10/site-packages/nornir/core/task.py", line 174, in run
    raise NornirSubTaskError(task=run_task, result=r)
nornir.core.exceptions.NornirSubTaskError: Subtask: netconf_get_config (failed)


2022-08-09 21:34:01,153 -  nornir.core -     INFO -        run() - Running task 'get_config' with args {} on 1 hosts
2022-08-09 21:34:01,155 - nornir.core.task -    ERROR -      start() - Host 'R1': task 'netconf_get_config' failed with traceback:
Traceback (most recent call last):
  File "/home/majid/.local/lib/python3.10/site-packages/nornir/core/task.py", line 99, in start
    r = self.task(self, **self.params)
TypeError: netconf_get_config() got an unexpected keyword argument 'filter'

2022-08-09 21:34:01,155 - nornir.core.task -    ERROR -      start() - Host 'R1': task 'get_config' failed with traceback:
Traceback (most recent call last):
  File "/home/majid/.local/lib/python3.10/site-packages/nornir/core/task.py", line 99, in start
    r = self.task(self, **self.params)
  File "/home/majid/devnet/pyhton_nornir/13.netconf/13.2.netconf_xpath_filter.py", line 14, in get_config
    task.run(task=netconf_get_config, source="running", xmldict="false", filter_type="xpath", filter="/native")
  File "/home/majid/.local/lib/python3.10/site-packages/nornir/core/task.py", line 174, in run
    raise NornirSubTaskError(task=run_task, result=r)
nornir.core.exceptions.NornirSubTaskError: Subtask: netconf_get_config (failed)


2022-08-09 21:34:33,383 -  nornir.core -     INFO -        run() - Running task 'get_config' with args {} on 1 hosts
2022-08-09 21:35:35,649 -  nornir.core -     INFO -        run() - Running task 'get_config' with args {} on 1 hosts
2022-08-09 21:35:58,392 -  nornir.core -     INFO -        run() - Running task 'get_config' with args {} on 1 hosts
2022-08-09 21:36:24,636 -  nornir.core -     INFO -        run() - Running task 'get_config' with args {} on 1 hosts
2022-08-09 22:01:48,310 -  nornir.core -     INFO -        run() - Running task 'get_config' with args {} on 1 hosts
2022-08-09 22:02:42,667 -  nornir.core -     INFO -        run() - Running task 'get_config' with args {} on 1 hosts
2022-08-09 22:03:29,374 -  nornir.core -     INFO -        run() - Running task 'get_config' with args {} on 1 hosts
2022-08-09 22:04:25,481 -  nornir.core -     INFO -        run() - Running task 'get_config' with args {} on 1 hosts
2022-08-10 00:39:19,907 -  nornir.core -     INFO -        run() - Running task 'get_config' with args {} on 1 hosts
2022-08-10 00:54:51,109 -  nornir.core -     INFO -        run() - Running task 'netconf_xpath' with args {} on 1 hosts
2022-08-10 01:01:20,497 -  nornir.core -     INFO -        run() - Running task 'netconf_xpath' with args {} on 1 hosts
2022-08-10 01:02:02,372 -  nornir.core -     INFO -        run() - Running task 'netconf_xpath' with args {} on 1 hosts
2022-08-10 01:02:53,727 -  nornir.core -     INFO -        run() - Running task 'netconf_xpath' with args {} on 1 hosts
2022-08-10 01:04:47,327 -  nornir.core -     INFO -        run() - Running task 'netconf_xpath' with args {} on 1 hosts
2022-08-10 01:06:14,509 -  nornir.core -     INFO -        run() - Running task 'netconf_xpath' with args {} on 1 hosts
2022-08-10 01:06:41,490 -  nornir.core -     INFO -        run() - Running task 'netconf_xpath' with args {} on 1 hosts
2022-08-10 01:07:08,205 -  nornir.core -     INFO -        run() - Running task 'netconf_xpath' with args {} on 1 hosts
2022-08-10 01:07:34,179 -  nornir.core -     INFO -        run() - Running task 'netconf_xpath' with args {} on 1 hosts
2022-08-10 01:09:11,471 -  nornir.core -     INFO -        run() - Running task 'netconf_xpath' with args {} on 1 hosts
2022-08-10 01:10:18,102 -  nornir.core -     INFO -        run() - Running task 'netconf_xpath' with args {} on 1 hosts
2022-08-10 01:12:07,544 -  nornir.core -     INFO -        run() - Running task 'netconf_xpath' with args {} on 1 hosts
2022-08-10 01:13:07,246 -  nornir.core -     INFO -        run() - Running task 'netconf_xpath' with args {} on 1 hosts
2022-08-10 01:13:31,580 -  nornir.core -     INFO -        run() - Running task 'netconf_xpath' with args {} on 1 hosts
2022-08-10 01:38:04,990 -  nornir.core -     INFO -        run() - Running task 'netconf_xpath_get' with args {} on 1 hosts
2022-08-10 01:38:04,991 - nornir.core.task -    ERROR -      start() - Host 'R1': task 'netconf_get' failed with traceback:
Traceback (most recent call last):
  File "/home/majid/.local/lib/python3.10/site-packages/nornir/core/task.py", line 99, in start
    r = self.task(self, **self.params)
TypeError: netconf_get() got an unexpected keyword argument 'source'

2022-08-10 01:38:04,991 - nornir.core.task -    ERROR -      start() - Host 'R1': task 'netconf_xpath_get' failed with traceback:
Traceback (most recent call last):
  File "/home/majid/.local/lib/python3.10/site-packages/nornir/core/task.py", line 99, in start
    r = self.task(self, **self.params)
  File "/home/majid/devnet/pyhton_nornir/13.netconf/13.3.netconf_xpath_filter_get.py", line 9, in netconf_xpath_get
    task.run(task=netconf_get, source="running", filter_type="xpath", filter_="//neighbor")
  File "/home/majid/.local/lib/python3.10/site-packages/nornir/core/task.py", line 174, in run
    raise NornirSubTaskError(task=run_task, result=r)
nornir.core.exceptions.NornirSubTaskError: Subtask: netconf_get (failed)


2022-08-10 01:38:28,797 -  nornir.core -     INFO -        run() - Running task 'netconf_xpath_get' with args {} on 1 hosts
2022-08-10 01:39:34,080 -  nornir.core -     INFO -        run() - Running task 'netconf_xpath_get' with args {} on 1 hosts
2022-08-10 01:40:29,245 -  nornir.core -     INFO -        run() - Running task 'netconf_xpath_get' with args {} on 1 hosts
2022-08-10 01:41:12,174 -  nornir.core -     INFO -        run() - Running task 'netconf_xpath_get' with args {} on 1 hosts
2022-08-10 01:44:14,805 -  nornir.core -     INFO -        run() - Running task 'netconf_xpath_get' with args {} on 1 hosts
2022-08-10 01:45:20,627 -  nornir.core -     INFO -        run() - Running task 'netconf_xpath_get' with args {} on 1 hosts
2022-08-10 01:47:28,669 -  nornir.core -     INFO -        run() - Running task 'netconf_xpath_get' with args {} on 1 hosts
2022-08-10 02:04:00,272 -  nornir.core -     INFO -        run() - Running task 'netconf_xpath_get' with args {} on 1 hosts
2022-08-10 02:05:17,704 -  nornir.core -     INFO -        run() - Running task 'netconf_xpath_get' with args {} on 1 hosts
2022-08-10 02:06:14,500 -  nornir.core -     INFO -        run() - Running task 'netconf_xpath_get' with args {} on 1 hosts
2022-08-10 02:06:56,073 -  nornir.core -     INFO -        run() - Running task 'netconf_xpath_get' with args {} on 1 hosts
2022-08-12 22:39:44,102 -  nornir.core -     INFO -        run() - Running task 'netconf_xpath' with args {} on 1 hosts
2022-08-12 22:39:56,532 -  nornir.core -     INFO -        run() - Running task 'netconf_xpath' with args {} on 1 hosts
2022-08-12 22:47:27,719 -  nornir.core -     INFO -        run() - Running task 'netconf_xpath' with args {} on 1 hosts
2022-08-12 22:47:27,720 - nornir.core.task -    ERROR -      start() - Host 'R1': task 'netconf_get_config' failed with traceback:
Traceback (most recent call last):
  File "/home/majid/.local/lib/python3.10/site-packages/nornir/core/task.py", line 99, in start
    r = self.task(self, **self.params)
TypeError: netconf_get_config() got an unexpected keyword argument 'filters'

2022-08-12 22:47:27,720 - nornir.core.task -    ERROR -      start() - Host 'R1': task 'netconf_xpath' failed with traceback:
Traceback (most recent call last):
  File "/home/majid/.local/lib/python3.10/site-packages/nornir/core/task.py", line 99, in start
    r = self.task(self, **self.params)
  File "/home/majid/devnet/pyhton_nornir/13.netconf/13.4.netconf_subtree_filter.py", line 14, in netconf_xpath
    task.run(task=netconf_get_config, source="running", filter_type="subtree", filters="filter1")
  File "/home/majid/.local/lib/python3.10/site-packages/nornir/core/task.py", line 174, in run
    raise NornirSubTaskError(task=run_task, result=r)
nornir.core.exceptions.NornirSubTaskError: Subtask: netconf_get_config (failed)


2022-08-12 22:48:58,067 -  nornir.core -     INFO -        run() - Running task 'netconf_xpath' with args {} on 1 hosts
2022-08-12 22:48:58,785 - nornir.core.task -    ERROR -      start() - Host 'R1': task 'netconf_get_config' failed with traceback:
Traceback (most recent call last):
  File "/home/majid/.local/lib/python3.10/site-packages/nornir/core/task.py", line 99, in start
    r = self.task(self, **self.params)
  File "/home/majid/.local/lib/python3.10/site-packages/nornir_scrapli/tasks/netconf/get_config.py", line 32, in netconf_get_config
    scrapli_response = scrapli_conn.get_config(
  File "/home/majid/.local/lib/python3.10/site-packages/scrapli_netconf/driver/sync_driver.py", line 172, in get_config
    response = self._pre_get_config(
  File "/home/majid/.local/lib/python3.10/site-packages/scrapli_netconf/driver/base_driver.py", line 659, in _pre_get_config
    xml_filter_elem = self._build_filter(filter_=filter_, filter_type=filter_type)
  File "/home/majid/.local/lib/python3.10/site-packages/scrapli_netconf/driver/base_driver.py", line 469, in _build_filter
    if tmp_xml_filter_element.getchildren()[0].tag == "filter":
IndexError: list index out of range

2022-08-12 22:48:58,786 - nornir.core.task -    ERROR -      start() - Host 'R1': task 'netconf_xpath' failed with traceback:
Traceback (most recent call last):
  File "/home/majid/.local/lib/python3.10/site-packages/nornir/core/task.py", line 99, in start
    r = self.task(self, **self.params)
  File "/home/majid/devnet/pyhton_nornir/13.netconf/13.4.netconf_subtree_filter.py", line 14, in netconf_xpath
    task.run(task=netconf_get_config, source="running", filter_type="subtree", filter_="filter1")
  File "/home/majid/.local/lib/python3.10/site-packages/nornir/core/task.py", line 174, in run
    raise NornirSubTaskError(task=run_task, result=r)
nornir.core.exceptions.NornirSubTaskError: Subtask: netconf_get_config (failed)


2022-08-12 22:50:03,369 -  nornir.core -     INFO -        run() - Running task 'netconf_xpath' with args {} on 1 hosts
2022-08-12 22:50:04,071 - nornir.core.task -    ERROR -      start() - Host 'R1': task 'netconf_get_config' failed with traceback:
Traceback (most recent call last):
  File "/home/majid/.local/lib/python3.10/site-packages/nornir/core/task.py", line 99, in start
    r = self.task(self, **self.params)
  File "/home/majid/.local/lib/python3.10/site-packages/nornir_scrapli/tasks/netconf/get_config.py", line 32, in netconf_get_config
    scrapli_response = scrapli_conn.get_config(
  File "/home/majid/.local/lib/python3.10/site-packages/scrapli_netconf/driver/sync_driver.py", line 172, in get_config
    response = self._pre_get_config(
  File "/home/majid/.local/lib/python3.10/site-packages/scrapli_netconf/driver/base_driver.py", line 659, in _pre_get_config
    xml_filter_elem = self._build_filter(filter_=filter_, filter_type=filter_type)
  File "/home/majid/.local/lib/python3.10/site-packages/scrapli_netconf/driver/base_driver.py", line 469, in _build_filter
    if tmp_xml_filter_element.getchildren()[0].tag == "filter":
IndexError: list index out of range

2022-08-12 22:50:04,072 - nornir.core.task -    ERROR -      start() - Host 'R1': task 'netconf_xpath' failed with traceback:
Traceback (most recent call last):
  File "/home/majid/.local/lib/python3.10/site-packages/nornir/core/task.py", line 99, in start
    r = self.task(self, **self.params)
  File "/home/majid/devnet/pyhton_nornir/13.netconf/13.4.netconf_subtree_filter.py", line 16, in netconf_xpath
    task.run(task=netconf_get_config, source="running", filter_type="subtree", filter_="filter1")
  File "/home/majid/.local/lib/python3.10/site-packages/nornir/core/task.py", line 174, in run
    raise NornirSubTaskError(task=run_task, result=r)
nornir.core.exceptions.NornirSubTaskError: Subtask: netconf_get_config (failed)


2022-08-12 22:50:16,907 -  nornir.core -     INFO -        run() - Running task 'netconf_xpath' with args {} on 1 hosts
2022-08-12 22:50:17,573 - nornir.core.task -    ERROR -      start() - Host 'R1': task 'netconf_get_config' failed with traceback:
Traceback (most recent call last):
  File "/home/majid/.local/lib/python3.10/site-packages/nornir/core/task.py", line 99, in start
    r = self.task(self, **self.params)
  File "/home/majid/.local/lib/python3.10/site-packages/nornir_scrapli/tasks/netconf/get_config.py", line 32, in netconf_get_config
    scrapli_response = scrapli_conn.get_config(
  File "/home/majid/.local/lib/python3.10/site-packages/scrapli_netconf/driver/sync_driver.py", line 172, in get_config
    response = self._pre_get_config(
  File "/home/majid/.local/lib/python3.10/site-packages/scrapli_netconf/driver/base_driver.py", line 659, in _pre_get_config
    xml_filter_elem = self._build_filter(filter_=filter_, filter_type=filter_type)
  File "/home/majid/.local/lib/python3.10/site-packages/scrapli_netconf/driver/base_driver.py", line 469, in _build_filter
    if tmp_xml_filter_element.getchildren()[0].tag == "filter":
IndexError: list index out of range

2022-08-12 22:50:17,574 - nornir.core.task -    ERROR -      start() - Host 'R1': task 'netconf_xpath' failed with traceback:
Traceback (most recent call last):
  File "/home/majid/.local/lib/python3.10/site-packages/nornir/core/task.py", line 99, in start
    r = self.task(self, **self.params)
  File "/home/majid/devnet/pyhton_nornir/13.netconf/13.4.netconf_subtree_filter.py", line 14, in netconf_xpath
    task.run(task=netconf_get_config, source="running", filter_type="subtree", filter_="filter1")
  File "/home/majid/.local/lib/python3.10/site-packages/nornir/core/task.py", line 174, in run
    raise NornirSubTaskError(task=run_task, result=r)
nornir.core.exceptions.NornirSubTaskError: Subtask: netconf_get_config (failed)


2022-08-12 22:50:54,814 -  nornir.core -     INFO -        run() - Running task 'netconf_xpath' with args {} on 1 hosts
2022-08-12 22:50:54,815 - nornir.core.task -    ERROR -      start() - Host 'R1': task 'netconf_get_config' failed with traceback:
Traceback (most recent call last):
  File "/home/majid/.local/lib/python3.10/site-packages/nornir/core/task.py", line 99, in start
    r = self.task(self, **self.params)
TypeError: netconf_get_config() got an unexpected keyword argument 'filters'

2022-08-12 22:50:54,815 - nornir.core.task -    ERROR -      start() - Host 'R1': task 'netconf_xpath' failed with traceback:
Traceback (most recent call last):
  File "/home/majid/.local/lib/python3.10/site-packages/nornir/core/task.py", line 99, in start
    r = self.task(self, **self.params)
  File "/home/majid/devnet/pyhton_nornir/13.netconf/13.4.netconf_subtree_filter.py", line 14, in netconf_xpath
    task.run(task=netconf_get_config, source="running", filter_type="subtree", filters="filter1")
  File "/home/majid/.local/lib/python3.10/site-packages/nornir/core/task.py", line 174, in run
    raise NornirSubTaskError(task=run_task, result=r)
nornir.core.exceptions.NornirSubTaskError: Subtask: netconf_get_config (failed)


2022-08-12 22:51:11,950 -  nornir.core -     INFO -        run() - Running task 'netconf_xpath' with args {} on 1 hosts
2022-08-12 22:51:11,951 - nornir.core.task -    ERROR -      start() - Host 'R1': task 'netconf_get_config' failed with traceback:
Traceback (most recent call last):
  File "/home/majid/.local/lib/python3.10/site-packages/nornir/core/task.py", line 99, in start
    r = self.task(self, **self.params)
TypeError: netconf_get_config() got an unexpected keyword argument 'filter'

2022-08-12 22:51:11,951 - nornir.core.task -    ERROR -      start() - Host 'R1': task 'netconf_xpath' failed with traceback:
Traceback (most recent call last):
  File "/home/majid/.local/lib/python3.10/site-packages/nornir/core/task.py", line 99, in start
    r = self.task(self, **self.params)
  File "/home/majid/devnet/pyhton_nornir/13.netconf/13.4.netconf_subtree_filter.py", line 14, in netconf_xpath
    task.run(task=netconf_get_config, source="running", filter_type="subtree", filter="filter1")
  File "/home/majid/.local/lib/python3.10/site-packages/nornir/core/task.py", line 174, in run
    raise NornirSubTaskError(task=run_task, result=r)
nornir.core.exceptions.NornirSubTaskError: Subtask: netconf_get_config (failed)


2022-08-12 22:51:24,816 -  nornir.core -     INFO -        run() - Running task 'netconf_xpath' with args {} on 1 hosts
2022-08-12 22:51:25,504 - nornir.core.task -    ERROR -      start() - Host 'R1': task 'netconf_get_config' failed with traceback:
Traceback (most recent call last):
  File "/home/majid/.local/lib/python3.10/site-packages/nornir/core/task.py", line 99, in start
    r = self.task(self, **self.params)
  File "/home/majid/.local/lib/python3.10/site-packages/nornir_scrapli/tasks/netconf/get_config.py", line 32, in netconf_get_config
    scrapli_response = scrapli_conn.get_config(
  File "/home/majid/.local/lib/python3.10/site-packages/scrapli_netconf/driver/sync_driver.py", line 172, in get_config
    response = self._pre_get_config(
  File "/home/majid/.local/lib/python3.10/site-packages/scrapli_netconf/driver/base_driver.py", line 659, in _pre_get_config
    xml_filter_elem = self._build_filter(filter_=filter_, filter_type=filter_type)
  File "/home/majid/.local/lib/python3.10/site-packages/scrapli_netconf/driver/base_driver.py", line 469, in _build_filter
    if tmp_xml_filter_element.getchildren()[0].tag == "filter":
IndexError: list index out of range

2022-08-12 22:51:25,505 - nornir.core.task -    ERROR -      start() - Host 'R1': task 'netconf_xpath' failed with traceback:
Traceback (most recent call last):
  File "/home/majid/.local/lib/python3.10/site-packages/nornir/core/task.py", line 99, in start
    r = self.task(self, **self.params)
  File "/home/majid/devnet/pyhton_nornir/13.netconf/13.4.netconf_subtree_filter.py", line 14, in netconf_xpath
    task.run(task=netconf_get_config, source="running", filter_type="subtree", filter_="filter1")
  File "/home/majid/.local/lib/python3.10/site-packages/nornir/core/task.py", line 174, in run
    raise NornirSubTaskError(task=run_task, result=r)
nornir.core.exceptions.NornirSubTaskError: Subtask: netconf_get_config (failed)


2022-08-12 22:52:20,915 -  nornir.core -     INFO -        run() - Running task 'netconf_xpath' with args {} on 1 hosts
2022-08-12 22:52:21,584 - nornir.core.task -    ERROR -      start() - Host 'R1': task 'netconf_get_config' failed with traceback:
Traceback (most recent call last):
  File "/home/majid/.local/lib/python3.10/site-packages/nornir/core/task.py", line 99, in start
    r = self.task(self, **self.params)
  File "/home/majid/.local/lib/python3.10/site-packages/nornir_scrapli/tasks/netconf/get_config.py", line 32, in netconf_get_config
    scrapli_response = scrapli_conn.get_config(
  File "/home/majid/.local/lib/python3.10/site-packages/scrapli_netconf/driver/sync_driver.py", line 172, in get_config
    response = self._pre_get_config(
  File "/home/majid/.local/lib/python3.10/site-packages/scrapli_netconf/driver/base_driver.py", line 659, in _pre_get_config
    xml_filter_elem = self._build_filter(filter_=filter_, filter_type=filter_type)
  File "/home/majid/.local/lib/python3.10/site-packages/scrapli_netconf/driver/base_driver.py", line 469, in _build_filter
    if tmp_xml_filter_element.getchildren()[0].tag == "filter":
IndexError: list index out of range

2022-08-12 22:52:21,586 - nornir.core.task -    ERROR -      start() - Host 'R1': task 'netconf_xpath' failed with traceback:
Traceback (most recent call last):
  File "/home/majid/.local/lib/python3.10/site-packages/nornir/core/task.py", line 99, in start
    r = self.task(self, **self.params)
  File "/home/majid/devnet/pyhton_nornir/13.netconf/13.4.netconf_subtree_filter.py", line 14, in netconf_xpath
    task.run(task=netconf_get_config, source="running", filter_type="subtree", filter_="filt")
  File "/home/majid/.local/lib/python3.10/site-packages/nornir/core/task.py", line 174, in run
    raise NornirSubTaskError(task=run_task, result=r)
nornir.core.exceptions.NornirSubTaskError: Subtask: netconf_get_config (failed)


2022-08-12 23:03:18,001 -  nornir.core -     INFO -        run() - Running task 'netconf_xpath' with args {} on 1 hosts
2022-08-12 23:03:18,680 - nornir.core.task -    ERROR -      start() - Host 'R1': task 'netconf_get_config' failed with traceback:
Traceback (most recent call last):
  File "/home/majid/.local/lib/python3.10/site-packages/nornir/core/task.py", line 99, in start
    r = self.task(self, **self.params)
  File "/home/majid/.local/lib/python3.10/site-packages/nornir_scrapli/tasks/netconf/get_config.py", line 32, in netconf_get_config
    scrapli_response = scrapli_conn.get_config(
  File "/home/majid/.local/lib/python3.10/site-packages/scrapli_netconf/driver/sync_driver.py", line 172, in get_config
    response = self._pre_get_config(
  File "/home/majid/.local/lib/python3.10/site-packages/scrapli_netconf/driver/base_driver.py", line 659, in _pre_get_config
    xml_filter_elem = self._build_filter(filter_=filter_, filter_type=filter_type)
  File "/home/majid/.local/lib/python3.10/site-packages/scrapli_netconf/driver/base_driver.py", line 469, in _build_filter
    if tmp_xml_filter_element.getchildren()[0].tag == "filter":
IndexError: list index out of range

2022-08-12 23:03:18,681 - nornir.core.task -    ERROR -      start() - Host 'R1': task 'netconf_xpath' failed with traceback:
Traceback (most recent call last):
  File "/home/majid/.local/lib/python3.10/site-packages/nornir/core/task.py", line 99, in start
    r = self.task(self, **self.params)
  File "/home/majid/devnet/pyhton_nornir/13.netconf/13.4.netconf_subtree_filter.py", line 14, in netconf_xpath
    task.run(task=netconf_get_config, source="running", filter_type="subtree", filter_="filt")
  File "/home/majid/.local/lib/python3.10/site-packages/nornir/core/task.py", line 174, in run
    raise NornirSubTaskError(task=run_task, result=r)
nornir.core.exceptions.NornirSubTaskError: Subtask: netconf_get_config (failed)


2022-08-12 23:04:23,388 -  nornir.core -     INFO -        run() - Running task 'netconf_subtree' with args {} on 1 hosts
2022-08-12 23:04:24,049 - nornir.core.task -    ERROR -      start() - Host 'R1': task 'netconf_get_config' failed with traceback:
Traceback (most recent call last):
  File "/home/majid/.local/lib/python3.10/site-packages/nornir/core/task.py", line 99, in start
    r = self.task(self, **self.params)
  File "/home/majid/.local/lib/python3.10/site-packages/nornir_scrapli/tasks/netconf/get_config.py", line 32, in netconf_get_config
    scrapli_response = scrapli_conn.get_config(
  File "/home/majid/.local/lib/python3.10/site-packages/scrapli_netconf/driver/sync_driver.py", line 172, in get_config
    response = self._pre_get_config(
  File "/home/majid/.local/lib/python3.10/site-packages/scrapli_netconf/driver/base_driver.py", line 659, in _pre_get_config
    xml_filter_elem = self._build_filter(filter_=filter_, filter_type=filter_type)
  File "/home/majid/.local/lib/python3.10/site-packages/scrapli_netconf/driver/base_driver.py", line 469, in _build_filter
    if tmp_xml_filter_element.getchildren()[0].tag == "filter":
IndexError: list index out of range

2022-08-12 23:04:24,050 - nornir.core.task -    ERROR -      start() - Host 'R1': task 'netconf_subtree' failed with traceback:
Traceback (most recent call last):
  File "/home/majid/.local/lib/python3.10/site-packages/nornir/core/task.py", line 99, in start
    r = self.task(self, **self.params)
  File "/home/majid/devnet/pyhton_nornir/13.netconf/13.4.netconf_subtree_filter.py", line 14, in netconf_subtree
    task.run(task=netconf_get_config, source="running", filter_type="subtree", filter_="filt")
  File "/home/majid/.local/lib/python3.10/site-packages/nornir/core/task.py", line 174, in run
    raise NornirSubTaskError(task=run_task, result=r)
nornir.core.exceptions.NornirSubTaskError: Subtask: netconf_get_config (failed)


2022-08-12 23:07:22,974 -  nornir.core -     INFO -        run() - Running task 'netconf_subtree' with args {} on 1 hosts
2022-08-12 23:07:23,652 - nornir.core.task -    ERROR -      start() - Host 'R1': task 'netconf_get_config' failed with traceback:
Traceback (most recent call last):
  File "/home/majid/.local/lib/python3.10/site-packages/nornir/core/task.py", line 99, in start
    r = self.task(self, **self.params)
  File "/home/majid/.local/lib/python3.10/site-packages/nornir_scrapli/tasks/netconf/get_config.py", line 32, in netconf_get_config
    scrapli_response = scrapli_conn.get_config(
  File "/home/majid/.local/lib/python3.10/site-packages/scrapli_netconf/driver/sync_driver.py", line 172, in get_config
    response = self._pre_get_config(
  File "/home/majid/.local/lib/python3.10/site-packages/scrapli_netconf/driver/base_driver.py", line 659, in _pre_get_config
    xml_filter_elem = self._build_filter(filter_=filter_, filter_type=filter_type)
  File "/home/majid/.local/lib/python3.10/site-packages/scrapli_netconf/driver/base_driver.py", line 469, in _build_filter
    if tmp_xml_filter_element.getchildren()[0].tag == "filter":
IndexError: list index out of range

2022-08-12 23:07:23,653 - nornir.core.task -    ERROR -      start() - Host 'R1': task 'netconf_subtree' failed with traceback:
Traceback (most recent call last):
  File "/home/majid/.local/lib/python3.10/site-packages/nornir/core/task.py", line 99, in start
    r = self.task(self, **self.params)
  File "/home/majid/devnet/pyhton_nornir/13.netconf/13.4.netconf_subtree_filter.py", line 14, in netconf_subtree
    task.run(task=netconf_get_config, source="running", filter_type="subtree", filter_="filt")
  File "/home/majid/.local/lib/python3.10/site-packages/nornir/core/task.py", line 174, in run
    raise NornirSubTaskError(task=run_task, result=r)
nornir.core.exceptions.NornirSubTaskError: Subtask: netconf_get_config (failed)


2022-08-12 23:08:00,540 -  nornir.core -     INFO -        run() - Running task 'netconf_subtree' with args {} on 1 hosts
2022-08-12 23:08:00,541 - nornir.core.task -    ERROR -      start() - Host 'R1': task 'netconf_get_config' failed with traceback:
Traceback (most recent call last):
  File "/home/majid/.local/lib/python3.10/site-packages/nornir/core/task.py", line 99, in start
    r = self.task(self, **self.params)
TypeError: netconf_get_config() got an unexpected keyword argument 'filters'

2022-08-12 23:08:00,542 - nornir.core.task -    ERROR -      start() - Host 'R1': task 'netconf_subtree' failed with traceback:
Traceback (most recent call last):
  File "/home/majid/.local/lib/python3.10/site-packages/nornir/core/task.py", line 99, in start
    r = self.task(self, **self.params)
  File "/home/majid/devnet/pyhton_nornir/13.netconf/13.4.netconf_subtree_filter.py", line 14, in netconf_subtree
    task.run(task=netconf_get_config, source="running", filter_type="subtree", filters=filt)
  File "/home/majid/.local/lib/python3.10/site-packages/nornir/core/task.py", line 174, in run
    raise NornirSubTaskError(task=run_task, result=r)
nornir.core.exceptions.NornirSubTaskError: Subtask: netconf_get_config (failed)


2022-08-12 23:08:43,616 -  nornir.core -     INFO -        run() - Running task 'netconf_subtree' with args {} on 1 hosts
2022-08-12 23:09:25,111 -  nornir.core -     INFO -        run() - Running task 'netconf_subtree' with args {} on 1 hosts
2022-08-12 23:10:03,324 -  nornir.core -     INFO -        run() - Running task 'netconf_subtree' with args {} on 1 hosts
2022-08-12 23:10:23,228 -  nornir.core -     INFO -        run() - Running task 'netconf_subtree' with args {} on 1 hosts
2022-08-12 23:10:37,974 -  nornir.core -     INFO -        run() - Running task 'netconf_subtree' with args {} on 1 hosts
2022-08-12 23:13:33,074 -  nornir.core -     INFO -        run() - Running task 'netconf_subtree' with args {} on 1 hosts
2022-08-12 23:14:45,071 -  nornir.core -     INFO -        run() - Running task 'netconf_subtree' with args {} on 1 hosts
2022-08-12 23:16:33,944 -  nornir.core -     INFO -        run() - Running task 'netconf_subtree' with args {} on 1 hosts
2022-08-12 23:18:22,529 -  nornir.core -     INFO -        run() - Running task 'netconf_subtree' with args {} on 1 hosts
2022-08-12 23:19:26,916 -  nornir.core -     INFO -        run() - Running task 'netconf_xpath' with args {} on 1 hosts
2022-08-12 23:19:35,287 -  nornir.core -     INFO -        run() - Running task 'netconf_xpath' with args {} on 1 hosts
2022-08-12 23:23:43,824 -  nornir.core -     INFO -        run() - Running task 'netconf_subtree' with args {} on 1 hosts
2022-08-12 23:24:01,085 -  nornir.core -     INFO -        run() - Running task 'netconf_subtree' with args {} on 1 hosts
2022-08-12 23:25:00,448 -  nornir.core -     INFO -        run() - Running task 'netconf_subtree' with args {} on 1 hosts
2022-08-12 23:25:44,944 -  nornir.core -     INFO -        run() - Running task 'netconf_subtree' with args {} on 1 hosts
2022-08-12 23:28:15,931 -  nornir.core -     INFO -        run() - Running task 'netconf_subtree' with args {} on 1 hosts
2022-08-13 00:20:49,553 -  nornir.core -     INFO -        run() - Running task 'netconf_subtree' with args {} on 1 hosts
2022-08-13 00:22:11,387 -  nornir.core -     INFO -        run() - Running task 'netconf_subtree' with args {} on 1 hosts
2022-08-13 00:22:11,388 - nornir.core.task -    ERROR -      start() - Host 'R1': task 'netconf_get_config' failed with traceback:
Traceback (most recent call last):
  File "/home/majid/.local/lib/python3.10/site-packages/nornir/core/task.py", line 99, in start
    r = self.task(self, **self.params)
TypeError: netconf_get_config() got an unexpected keyword argument 'filter'

2022-08-13 00:22:11,389 - nornir.core.task -    ERROR -      start() - Host 'R1': task 'netconf_subtree' failed with traceback:
Traceback (most recent call last):
  File "/home/majid/.local/lib/python3.10/site-packages/nornir/core/task.py", line 99, in start
    r = self.task(self, **self.params)
  File "/home/majid/devnet/pyhton_nornir/13.netconf/13.4.netconf_subtree_filter.py", line 33, in netconf_subtree
    task.run(task=netconf_get_config, source="running", xmldict="false", filter_type="subtree", filter=filter3)
  File "/home/majid/.local/lib/python3.10/site-packages/nornir/core/task.py", line 174, in run
    raise NornirSubTaskError(task=run_task, result=r)
nornir.core.exceptions.NornirSubTaskError: Subtask: netconf_get_config (failed)


2022-08-13 00:22:27,217 -  nornir.core -     INFO -        run() - Running task 'netconf_subtree' with args {} on 1 hosts
2022-08-13 00:22:27,218 - nornir.core.task -    ERROR -      start() - Host 'R1': task 'netconf_get_config' failed with traceback:
Traceback (most recent call last):
  File "/home/majid/.local/lib/python3.10/site-packages/nornir/core/task.py", line 99, in start
    r = self.task(self, **self.params)
TypeError: netconf_get_config() got an unexpected keyword argument 'filter_'

2022-08-13 00:22:27,218 - nornir.core.task -    ERROR -      start() - Host 'R1': task 'netconf_subtree' failed with traceback:
Traceback (most recent call last):
  File "/home/majid/.local/lib/python3.10/site-packages/nornir/core/task.py", line 99, in start
    r = self.task(self, **self.params)
  File "/home/majid/devnet/pyhton_nornir/13.netconf/13.4.netconf_subtree_filter.py", line 33, in netconf_subtree
    task.run(task=netconf_get_config, source="running", xmldict="false", filter_type="subtree", filter_=filter3)
  File "/home/majid/.local/lib/python3.10/site-packages/nornir/core/task.py", line 174, in run
    raise NornirSubTaskError(task=run_task, result=r)
nornir.core.exceptions.NornirSubTaskError: Subtask: netconf_get_config (failed)


2022-08-13 00:22:45,210 -  nornir.core -     INFO -        run() - Running task 'netconf_subtree' with args {} on 1 hosts
2022-08-13 00:22:45,211 - nornir.core.task -    ERROR -      start() - Host 'R1': task 'netconf_get_config' failed with traceback:
Traceback (most recent call last):
  File "/home/majid/.local/lib/python3.10/site-packages/nornir/core/task.py", line 99, in start
    r = self.task(self, **self.params)
TypeError: netconf_get_config() got an unexpected keyword argument 'filter'

2022-08-13 00:22:45,211 - nornir.core.task -    ERROR -      start() - Host 'R1': task 'netconf_subtree' failed with traceback:
Traceback (most recent call last):
  File "/home/majid/.local/lib/python3.10/site-packages/nornir/core/task.py", line 99, in start
    r = self.task(self, **self.params)
  File "/home/majid/devnet/pyhton_nornir/13.netconf/13.4.netconf_subtree_filter.py", line 33, in netconf_subtree
    task.run(task=netconf_get_config, source="running", xmldict="false", filter_type="subtree", filter=filter3)
  File "/home/majid/.local/lib/python3.10/site-packages/nornir/core/task.py", line 174, in run
    raise NornirSubTaskError(task=run_task, result=r)
nornir.core.exceptions.NornirSubTaskError: Subtask: netconf_get_config (failed)


2022-08-13 00:23:05,043 -  nornir.core -     INFO -        run() - Running task 'netconf_subtree' with args {} on 1 hosts
2022-08-13 00:23:05,044 - nornir.core.task -    ERROR -      start() - Host 'R1': task 'netconf_get_config' failed with traceback:
Traceback (most recent call last):
  File "/home/majid/.local/lib/python3.10/site-packages/nornir/core/task.py", line 99, in start
    r = self.task(self, **self.params)
TypeError: netconf_get_config() got an unexpected keyword argument 'filters'

2022-08-13 00:23:05,044 - nornir.core.task -    ERROR -      start() - Host 'R1': task 'netconf_subtree' failed with traceback:
Traceback (most recent call last):
  File "/home/majid/.local/lib/python3.10/site-packages/nornir/core/task.py", line 99, in start
    r = self.task(self, **self.params)
  File "/home/majid/devnet/pyhton_nornir/13.netconf/13.4.netconf_subtree_filter.py", line 33, in netconf_subtree
    task.run(task=netconf_get_config, source="running", xmldict="false", filter_type="subtree", filters=filter3)
  File "/home/majid/.local/lib/python3.10/site-packages/nornir/core/task.py", line 174, in run
    raise NornirSubTaskError(task=run_task, result=r)
nornir.core.exceptions.NornirSubTaskError: Subtask: netconf_get_config (failed)


2022-08-13 00:24:24,495 -  nornir.core -     INFO -        run() - Running task 'netconf_subtree' with args {} on 1 hosts
2022-08-13 00:34:18,769 -  nornir.core -     INFO -        run() - Running task 'netconf_subtree_get_config' with args {} on 1 hosts
2022-08-13 00:36:05,051 -  nornir.core -     INFO -        run() - Running task 'netconf_subtree_get_config' with args {} on 1 hosts
2022-08-13 00:42:26,165 -  nornir.core -     INFO -        run() - Running task 'netconf_subtree_get' with args {} on 1 hosts
2022-08-13 00:44:34,554 -  nornir.core -     INFO -        run() - Running task 'netconf_subtree_get' with args {} on 1 hosts
2022-08-13 00:47:00,634 -  nornir.core -     INFO -        run() - Running task 'netconf_subtree_get' with args {} on 1 hosts
2022-08-13 00:47:23,646 -  nornir.core -     INFO -        run() - Running task 'netconf_subtree_get' with args {} on 1 hosts
2022-08-13 00:47:23,647 - nornir.core.task -    ERROR -      start() - Host 'R1': task 'netconf_get' failed with traceback:
Traceback (most recent call last):
  File "/home/majid/.local/lib/python3.10/site-packages/nornir/core/task.py", line 99, in start
    r = self.task(self, **self.params)
TypeError: netconf_get() got an unexpected keyword argument 'xmldict'

2022-08-13 00:47:23,647 - nornir.core.task -    ERROR -      start() - Host 'R1': task 'netconf_subtree_get' failed with traceback:
Traceback (most recent call last):
  File "/home/majid/.local/lib/python3.10/site-packages/nornir/core/task.py", line 99, in start
    r = self.task(self, **self.params)
  File "/home/majid/devnet/pyhton_nornir/13.netconf/13.5.netconf_subtree_filter_get.py", line 36, in netconf_subtree_get
    task.run(task=netconf_get, xmldict="false", filter_type="subtree", path=filter3)
  File "/home/majid/.local/lib/python3.10/site-packages/nornir/core/task.py", line 174, in run
    raise NornirSubTaskError(task=run_task, result=r)
nornir.core.exceptions.NornirSubTaskError: Subtask: netconf_get (failed)


2022-08-13 00:47:58,641 -  nornir.core -     INFO -        run() - Running task 'netconf_subtree_get' with args {} on 1 hosts
2022-08-13 00:47:58,642 - nornir.core.task -    ERROR -      start() - Host 'R1': task 'netconf_get' failed with traceback:
Traceback (most recent call last):
  File "/home/majid/.local/lib/python3.10/site-packages/nornir/core/task.py", line 99, in start
    r = self.task(self, **self.params)
TypeError: netconf_get() got an unexpected keyword argument 'path'

2022-08-13 00:47:58,643 - nornir.core.task -    ERROR -      start() - Host 'R1': task 'netconf_subtree_get' failed with traceback:
Traceback (most recent call last):
  File "/home/majid/.local/lib/python3.10/site-packages/nornir/core/task.py", line 99, in start
    r = self.task(self, **self.params)
  File "/home/majid/devnet/pyhton_nornir/13.netconf/13.5.netconf_subtree_filter_get.py", line 36, in netconf_subtree_get
    task.run(task=netconf_get, filter_type="subtree", path=filter3)
  File "/home/majid/.local/lib/python3.10/site-packages/nornir/core/task.py", line 174, in run
    raise NornirSubTaskError(task=run_task, result=r)
nornir.core.exceptions.NornirSubTaskError: Subtask: netconf_get (failed)


2022-08-13 00:49:30,543 -  nornir.core -     INFO -        run() - Running task 'netconf_subtree_get' with args {} on 1 hosts
2022-08-13 00:49:30,544 - nornir.core.task -    ERROR -      start() - Host 'R1': task 'netconf_get' failed with traceback:
Traceback (most recent call last):
  File "/home/majid/.local/lib/python3.10/site-packages/nornir/core/task.py", line 99, in start
    r = self.task(self, **self.params)
TypeError: netconf_get() got an unexpected keyword argument 'filter'

2022-08-13 00:49:30,544 - nornir.core.task -    ERROR -      start() - Host 'R1': task 'netconf_subtree_get' failed with traceback:
Traceback (most recent call last):
  File "/home/majid/.local/lib/python3.10/site-packages/nornir/core/task.py", line 99, in start
    r = self.task(self, **self.params)
  File "/home/majid/devnet/pyhton_nornir/13.netconf/13.5.netconf_subtree_filter_get.py", line 36, in netconf_subtree_get
    task.run(task=netconf_get, filter_type="subtree", filter=filter3)
  File "/home/majid/.local/lib/python3.10/site-packages/nornir/core/task.py", line 174, in run
    raise NornirSubTaskError(task=run_task, result=r)
nornir.core.exceptions.NornirSubTaskError: Subtask: netconf_get (failed)


2022-08-13 00:49:52,130 -  nornir.core -     INFO -        run() - Running task 'netconf_subtree_get' with args {} on 1 hosts
2022-08-13 00:50:27,611 -  nornir.core -     INFO -        run() - Running task 'netconf_subtree_get' with args {} on 1 hosts
2022-08-13 00:51:20,819 -  nornir.core -     INFO -        run() - Running task 'netconf_subtree_get' with args {} on 1 hosts
2022-08-13 00:51:51,035 -  nornir.core -     INFO -        run() - Running task 'netconf_subtree_get' with args {} on 1 hosts
2022-08-13 01:21:45,986 -  nornir.core -     INFO -        run() - Running task 'netconf_xpath' with args {} on 1 hosts
2022-08-13 01:22:01,393 -  nornir.core -     INFO -        run() - Running task 'netconf_xpath' with args {} on 1 hosts
2022-08-13 01:24:17,517 -  nornir.core -     INFO -        run() - Running task 'netconf_subtree_get_config' with args {} on 1 hosts
2022-08-13 01:26:16,812 -  nornir.core -     INFO -        run() - Running task 'netconf_subtree_get_config' with args {} on 1 hosts
2022-08-13 01:27:09,882 -  nornir.core -     INFO -        run() - Running task 'netconf_subtree_get_config' with args {} on 1 hosts
2022-08-13 01:28:01,742 -  nornir.core -     INFO -        run() - Running task 'netconf_subtree_get_config' with args {} on 1 hosts
2022-08-13 01:28:28,462 -  nornir.core -     INFO -        run() - Running task 'netconf_subtree_get_config' with args {} on 1 hosts
2022-08-13 01:28:58,776 -  nornir.core -     INFO -        run() - Running task 'netconf_subtree_get_config' with args {} on 1 hosts
2022-08-13 01:29:59,761 -  nornir.core -     INFO -        run() - Running task 'netconf_subtree_get_config' with args {} on 1 hosts
2022-08-13 01:30:41,760 -  nornir.core -     INFO -        run() - Running task 'netconf_subtree_get_config' with args {} on 1 hosts
2022-08-13 01:31:53,521 -  nornir.core -     INFO -        run() - Running task 'netconf_subtree_get_config' with args {} on 1 hosts
2022-08-13 01:35:46,792 -  nornir.core -     INFO -        run() - Running task 'netconf_subtree_get' with args {} on 1 hosts
2022-08-13 01:37:03,357 -  nornir.core -     INFO -        run() - Running task 'netconf_subtree_get' with args {} on 1 hosts
2022-08-13 01:38:15,499 -  nornir.core -     INFO -        run() - Running task 'netconf_subtree_get' with args {} on 1 hosts
2022-08-13 01:39:11,773 -  nornir.core -     INFO -        run() - Running task 'netconf_subtree_get' with args {} on 1 hosts
2022-08-13 01:39:38,006 -  nornir.core -     INFO -        run() - Running task 'netconf_subtree_get' with args {} on 1 hosts
2022-08-13 01:39:39,271 - nornir.core.task -    ERROR -      start() - Host 'R1': task 'netconf_get' failed with traceback:
Traceback (most recent call last):
  File "/home/majid/.local/lib/python3.10/site-packages/nornir/core/task.py", line 99, in start
    r = self.task(self, **self.params)
  File "/home/majid/.local/lib/python3.10/site-packages/nornir_netconf/plugins/tasks/retrieval/netconf_get.py", line 45, in netconf_get
    result = manager.get(**params)
  File "/home/majid/.local/lib/python3.10/site-packages/ncclient/manager.py", line 246, in execute
    return cls(self._session,
  File "/home/majid/.local/lib/python3.10/site-packages/ncclient/operations/retrieve.py", line 83, in request
    node.append(util.build_filter(filter))
  File "/home/majid/.local/lib/python3.10/site-packages/ncclient/operations/util.py", line 65, in build_filter
    rep.append(to_ele(criteria))
  File "/home/majid/.local/lib/python3.10/site-packages/ncclient/xml_.py", line 129, in to_ele
    return x if etree.iselement(x) else etree.fromstring(x.encode('UTF-8'), parser=_get_parser(huge_tree))
  File "src/lxml/etree.pyx", line 3254, in lxml.etree.fromstring
  File "src/lxml/parser.pxi", line 1913, in lxml.etree._parseMemoryDocument
  File "src/lxml/parser.pxi", line 1800, in lxml.etree._parseDoc
  File "src/lxml/parser.pxi", line 1141, in lxml.etree._BaseParser._parseDoc
  File "src/lxml/parser.pxi", line 615, in lxml.etree._ParserContext._handleParseResultDoc
  File "src/lxml/parser.pxi", line 725, in lxml.etree._handleParseResult
  File "src/lxml/parser.pxi", line 654, in lxml.etree._raiseParseError
  File "<string>", line 10
lxml.etree.XMLSyntaxError: expected '>', line 10, column 11

2022-08-13 01:39:39,271 - nornir.core.task -    ERROR -      start() - Host 'R1': task 'netconf_subtree_get' failed with traceback:
Traceback (most recent call last):
  File "/home/majid/.local/lib/python3.10/site-packages/nornir/core/task.py", line 99, in start
    r = self.task(self, **self.params)
  File "/home/majid/devnet/pyhton_nornir/13.netconf/13.5.netconf_subtree_filter_get.py", line 50, in netconf_subtree_get
    task.run(task=netconf_get, xmldict="false", filter_type="subtree", path=filter4)
  File "/home/majid/.local/lib/python3.10/site-packages/nornir/core/task.py", line 174, in run
    raise NornirSubTaskError(task=run_task, result=r)
nornir.core.exceptions.NornirSubTaskError: Subtask: netconf_get (failed)


2022-08-13 01:40:05,139 -  nornir.core -     INFO -        run() - Running task 'netconf_subtree_get' with args {} on 1 hosts
2022-08-13 01:40:32,696 -  nornir.core -     INFO -        run() - Running task 'netconf_subtree_get' with args {} on 1 hosts
2022-08-13 01:40:33,857 - nornir.core.task -    ERROR -      start() - Host 'R1': task 'netconf_get' failed with traceback:
Traceback (most recent call last):
  File "/home/majid/.local/lib/python3.10/site-packages/nornir/core/task.py", line 99, in start
    r = self.task(self, **self.params)
  File "/home/majid/.local/lib/python3.10/site-packages/nornir_netconf/plugins/tasks/retrieval/netconf_get.py", line 45, in netconf_get
    result = manager.get(**params)
  File "/home/majid/.local/lib/python3.10/site-packages/ncclient/manager.py", line 246, in execute
    return cls(self._session,
  File "/home/majid/.local/lib/python3.10/site-packages/ncclient/operations/retrieve.py", line 83, in request
    node.append(util.build_filter(filter))
  File "/home/majid/.local/lib/python3.10/site-packages/ncclient/operations/util.py", line 65, in build_filter
    rep.append(to_ele(criteria))
  File "/home/majid/.local/lib/python3.10/site-packages/ncclient/xml_.py", line 129, in to_ele
    return x if etree.iselement(x) else etree.fromstring(x.encode('UTF-8'), parser=_get_parser(huge_tree))
  File "src/lxml/etree.pyx", line 3254, in lxml.etree.fromstring
  File "src/lxml/parser.pxi", line 1913, in lxml.etree._parseMemoryDocument
  File "src/lxml/parser.pxi", line 1800, in lxml.etree._parseDoc
  File "src/lxml/parser.pxi", line 1141, in lxml.etree._BaseParser._parseDoc
  File "src/lxml/parser.pxi", line 615, in lxml.etree._ParserContext._handleParseResultDoc
  File "src/lxml/parser.pxi", line 725, in lxml.etree._handleParseResult
  File "src/lxml/parser.pxi", line 654, in lxml.etree._raiseParseError
  File "<string>", line 10
lxml.etree.XMLSyntaxError: expected '>', line 10, column 11

2022-08-13 01:40:33,858 - nornir.core.task -    ERROR -      start() - Host 'R1': task 'netconf_subtree_get' failed with traceback:
Traceback (most recent call last):
  File "/home/majid/.local/lib/python3.10/site-packages/nornir/core/task.py", line 99, in start
    r = self.task(self, **self.params)
  File "/home/majid/devnet/pyhton_nornir/13.netconf/13.5.netconf_subtree_filter_get.py", line 50, in netconf_subtree_get
    task.run(task=netconf_get, xmldict="false", filter_type="subtree", path=filter4)
  File "/home/majid/.local/lib/python3.10/site-packages/nornir/core/task.py", line 174, in run
    raise NornirSubTaskError(task=run_task, result=r)
nornir.core.exceptions.NornirSubTaskError: Subtask: netconf_get (failed)


2022-08-13 14:20:06,502 -  nornir.core -     INFO -        run() - Running task 'netconf_subtree_get_config' with args {} on 1 hosts
2022-08-13 14:29:16,960 -  nornir.core -     INFO -        run() - Running task 'netconf_subtree_get_config' with args {} on 1 hosts
2022-08-13 14:33:54,206 -  nornir.core -     INFO -        run() - Running task 'netconf_xmltodict' with args {} on 1 hosts
2022-08-13 14:34:47,479 -  nornir.core -     INFO -        run() - Running task 'netconf_xmltodict' with args {} on 1 hosts
2022-08-13 14:36:10,455 -  nornir.core -     INFO -        run() - Running task 'netconf_xmltodict' with args {} on 1 hosts
2022-08-13 14:36:50,553 -  nornir.core -     INFO -        run() - Running task 'netconf_xmltodict' with args {} on 1 hosts
2022-08-13 14:37:33,184 -  nornir.core -     INFO -        run() - Running task 'netconf_xmltodict' with args {} on 1 hosts
2022-08-13 14:38:13,527 -  nornir.core -     INFO -        run() - Running task 'netconf_xmltodict' with args {} on 1 hosts
2022-08-13 14:39:31,076 -  nornir.core -     INFO -        run() - Running task 'netconf_xmltodict' with args {} on 1 hosts
2022-08-13 14:39:31,856 - nornir.core.task -    ERROR -      start() - Host 'R1': task 'netconf_xmltodict' failed with traceback:
Traceback (most recent call last):
  File "/home/majid/.local/lib/python3.10/site-packages/nornir/core/task.py", line 99, in start
    r = self.task(self, **self.params)
  File "/home/majid/devnet/pyhton_nornir/13.netconf/13.6.netconf_xmltodict.py", line 24, in netconf_xmltodict
    pprint(interfaces_dic["rpc-reply"]["data"]["interfaces"]["interface"]["name"])
TypeError: list indices must be integers or slices, not str

2022-08-13 14:39:50,537 -  nornir.core -     INFO -        run() - Running task 'netconf_xmltodict' with args {} on 1 hosts
2022-08-13 14:39:51,322 - nornir.core.task -    ERROR -      start() - Host 'R1': task 'netconf_xmltodict' failed with traceback:
Traceback (most recent call last):
  File "/home/majid/.local/lib/python3.10/site-packages/nornir/core/task.py", line 99, in start
    r = self.task(self, **self.params)
  File "/home/majid/devnet/pyhton_nornir/13.netconf/13.6.netconf_xmltodict.py", line 24, in netconf_xmltodict
    pprint(interfaces_dic["rpc-reply"]["data"]["interfaces"]["interface"]["name"])
TypeError: list indices must be integers or slices, not str

2022-08-13 14:40:34,985 -  nornir.core -     INFO -        run() - Running task 'netconf_xmltodict' with args {} on 1 hosts
2022-08-13 14:40:53,891 -  nornir.core -     INFO -        run() - Running task 'netconf_xmltodict' with args {} on 1 hosts
2022-08-13 14:40:54,687 - nornir.core.task -    ERROR -      start() - Host 'R1': task 'netconf_xmltodict' failed with traceback:
Traceback (most recent call last):
  File "/home/majid/.local/lib/python3.10/site-packages/nornir/core/task.py", line 99, in start
    r = self.task(self, **self.params)
  File "/home/majid/devnet/pyhton_nornir/13.netconf/13.6.netconf_xmltodict.py", line 24, in netconf_xmltodict
    pprint(interfaces_dic["rpc-reply"]["data"]["interfaces"]["interface"]["name"])
TypeError: list indices must be integers or slices, not str

2022-08-13 14:41:32,784 -  nornir.core -     INFO -        run() - Running task 'netconf_xmltodict' with args {} on 1 hosts
2022-08-13 14:41:33,606 - nornir.core.task -    ERROR -      start() - Host 'R1': task 'netconf_xmltodict' failed with traceback:
Traceback (most recent call last):
  File "/home/majid/.local/lib/python3.10/site-packages/nornir/core/task.py", line 99, in start
    r = self.task(self, **self.params)
  File "/home/majid/devnet/pyhton_nornir/13.netconf/13.6.netconf_xmltodict.py", line 24, in netconf_xmltodict
    pprint(type(interfaces_dic["rpc-reply"]["data"]["interfaces"]["interface"]["name"]))
TypeError: list indices must be integers or slices, not str

2022-08-13 14:42:01,456 -  nornir.core -     INFO -        run() - Running task 'netconf_xmltodict' with args {} on 1 hosts
2022-08-13 14:45:24,587 -  nornir.core -     INFO -        run() - Running task 'netconf_xmltodict' with args {} on 1 hosts
2022-08-13 14:47:01,393 -  nornir.core -     INFO -        run() - Running task 'netconf_xmltodict' with args {} on 1 hosts
2022-08-13 14:48:06,483 -  nornir.core -     INFO -        run() - Running task 'netconf_xmltodict' with args {} on 1 hosts
2022-08-13 14:48:45,258 -  nornir.core -     INFO -        run() - Running task 'netconf_xmltodict' with args {} on 1 hosts
2022-08-13 14:48:46,091 - nornir.core.task -    ERROR -      start() - Host 'R1': task 'netconf_xmltodict' failed with traceback:
Traceback (most recent call last):
  File "/home/majid/.local/lib/python3.10/site-packages/nornir/core/task.py", line 99, in start
    r = self.task(self, **self.params)
  File "/home/majid/devnet/pyhton_nornir/13.netconf/13.6.netconf_xmltodict.py", line 31, in netconf_xmltodict
    pprint(interface["ipv4"]["address"])
KeyError: 'address'

2022-08-13 14:49:21,791 -  nornir.core -     INFO -        run() - Running task 'netconf_xmltodict' with args {} on 1 hosts
2022-08-13 14:49:22,598 - nornir.core.task -    ERROR -      start() - Host 'R1': task 'netconf_xmltodict' failed with traceback:
Traceback (most recent call last):
  File "/home/majid/.local/lib/python3.10/site-packages/nornir/core/task.py", line 99, in start
    r = self.task(self, **self.params)
  File "/home/majid/devnet/pyhton_nornir/13.netconf/13.6.netconf_xmltodict.py", line 32, in netconf_xmltodict
    pprint(interface["ipv4"]["address"]["ip"])
KeyError: 'address'

2022-08-13 14:52:12,874 -  nornir.core -     INFO -        run() - Running task 'netconf_xmltodict' with args {} on 1 hosts
2022-08-13 14:52:14,430 - nornir.core.task -    ERROR -      start() - Host 'R1': task 'netconf_xmltodict' failed with traceback:
Traceback (most recent call last):
  File "/home/majid/.local/lib/python3.10/site-packages/nornir/core/task.py", line 99, in start
    r = self.task(self, **self.params)
  File "/home/majid/devnet/pyhton_nornir/13.netconf/13.6.netconf_xmltodict.py", line 36, in netconf_xmltodict
    interfaceslist = interfaces_dic["rpc-reply"]["data"]["interfaces"]["interface"]
TypeError: list indices must be integers or slices, not str

2022-08-13 14:52:49,467 -  nornir.core -     INFO -        run() - Running task 'netconf_xmltodict' with args {} on 1 hosts
2022-08-13 14:52:50,914 - nornir.core.task -    ERROR -      start() - Host 'R1': task 'netconf_xmltodict' failed with traceback:
Traceback (most recent call last):
  File "/home/majid/.local/lib/python3.10/site-packages/nornir/core/task.py", line 99, in start
    r = self.task(self, **self.params)
  File "/home/majid/devnet/pyhton_nornir/13.netconf/13.6.netconf_xmltodict.py", line 36, in netconf_xmltodict
    interfaceslist = interfaces_dic["rpc-reply"]["data"]["interfaces"]["interface"]
TypeError: list indices must be integers or slices, not str

2022-08-13 14:53:21,432 -  nornir.core -     INFO -        run() - Running task 'netconf_xmltodict' with args {} on 1 hosts
2022-08-13 14:53:22,902 - nornir.core.task -    ERROR -      start() - Host 'R1': task 'netconf_xmltodict' failed with traceback:
Traceback (most recent call last):
  File "/home/majid/.local/lib/python3.10/site-packages/nornir/core/task.py", line 99, in start
    r = self.task(self, **self.params)
  File "/home/majid/devnet/pyhton_nornir/13.netconf/13.6.netconf_xmltodict.py", line 37, in netconf_xmltodict
    interfaceslist = interfaces_dic["rpc-reply"]["data"]["interfaces"]["interface"]
TypeError: list indices must be integers or slices, not str

2022-08-13 14:53:41,086 -  nornir.core -     INFO -        run() - Running task 'netconf_xmltodict' with args {} on 1 hosts
2022-08-13 14:53:42,542 - nornir.core.task -    ERROR -      start() - Host 'R1': task 'netconf_xmltodict' failed with traceback:
Traceback (most recent call last):
  File "/home/majid/.local/lib/python3.10/site-packages/nornir/core/task.py", line 99, in start
    r = self.task(self, **self.params)
  File "/home/majid/devnet/pyhton_nornir/13.netconf/13.6.netconf_xmltodict.py", line 37, in netconf_xmltodict
    interfaceslist = interfaces_dic["rpc-reply"]["data"]["interfaces"]["interface"]
TypeError: list indices must be integers or slices, not str

2022-08-13 14:54:33,089 -  nornir.core -     INFO -        run() - Running task 'netconf_xmltodict' with args {} on 1 hosts
2022-08-13 14:54:34,564 - nornir.core.task -    ERROR -      start() - Host 'R1': task 'netconf_xmltodict' failed with traceback:
Traceback (most recent call last):
  File "/home/majid/.local/lib/python3.10/site-packages/nornir/core/task.py", line 99, in start
    r = self.task(self, **self.params)
  File "/home/majid/devnet/pyhton_nornir/13.netconf/13.6.netconf_xmltodict.py", line 37, in netconf_xmltodict
    interfaceslist = interfaces_dic["rpc-reply"]["data"]["interfaces"]["interface"]
KeyError: 'rpc-reply'

2022-08-13 14:54:58,367 -  nornir.core -     INFO -        run() - Running task 'netconf_xmltodict' with args {} on 1 hosts
2022-08-13 14:54:59,803 - nornir.core.task -    ERROR -      start() - Host 'R1': task 'netconf_xmltodict' failed with traceback:
Traceback (most recent call last):
  File "/home/majid/.local/lib/python3.10/site-packages/nornir/core/task.py", line 99, in start
    r = self.task(self, **self.params)
  File "/home/majid/devnet/pyhton_nornir/13.netconf/13.6.netconf_xmltodict.py", line 38, in netconf_xmltodict
    interfaceslist = interfaces_dic["rpc-reply"]["data"]["interfaces"]["interface"]
KeyError: 'rpc-reply'

2022-08-13 14:55:43,936 -  nornir.core -     INFO -        run() - Running task 'netconf_xmltodict' with args {} on 1 hosts
2022-08-13 14:55:45,511 - nornir.core.task -    ERROR -      start() - Host 'R1': task 'netconf_xmltodict' failed with traceback:
Traceback (most recent call last):
  File "/home/majid/.local/lib/python3.10/site-packages/nornir/core/task.py", line 99, in start
    r = self.task(self, **self.params)
  File "/home/majid/devnet/pyhton_nornir/13.netconf/13.6.netconf_xmltodict.py", line 38, in netconf_xmltodict
    interfaceslist = interfaces_dic["data"]["interfaces"]["interface"]
KeyError: 'data'

2022-08-13 14:56:10,000 -  nornir.core -     INFO -        run() - Running task 'netconf_xmltodict' with args {} on 1 hosts
2022-08-13 14:56:11,483 - nornir.core.task -    ERROR -      start() - Host 'R1': task 'netconf_xmltodict' failed with traceback:
Traceback (most recent call last):
  File "/home/majid/.local/lib/python3.10/site-packages/nornir/core/task.py", line 99, in start
    r = self.task(self, **self.params)
  File "/home/majid/devnet/pyhton_nornir/13.netconf/13.6.netconf_xmltodict.py", line 38, in netconf_xmltodict
    interfaceslist = interfaces_dic["data"]["interfaces"]["interface"]
KeyError: 'data'

2022-08-13 14:56:43,154 -  nornir.core -     INFO -        run() - Running task 'netconf_xmltodict' with args {} on 1 hosts
2022-08-13 14:56:44,628 - nornir.core.task -    ERROR -      start() - Host 'R1': task 'netconf_xmltodict' failed with traceback:
Traceback (most recent call last):
  File "/home/majid/.local/lib/python3.10/site-packages/nornir/core/task.py", line 99, in start
    r = self.task(self, **self.params)
  File "/home/majid/devnet/pyhton_nornir/13.netconf/13.6.netconf_xmltodict.py", line 37, in netconf_xmltodict
    interfaceslist = interfaces_dic["data"]["interfaces"]["interface"]
KeyError: 'data'

2022-08-13 14:57:00,096 -  nornir.core -     INFO -        run() - Running task 'netconf_xmltodict' with args {} on 1 hosts
2022-08-13 14:57:01,499 - nornir.core.task -    ERROR -      start() - Host 'R1': task 'netconf_xmltodict' failed with traceback:
Traceback (most recent call last):
  File "/home/majid/.local/lib/python3.10/site-packages/nornir/core/task.py", line 99, in start
    r = self.task(self, **self.params)
  File "/home/majid/devnet/pyhton_nornir/13.netconf/13.6.netconf_xmltodict.py", line 37, in netconf_xmltodict
    interfaceslist = interfaces_dic["data"]["interfaces"]["interface"]
KeyError: 'data'

2022-08-13 14:57:24,987 -  nornir.core -     INFO -        run() - Running task 'netconf_xmltodict' with args {} on 1 hosts
2022-08-13 14:57:26,578 - nornir.core.task -    ERROR -      start() - Host 'R1': task 'netconf_xmltodict' failed with traceback:
Traceback (most recent call last):
  File "/home/majid/.local/lib/python3.10/site-packages/nornir/core/task.py", line 99, in start
    r = self.task(self, **self.params)
  File "/home/majid/devnet/pyhton_nornir/13.netconf/13.6.netconf_xmltodict.py", line 37, in netconf_xmltodict
    interfaceslist = interfaces_dic["data"]["interfaces"]
KeyError: 'data'

2022-08-13 14:57:43,792 -  nornir.core -     INFO -        run() - Running task 'netconf_xmltodict' with args {} on 1 hosts
2022-08-13 14:57:45,229 - nornir.core.task -    ERROR -      start() - Host 'R1': task 'netconf_xmltodict' failed with traceback:
Traceback (most recent call last):
  File "/home/majid/.local/lib/python3.10/site-packages/nornir/core/task.py", line 99, in start
    r = self.task(self, **self.params)
  File "/home/majid/devnet/pyhton_nornir/13.netconf/13.6.netconf_xmltodict.py", line 37, in netconf_xmltodict
    interfaceslist = interfaces_dic["data"]
KeyError: 'data'

2022-08-13 14:58:32,505 -  nornir.core -     INFO -        run() - Running task 'netconf_xmltodict' with args {} on 1 hosts
2022-08-13 14:58:57,846 -  nornir.core -     INFO -        run() - Running task 'netconf_xmltodict' with args {} on 1 hosts
2022-08-13 14:58:59,265 - nornir.core.task -    ERROR -      start() - Host 'R1': task 'netconf_xmltodict' failed with traceback:
Traceback (most recent call last):
  File "/home/majid/.local/lib/python3.10/site-packages/nornir/core/task.py", line 99, in start
    r = self.task(self, **self.params)
  File "/home/majid/devnet/pyhton_nornir/13.netconf/13.6.netconf_xmltodict.py", line 37, in netconf_xmltodict
    pprint(interfaces_dic["data"])
KeyError: 'data'

2022-08-13 14:59:23,698 -  nornir.core -     INFO -        run() - Running task 'netconf_xmltodict' with args {} on 1 hosts
2022-08-13 14:59:57,289 -  nornir.core -     INFO -        run() - Running task 'netconf_xmltodict' with args {} on 1 hosts
2022-08-13 15:01:06,691 -  nornir.core -     INFO -        run() - Running task 'netconf_xmltodict' with args {} on 1 hosts
2022-08-13 15:01:08,138 - nornir.core.task -    ERROR -      start() - Host 'R1': task 'netconf_xmltodict' failed with traceback:
Traceback (most recent call last):
  File "/home/majid/.local/lib/python3.10/site-packages/nornir/core/task.py", line 99, in start
    r = self.task(self, **self.params)
  File "/home/majid/devnet/pyhton_nornir/13.netconf/13.6.netconf_xmltodict.py", line 38, in netconf_xmltodict
    for key,value in interfaces_dic:
ValueError: too many values to unpack (expected 2)

2022-08-13 15:01:37,295 -  nornir.core -     INFO -        run() - Running task 'netconf_xmltodict' with args {} on 1 hosts
2022-08-13 15:01:38,736 - nornir.core.task -    ERROR -      start() - Host 'R1': task 'netconf_xmltodict' failed with traceback:
Traceback (most recent call last):
  File "/home/majid/.local/lib/python3.10/site-packages/nornir/core/task.py", line 99, in start
    r = self.task(self, **self.params)
  File "/home/majid/devnet/pyhton_nornir/13.netconf/13.6.netconf_xmltodict.py", line 38, in netconf_xmltodict
    for key,value in interfaces_dic:
ValueError: too many values to unpack (expected 2)

2022-08-13 15:02:36,195 -  nornir.core -     INFO -        run() - Running task 'netconf_xmltodict' with args {} on 1 hosts
2022-08-13 15:04:01,351 -  nornir.core -     INFO -        run() - Running task 'netconf_xmltodict' with args {} on 1 hosts
2022-08-13 15:04:48,432 -  nornir.core -     INFO -        run() - Running task 'netconf_xmltodict' with args {} on 1 hosts
2022-08-13 15:04:49,898 - nornir.core.task -    ERROR -      start() - Host 'R1': task 'netconf_xmltodict' failed with traceback:
Traceback (most recent call last):
  File "/home/majid/.local/lib/python3.10/site-packages/nornir/core/task.py", line 99, in start
    r = self.task(self, **self.params)
  File "/home/majid/devnet/pyhton_nornir/13.netconf/13.6.netconf_xmltodict.py", line 39, in netconf_xmltodict
    pprint("key=",key)
  File "/usr/lib/python3.10/pprint.py", line 55, in pprint
    printer.pprint(object)
  File "/usr/lib/python3.10/pprint.py", line 152, in pprint
    self._format(object, self._stream, 0, 0, {}, 0)
  File "/usr/lib/python3.10/pprint.py", line 193, in _format
    stream.write(rep)
AttributeError: 'str' object has no attribute 'write'

2022-08-13 15:05:06,391 -  nornir.core -     INFO -        run() - Running task 'netconf_xmltodict' with args {} on 1 hosts
2022-08-13 15:06:56,301 -  nornir.core -     INFO -        run() - Running task 'netconf_xmltodict' with args {} on 1 hosts
2022-08-13 15:07:38,915 -  nornir.core -     INFO -        run() - Running task 'netconf_xmltodict' with args {} on 1 hosts
2022-08-13 15:08:24,321 -  nornir.core -     INFO -        run() - Running task 'netconf_xmltodict' with args {} on 1 hosts
2022-08-13 15:09:10,908 -  nornir.core -     INFO -        run() - Running task 'netconf_xmltodict' with args {} on 1 hosts
2022-08-13 15:09:12,368 - nornir.core.task -    ERROR -      start() - Host 'R1': task 'netconf_xmltodict' failed with traceback:
Traceback (most recent call last):
  File "/home/majid/.local/lib/python3.10/site-packages/nornir/core/task.py", line 99, in start
    r = self.task(self, **self.params)
  File "/home/majid/devnet/pyhton_nornir/13.netconf/13.6.netconf_xmltodict.py", line 43, in netconf_xmltodict
    pprint(interface["name"])
TypeError: string indices must be integers

2022-08-13 15:09:58,347 -  nornir.core -     INFO -        run() - Running task 'netconf_xmltodict' with args {} on 1 hosts
2022-08-13 15:10:22,612 -  nornir.core -     INFO -        run() - Running task 'netconf_xmltodict' with args {} on 1 hosts
2022-08-13 15:11:29,978 -  nornir.core -     INFO -        run() - Running task 'netconf_xmltodict' with args {} on 1 hosts
2022-08-13 15:12:16,578 -  nornir.core -     INFO -        run() - Running task 'netconf_xmltodict' with args {} on 1 hosts
2022-08-13 15:12:52,374 -  nornir.core -     INFO -        run() - Running task 'netconf_xmltodict' with args {} on 1 hosts
2022-08-13 15:13:16,468 -  nornir.core -     INFO -        run() - Running task 'netconf_xmltodict' with args {} on 1 hosts
2022-08-13 15:13:17,947 - nornir.core.task -    ERROR -      start() - Host 'R1': task 'netconf_xmltodict' failed with traceback:
Traceback (most recent call last):
  File "/home/majid/.local/lib/python3.10/site-packages/nornir/core/task.py", line 99, in start
    r = self.task(self, **self.params)
  File "/home/majid/devnet/pyhton_nornir/13.netconf/13.6.netconf_xmltodict.py", line 43, in netconf_xmltodict
    for key,value in interfaceslist.items():
AttributeError: 'list' object has no attribute 'items'

2022-08-13 15:13:54,630 -  nornir.core -     INFO -        run() - Running task 'netconf_xmltodict' with args {} on 1 hosts
2022-08-13 15:14:19,068 -  nornir.core -     INFO -        run() - Running task 'netconf_xmltodict' with args {} on 1 hosts
2022-08-13 15:14:20,495 - nornir.core.task -    ERROR -      start() - Host 'R1': task 'netconf_xmltodict' failed with traceback:
Traceback (most recent call last):
  File "/home/majid/.local/lib/python3.10/site-packages/nornir/core/task.py", line 99, in start
    r = self.task(self, **self.params)
  File "/home/majid/devnet/pyhton_nornir/13.netconf/13.6.netconf_xmltodict.py", line 50, in netconf_xmltodict
    pprint(interface["ipv4"]["address"]["ip"])
KeyError: 'address'

2022-08-13 15:17:00,411 -  nornir.core -     INFO -        run() - Running task 'netconf_xmltodict' with args {} on 1 hosts
2022-08-13 15:17:01,262 - nornir.core.task -    ERROR -      start() - Host 'R1': task 'netconf_xmltodict' failed with traceback:
Traceback (most recent call last):
  File "/home/majid/.local/lib/python3.10/site-packages/nornir/core/task.py", line 99, in start
    r = self.task(self, **self.params)
  File "/home/majid/devnet/pyhton_nornir/13.netconf/13.6.nornir_scrapli_netconf_xmltodict.py", line 31, in netconf_xmltodict
    pprint(interface["ipv4"]["address"]["ip"])
KeyError: 'address'

