[1m[36mnetmiko_send_commands_example***************************************************[0m
[0m[1m[34m* R1 ** changed : False ********************************************************[0m
[0m[1m[31mvvvv netmiko_send_commands_example ** changed : False vvvvvvvvvvvvvvvvvvvvvvvvvv ERROR[0m
[0mSubtask: netmiko_send_command (failed)
[0m
[0m[1m[31m---- netmiko_send_command ** changed : False ----------------------------------- ERROR[0m
[0mTraceback (most recent call last):
  File "/home/majid/.local/lib/python3.10/site-packages/netmiko/base_connection.py", line 935, in establish_connection
    self.remote_conn_pre.connect(**ssh_connect_params)
  File "/home/majid/.local/lib/python3.10/site-packages/paramiko/client.py", line 435, in connect
    self._auth(
  File "/home/majid/.local/lib/python3.10/site-packages/paramiko/client.py", line 766, in _auth
    raise saved_exception
  File "/home/majid/.local/lib/python3.10/site-packages/paramiko/client.py", line 753, in _auth
    self._transport.auth_password(username, password)
  File "/home/majid/.local/lib/python3.10/site-packages/paramiko/transport.py", line 1564, in auth_password
    return self.auth_handler.wait_for_response(my_event)
  File "/home/majid/.local/lib/python3.10/site-packages/paramiko/auth_handler.py", line 245, in wait_for_response
    raise e
paramiko.ssh_exception.AuthenticationException: Authentication failed.

During handling of the above exception, another exception occurred:

Traceback (most recent call last):
  File "/home/majid/.local/lib/python3.10/site-packages/nornir/core/task.py", line 99, in start
    r = self.task(self, **self.params)
  File "/home/majid/.local/lib/python3.10/site-packages/nornir_netmiko/tasks/netmiko_send_command.py", line 26, in netmiko_send_command
    net_connect = task.host.get_connection(CONNECTION_NAME, task.nornir.config)
  File "/home/majid/.local/lib/python3.10/site-packages/nornir/core/inventory.py", line 494, in get_connection
    self.open_connection(
  File "/home/majid/.local/lib/python3.10/site-packages/nornir/core/inventory.py", line 546, in open_connection
    conn_obj.open(
  File "/home/majid/.local/lib/python3.10/site-packages/nornir_netmiko/connections/netmiko.py", line 59, in open
    connection = ConnectHandler(**parameters)
  File "/home/majid/.local/lib/python3.10/site-packages/netmiko/ssh_dispatcher.py", line 326, in ConnectHandler
    return ConnectionClass(*args, **kwargs)
  File "/home/majid/.local/lib/python3.10/site-packages/netmiko/cisco/cisco_ios.py", line 17, in __init__
    return super().__init__(*args, **kwargs)
  File "/home/majid/.local/lib/python3.10/site-packages/netmiko/base_connection.py", line 350, in __init__
    self._open()
  File "/home/majid/.local/lib/python3.10/site-packages/netmiko/base_connection.py", line 355, in _open
    self.establish_connection()
  File "/home/majid/.local/lib/python3.10/site-packages/netmiko/base_connection.py", line 972, in establish_connection
    raise NetmikoAuthenticationException(msg)
netmiko.ssh_exception.NetmikoAuthenticationException: Authentication to device failed.

Common causes of this problem are:
1. Invalid username and password
2. Incorrect SSH-key file
3. Connecting to the wrong device

Device settings: cisco_ios 192.168.2.91:22


Authentication failed.
[0m
[0m[1m[31m^^^^ END netmiko_send_commands_example ^^^^^^^^^^^^^^^^^^^^^^^^^^^^^^^^^^^^^^^^^[0m
[0m