2022-05-23 00:00:55,770 -  nornir.core -     INFO -        run() - Running task 'send_command' with args {'command': 'show ntp config'} on 1 hosts
2022-05-23 00:00:55,815 - nornir.core.task -    ERROR -      start() - Host 'R1': task 'send_command' failed with traceback:
Traceback (most recent call last):
  File "/home/majid/projects/venv/lib/python3.10/site-packages/nornir/core/task.py", line 99, in start
    r = self.task(self, **self.params)
  File "/home/majid/projects/venv/lib/python3.10/site-packages/nornir_scrapli/tasks/core/send_command.py", line 36, in send_command
    scrapli_conn = task.host.get_connection("scrapli", task.nornir.config)
  File "/home/majid/projects/venv/lib/python3.10/site-packages/nornir/core/inventory.py", line 494, in get_connection
    self.open_connection(
  File "/home/majid/projects/venv/lib/python3.10/site-packages/nornir/core/inventory.py", line 546, in open_connection
    conn_obj.open(
  File "/home/majid/projects/venv/lib/python3.10/site-packages/nornir_scrapli/connection.py", line 98, in open
    connection.open()
  File "/home/majid/projects/venv/lib/python3.10/site-packages/scrapli/driver/base/sync_driver.py", line 86, in open
    self.channel.channel_authenticate_ssh(
  File "/home/majid/projects/venv/lib/python3.10/site-packages/scrapli/decorators.py", line 280, in decorate
    return self._multiprocessing_timeout(
  File "/home/majid/projects/venv/lib/python3.10/site-packages/scrapli/decorators.py", line 341, in _multiprocessing_timeout
    return future.result()
  File "/usr/lib/python3.10/concurrent/futures/_base.py", line 439, in result
    return self.__get_result()
  File "/usr/lib/python3.10/concurrent/futures/_base.py", line 391, in __get_result
    raise self._exception
  File "/usr/lib/python3.10/concurrent/futures/thread.py", line 58, in run
    result = self.fn(*self.args, **self.kwargs)
  File "/home/majid/projects/venv/lib/python3.10/site-packages/scrapli/channel/sync_channel.py", line 290, in channel_authenticate_ssh
    self._ssh_message_handler(output=authenticate_buf)
  File "/home/majid/projects/venv/lib/python3.10/site-packages/scrapli/channel/base_channel.py", line 432, in _ssh_message_handler
    raise ScrapliAuthenticationFailed(msg)
scrapli.exceptions.ScrapliAuthenticationFailed: No matching key exchange found for host, their offer: diffie-hellman-group14-sha1

2022-05-23 00:03:07,230 -  nornir.core -     INFO -        run() - Running task 'send_command' with args {'command': 'show ntp config'} on 1 hosts
2022-05-23 00:03:07,273 - nornir.core.task -    ERROR -      start() - Host 'R1': task 'send_command' failed with traceback:
Traceback (most recent call last):
  File "/home/majid/projects/venv/lib/python3.10/site-packages/nornir/core/task.py", line 99, in start
    r = self.task(self, **self.params)
  File "/home/majid/projects/venv/lib/python3.10/site-packages/nornir_scrapli/tasks/core/send_command.py", line 36, in send_command
    scrapli_conn = task.host.get_connection("scrapli", task.nornir.config)
  File "/home/majid/projects/venv/lib/python3.10/site-packages/nornir/core/inventory.py", line 494, in get_connection
    self.open_connection(
  File "/home/majid/projects/venv/lib/python3.10/site-packages/nornir/core/inventory.py", line 546, in open_connection
    conn_obj.open(
  File "/home/majid/projects/venv/lib/python3.10/site-packages/nornir_scrapli/connection.py", line 98, in open
    connection.open()
  File "/home/majid/projects/venv/lib/python3.10/site-packages/scrapli/driver/base/sync_driver.py", line 86, in open
    self.channel.channel_authenticate_ssh(
  File "/home/majid/projects/venv/lib/python3.10/site-packages/scrapli/decorators.py", line 280, in decorate
    return self._multiprocessing_timeout(
  File "/home/majid/projects/venv/lib/python3.10/site-packages/scrapli/decorators.py", line 341, in _multiprocessing_timeout
    return future.result()
  File "/usr/lib/python3.10/concurrent/futures/_base.py", line 439, in result
    return self.__get_result()
  File "/usr/lib/python3.10/concurrent/futures/_base.py", line 391, in __get_result
    raise self._exception
  File "/usr/lib/python3.10/concurrent/futures/thread.py", line 58, in run
    result = self.fn(*self.args, **self.kwargs)
  File "/home/majid/projects/venv/lib/python3.10/site-packages/scrapli/channel/sync_channel.py", line 290, in channel_authenticate_ssh
    self._ssh_message_handler(output=authenticate_buf)
  File "/home/majid/projects/venv/lib/python3.10/site-packages/scrapli/channel/base_channel.py", line 432, in _ssh_message_handler
    raise ScrapliAuthenticationFailed(msg)
scrapli.exceptions.ScrapliAuthenticationFailed: No matching key exchange found for host, their offer: diffie-hellman-group14-sha1

2022-05-23 00:18:42,263 -  nornir.core -     INFO -        run() - Running task 'send_command' with args {'command': 'show ntp config'} on 1 hosts
2022-05-23 00:18:42,285 - nornir.core.task -    ERROR -      start() - Host 'R1': task 'send_command' failed with traceback:
Traceback (most recent call last):
  File "/home/majid/projects/venv/lib/python3.10/site-packages/nornir/core/task.py", line 99, in start
    r = self.task(self, **self.params)
  File "/home/majid/projects/venv/lib/python3.10/site-packages/nornir_scrapli/tasks/core/send_command.py", line 36, in send_command
    scrapli_conn = task.host.get_connection("scrapli", task.nornir.config)
  File "/home/majid/projects/venv/lib/python3.10/site-packages/nornir/core/inventory.py", line 494, in get_connection
    self.open_connection(
  File "/home/majid/projects/venv/lib/python3.10/site-packages/nornir/core/inventory.py", line 546, in open_connection
    conn_obj.open(
  File "/home/majid/projects/venv/lib/python3.10/site-packages/nornir_scrapli/connection.py", line 98, in open
    connection.open()
  File "/home/majid/projects/venv/lib/python3.10/site-packages/scrapli/driver/base/sync_driver.py", line 86, in open
    self.channel.channel_authenticate_ssh(
  File "/home/majid/projects/venv/lib/python3.10/site-packages/scrapli/decorators.py", line 280, in decorate
    return self._multiprocessing_timeout(
  File "/home/majid/projects/venv/lib/python3.10/site-packages/scrapli/decorators.py", line 341, in _multiprocessing_timeout
    return future.result()
  File "/usr/lib/python3.10/concurrent/futures/_base.py", line 439, in result
    return self.__get_result()
  File "/usr/lib/python3.10/concurrent/futures/_base.py", line 391, in __get_result
    raise self._exception
  File "/usr/lib/python3.10/concurrent/futures/thread.py", line 58, in run
    result = self.fn(*self.args, **self.kwargs)
  File "/home/majid/projects/venv/lib/python3.10/site-packages/scrapli/channel/sync_channel.py", line 290, in channel_authenticate_ssh
    self._ssh_message_handler(output=authenticate_buf)
  File "/home/majid/projects/venv/lib/python3.10/site-packages/scrapli/channel/base_channel.py", line 432, in _ssh_message_handler
    raise ScrapliAuthenticationFailed(msg)
scrapli.exceptions.ScrapliAuthenticationFailed: No matching key exchange found for host, their offer: diffie-hellman-group14-sha1

2022-05-23 00:34:26,302 -  nornir.core -     INFO -        run() - Running task 'send_command' with args {'command': 'show ntp config'} on 1 hosts
2022-05-24 15:54:20,123 -  nornir.core -     INFO -        run() - Running task 'send_command' with args {'command': 'show ntp config'} on 1 hosts
2022-05-24 17:00:06,061 -  nornir.core -     INFO -        run() - Running task 'send_command' with args {'command': 'show ntp config'} on 1 hosts
2022-05-25 23:23:33,769 -  nornir.core -     INFO -        run() - Running task 'send_command' with args {'command': 'show ntp config'} on 1 hosts
2022-05-25 23:24:05,951 -  nornir.core -     INFO -        run() - Running task 'send_command' with args {'command': 'show version | inc ios'} on 1 hosts
2022-05-25 23:24:26,818 -  nornir.core -     INFO -        run() - Running task 'send_command' with args {'command': 'show version'} on 1 hosts
2022-05-25 23:24:56,394 -  nornir.core -     INFO -        run() - Running task 'send_command' with args {'command': 'show version | inc IOS|XE'} on 1 hosts
2022-05-25 23:27:04,936 -  nornir.core -     INFO -        run() - Running task 'send_command' with args {'command': 'show version | inc IOS|XE'} on 1 hosts
2022-05-25 23:28:23,386 -  nornir.core -     INFO -        run() - Running task 'send_command' with args {'command': 'show version | inc IOS|XE'} on 1 hosts
2022-05-25 23:39:05,678 -  nornir.core -     INFO -        run() - Running task 'send_command' with args {'command': 'show version | inc IOS|XE'} on 1 hosts
2022-05-25 23:39:51,391 -  nornir.core -     INFO -        run() - Running task 'send_command' with args {'command': 'show version | inc IOS|XE'} on 1 hosts
2022-05-26 00:31:51,289 -  nornir.core -     INFO -        run() - Running task 'send_command' with args {'command': 'show version | inc IOS|XE'} on 1 hosts
2022-05-26 00:32:31,867 -  nornir.core -     INFO -        run() - Running task 'send_command' with args {'command': 'show version | inc IOS|XE'} on 1 hosts
2022-05-26 00:32:43,551 -  nornir.core -     INFO -        run() - Running task 'send_command' with args {'command': 'show version | inc IOS|XE'} on 1 hosts
2022-05-27 13:40:34,211 -  nornir.core -     INFO -        run() - Running task 'random_config' with args {} on 1 hosts
2022-05-27 14:19:24,206 -  nornir.core -     INFO -        run() - Running task 'send_config' with args {'config': 'ntp server 1.1.1.1'} on 1 hosts
2022-05-27 14:19:41,824 -  nornir.core -     INFO -        run() - Running task 'send_config' with args {'config': 'ntp server 1.1.1.1'} on 1 hosts
2022-05-27 14:43:14,494 -  nornir.core -     INFO -        run() - Running task 'ntp_config' with args {} on 1 hosts
2022-05-28 16:47:32,188 -  nornir.core -     INFO -        run() - Running task 'send_command' with args {'command': 'show version | inc IOS|XE'} on 1 hosts
2022-05-28 16:48:22,567 -  nornir.core -     INFO -        run() - Running task 'send_command' with args {'command': 'show version | inc IOS|XE'} on 1 hosts
2022-05-28 16:48:37,595 - nornir.core.task -    ERROR -      start() - Host 'R1': task 'send_command' failed with traceback:
Traceback (most recent call last):
  File "/home/majid/.local/lib/python3.10/site-packages/nornir/core/task.py", line 99, in start
    r = self.task(self, **self.params)
  File "/home/majid/.local/lib/python3.10/site-packages/nornir_scrapli/tasks/core/send_command.py", line 36, in send_command
    scrapli_conn = task.host.get_connection("scrapli", task.nornir.config)
  File "/home/majid/.local/lib/python3.10/site-packages/nornir/core/inventory.py", line 494, in get_connection
    self.open_connection(
  File "/home/majid/.local/lib/python3.10/site-packages/nornir/core/inventory.py", line 546, in open_connection
    conn_obj.open(
  File "/home/majid/.local/lib/python3.10/site-packages/nornir_scrapli/connection.py", line 98, in open
    connection.open()
  File "/home/majid/.local/lib/python3.10/site-packages/scrapli/driver/base/sync_driver.py", line 86, in open
    self.channel.channel_authenticate_ssh(
  File "/home/majid/.local/lib/python3.10/site-packages/scrapli/decorators.py", line 280, in decorate
    return self._multiprocessing_timeout(
  File "/home/majid/.local/lib/python3.10/site-packages/scrapli/decorators.py", line 341, in _multiprocessing_timeout
    return future.result()
  File "/usr/lib/python3.10/concurrent/futures/_base.py", line 439, in result
    return self.__get_result()
  File "/usr/lib/python3.10/concurrent/futures/_base.py", line 391, in __get_result
    raise self._exception
  File "/usr/lib/python3.10/concurrent/futures/thread.py", line 58, in run
    result = self.fn(*self.args, **self.kwargs)
  File "/home/majid/.local/lib/python3.10/site-packages/scrapli/channel/sync_channel.py", line 290, in channel_authenticate_ssh
    self._ssh_message_handler(output=authenticate_buf)
  File "/home/majid/.local/lib/python3.10/site-packages/scrapli/channel/base_channel.py", line 432, in _ssh_message_handler
    raise ScrapliAuthenticationFailed(msg)
scrapli.exceptions.ScrapliAuthenticationFailed: Timed out connecting to host

2022-05-28 16:49:07,606 -  nornir.core -     INFO -        run() - Running task 'send_command' with args {'command': 'show version | inc IOS|XE'} on 1 hosts
2022-05-28 16:49:41,230 -  nornir.core -     INFO -        run() - Running task 'send_command' with args {'command': 'show ip interface brief'} on 1 hosts
2022-05-28 16:54:02,484 -  nornir.core -     INFO -        run() - Running task 'send_commands' with args {'commands': ['show ip interface brief', 'show interface status']} on 1 hosts
2022-05-28 16:54:25,340 -  nornir.core -     INFO -        run() - Running task 'send_commands' with args {'commands': ['show ip interface brief', 'show interface gigaethernet1']} on 1 hosts
2022-05-28 16:54:38,382 -  nornir.core -     INFO -        run() - Running task 'send_commands' with args {'commands': ['show ip interface brief', 'show version']} on 1 hosts
2022-05-28 16:55:30,928 -  nornir.core -     INFO -        run() - Running task 'send_commands' with args {'commands': ['show ip interface brief', 'show interface gigabitEthernet 1']} on 1 hosts
2022-05-28 16:58:25,217 -  nornir.core -     INFO -        run() - Running task 'send_commands_from_file' with args {'file': 'command_list'} on 1 hosts
2022-05-28 18:28:24,072 -  nornir.core -     INFO -        run() - Running task 'send_commands_from_file' with args {'file': 'command_list'} on 1 hosts
2022-05-28 23:08:38,656 -  nornir.core -     INFO -        run() - Running task 'send_command' with args {'command': 'show ip interface brief'} on 1 hosts
2022-05-28 23:25:50,908 -  nornir.core -     INFO -        run() - Running task 'send_command' with args {'command': 'show ip interface brief'} on 1 hosts
2022-05-28 23:26:17,705 -  nornir.core -     INFO -        run() - Running task 'send_command' with args {'command': 'show ip interface brief | exc unassig'} on 1 hosts
2022-05-28 23:26:32,564 -  nornir.core -     INFO -        run() - Running task 'send_command' with args {'command': 'show version'} on 1 hosts
2022-05-28 23:26:46,299 -  nornir.core -     INFO -        run() - Running task 'send_command' with args {'command': 'show version | inc XE'} on 1 hosts
2022-05-28 23:29:41,655 -  nornir.core -     INFO -        run() - Running task 'send_commands' with args {'commands': ['show ip interface brief', 'show interface gigabitEthernet 1']} on 1 hosts
2022-05-28 23:30:34,010 -  nornir.core -     INFO -        run() - Running task 'send_commands_from_file' with args {'file': 'command_list'} on 1 hosts
2022-05-30 21:29:41,251 -  nornir.core -     INFO -        run() - Running task 'send_config' with args {'config': 'ntp server 2.3.4.5'} on 1 hosts
2022-05-30 22:06:44,483 -  nornir.core -     INFO -        run() - Running task 'ntp_config' with args {} on 2 hosts
2022-05-30 22:07:38,092 -  nornir.core -     INFO -        run() - Running task 'ntp_config' with args {} on 2 hosts
2022-05-30 22:07:38,094 - nornir.core.task -    ERROR -      start() - Host 'R2': task 'ntp_config' failed with traceback:
Traceback (most recent call last):
  File "/home/majid/.local/lib/python3.10/site-packages/nornir/core/task.py", line 99, in start
    r = self.task(self, **self.params)
  File "/home/majid/projects/2.1.send_commad_versus_send_config_access_data.py", line 7, in ntp_config
    print(task.host[ntp_server])
NameError: name 'ntp_server' is not defined

2022-05-30 22:07:38,094 - nornir.core.task -    ERROR -      start() - Host 'R1': task 'ntp_config' failed with traceback:
Traceback (most recent call last):
  File "/home/majid/.local/lib/python3.10/site-packages/nornir/core/task.py", line 99, in start
    r = self.task(self, **self.params)
  File "/home/majid/projects/2.1.send_commad_versus_send_config_access_data.py", line 7, in ntp_config
    print(task.host[ntp_server])
NameError: name 'ntp_server' is not defined

2022-05-30 22:08:03,392 -  nornir.core -     INFO -        run() - Running task 'ntp_config' with args {} on 2 hosts
2022-05-30 22:09:09,198 -  nornir.core -     INFO -        run() - Running task 'access_data' with args {} on 2 hosts
2022-05-30 22:45:18,248 -  nornir.core -     INFO -        run() - Running task 'access_data' with args {} on 2 hosts
2022-05-30 23:20:59,310 -  nornir.core -     INFO -        run() - Running task 'access_data' with args {} on 3 hosts
2022-05-30 23:21:21,412 -  nornir.core -     INFO -        run() - Running task 'access_data' with args {} on 3 hosts
2022-05-30 23:23:00,959 -  nornir.core -     INFO -        run() - Running task 'access_data' with args {} on 3 hosts
2022-06-02 21:23:18,664 -  nornir.core -     INFO -        run() - Running task 'send_config' with args {'config': 'snmp-server community rayka'} on 1 hosts
2022-06-02 21:24:09,797 -  nornir.core -     INFO -        run() - Running task 'send_config' with args {'config': 'snmp-server community rayka'} on 1 hosts
2022-06-02 21:24:50,229 -  nornir.core -     INFO -        run() - Running task 'ntp_config' with args {} on 1 hosts
2022-06-02 21:25:03,785 -  nornir.core -     INFO -        run() - Running task 'ntp_config' with args {} on 1 hosts
2022-06-02 21:25:43,804 -  nornir.core -     INFO -        run() - Running task 'send_config' with args {'config': 'snmp-server community rayka'} on 1 hosts
2022-06-02 21:36:36,552 -  nornir.core -     INFO -        run() - Running task 'send_configs_test' with args {} on 1 hosts
2022-06-02 21:36:36,554 - nornir.core.task -    ERROR -      start() - Host 'R1': task 'send_configs_test' failed with traceback:
Traceback (most recent call last):
  File "/home/majid/.local/lib/python3.10/site-packages/nornir/core/task.py", line 99, in start
    r = self.task(self, **self.params)
  File "/home/majid/projects/3.2.nornir_scrapli_send_configs.py", line 8, in send_configs_test
    task.run(task=send_config, configs=[f"snmp-server community {task.host['community']}", "ntp server 1.1.1.1"])
NameError: name 'send_config' is not defined

2022-06-02 21:38:01,078 -  nornir.core -     INFO -        run() - Running task 'send_configs_test' with args {} on 1 hosts
2022-06-02 21:38:01,079 - nornir.core.task -    ERROR -      start() - Host 'R1': task 'send_configs_test' failed with traceback:
Traceback (most recent call last):
  File "/home/majid/.local/lib/python3.10/site-packages/nornir/core/task.py", line 99, in start
    r = self.task(self, **self.params)
  File "/home/majid/projects/3.2.nornir_scrapli_send_configs.py", line 8, in send_configs_test
    task.run(task=send_config, configs=["ntp server 2.2.2.2", "ntp server 1.1.1.1"])
NameError: name 'send_config' is not defined

2022-06-02 21:39:12,363 -  nornir.core -     INFO -        run() - Running task 'send_configs_test' with args {} on 1 hosts
2022-06-02 21:43:50,225 -  nornir.core -     INFO -        run() - Running task 'send_configs_test' with args {} on 1 hosts
2022-06-02 21:47:08,012 -  nornir.core -     INFO -        run() - Running task 'send_configs_test' with args {} on 1 hosts
2022-06-02 21:49:59,197 -  nornir.core -     INFO -        run() - Running task 'send_configs_test' with args {} on 1 hosts
2022-06-02 21:49:59,198 - nornir.core.task -    ERROR -      start() - Host 'R1': task 'send_configs_test' failed with traceback:
Traceback (most recent call last):
  File "/home/majid/.local/lib/python3.10/site-packages/nornir/core/task.py", line 99, in start
    r = self.task(self, **self.params)
  File "/home/majid/projects/3.3.nornir_scrapli_send_configs_from_file.py", line 8, in send_configs_test
    task.run(task=send_configs_from_file, file="config_list", dry_run=true)
NameError: name 'true' is not defined

2022-06-02 21:50:11,433 -  nornir.core -     INFO -        run() - Running task 'send_configs_test' with args {} on 1 hosts
2022-06-02 21:50:40,336 -  nornir.core -     INFO -        run() - Running task 'send_configs_test' with args {} on 1 hosts
2022-06-02 21:51:01,897 -  nornir.core -     INFO -        run() - Running task 'send_configs_test' with args {} on 1 hosts
2022-06-02 22:19:54,503 -  nornir.core -     INFO -        run() - Running task 'send_config' with args {'config': 'snmp-server community rayka'} on 1 hosts
2022-06-02 22:20:34,955 -  nornir.core -     INFO -        run() - Running task 'send_config' with args {'config': 'snmp-server community rayka', 'dry_run': 'true'} on 1 hosts
2022-06-02 22:20:55,130 -  nornir.core -     INFO -        run() - Running task 'send_config' with args {'config': 'snmp-server community rayka', 'dry_run': 'false'} on 1 hosts
2022-06-02 22:21:15,619 -  nornir.core -     INFO -        run() - Running task 'send_config' with args {'config': 'snmp-server community rayka', 'dry_run': 'None'} on 1 hosts
2022-06-02 22:21:27,544 -  nornir.core -     INFO -        run() - Running task 'send_config' with args {'config': 'snmp-server community rayka', 'dry_run': 'False'} on 1 hosts
2022-06-02 22:21:49,125 -  nornir.core -     INFO -        run() - Running task 'send_config' with args {'config': 'snmp-server community rayka'} on 1 hosts
2022-06-02 22:22:06,363 -  nornir.core -     INFO -        run() - Running task 'snmp_config' with args {} on 1 hosts
2022-06-02 22:22:52,025 -  nornir.core -     INFO -        run() - Running task 'snmp_config' with args {} on 1 hosts
2022-06-02 22:24:09,346 -  nornir.core -     INFO -        run() - Running task 'send_configs_test' with args {} on 1 hosts
2022-06-02 22:24:24,135 -  nornir.core -     INFO -        run() - Running task 'send_configs_test' with args {} on 1 hosts
2022-06-02 22:24:59,754 -  nornir.core -     INFO -        run() - Running task 'send_configs_test' with args {} on 1 hosts
2022-06-02 22:26:20,530 -  nornir.core -     INFO -        run() - Running task 'send_configs_test' with args {} on 1 hosts
2022-06-02 22:26:42,489 -  nornir.core -     INFO -        run() - Running task 'send_configs_test' with args {} on 1 hosts
2022-06-02 22:26:52,142 -  nornir.core -     INFO -        run() - Running task 'send_configs_test' with args {} on 1 hosts
2022-06-02 22:27:03,657 -  nornir.core -     INFO -        run() - Running task 'send_configs_test' with args {} on 1 hosts
2022-06-05 13:11:31,600 -  nornir.core -     INFO -        run() - Running task 'netmiko_send_command' with args {'command_string': 'show ip int brief | exc unass'} on 1 hosts
2022-06-05 13:16:51,861 -  nornir.core -     INFO -        run() - Running task 'netmiko_send_command' with args {'command_string': 'show ip int brief | exc unass'} on 1 hosts
2022-06-05 13:16:52,579 -  nornir.core -     INFO -        run() - Running task 'netmiko_send_command' with args {'command_string': 'show version | inc XE'} on 1 hosts
2022-06-05 17:59:04,037 -  nornir.core -     INFO -        run() - Running task 'interactive_commands_exmple' with args {} on 1 hosts
2022-06-05 17:59:04,040 - nornir.core.task -    ERROR -      start() - Host 'R1': task 'interactive_commands_exmple' failed with traceback:
Traceback (most recent call last):
  File "/home/majid/.local/lib/python3.10/site-packages/nornir/core/task.py", line 99, in start
    r = self.task(self, **self.params)
  File "/home/majid/devnet/pyhton_nornir/4.nornir_scrapli_send_interactive.py", line 15, in interactive_commands_exmple
    ("rayka-co.com", prompt, True),
NameError: name 'prompt' is not defined

2022-06-05 18:03:31,002 -  nornir.core -     INFO -        run() - Running task 'interactive_commands_exmple' with args {} on 1 hosts
2022-06-05 18:04:01,943 -  nornir.core -     INFO -        run() - Running task 'interactive_commands_exmple' with args {} on 1 hosts
2022-06-05 18:04:32,546 - nornir.core.task -    ERROR -      start() - Host 'R1': task 'send_interactive' failed with traceback:
Traceback (most recent call last):
  File "/home/majid/.local/lib/python3.10/site-packages/nornir/core/task.py", line 99, in start
    r = self.task(self, **self.params)
  File "/home/majid/.local/lib/python3.10/site-packages/nornir_scrapli/tasks/core/send_interactive.py", line 80, in send_interactive
    scrapli_response = scrapli_conn.send_interactive(
  File "/home/majid/.local/lib/python3.10/site-packages/scrapli/driver/network/sync_driver.py", line 437, in send_interactive
    response: Response = super().send_interactive(
  File "/home/majid/.local/lib/python3.10/site-packages/scrapli/decorators.py", line 413, in decorate
    result = wrapped_func(*args, **kwargs)
  File "/home/majid/.local/lib/python3.10/site-packages/scrapli/driver/generic/sync_driver.py", line 438, in send_interactive
    raw_response, processed_response = self.channel.send_inputs_interact(
  File "/home/majid/.local/lib/python3.10/site-packages/scrapli/decorators.py", line 280, in decorate
    return self._multiprocessing_timeout(
  File "/home/majid/.local/lib/python3.10/site-packages/scrapli/decorators.py", line 340, in _multiprocessing_timeout
    self._handle_timeout()
  File "/home/majid/.local/lib/python3.10/site-packages/scrapli/decorators.py", line 316, in _handle_timeout
    raise ScrapliTimeout(self.message)
scrapli.exceptions.ScrapliTimeout: timed out sending interactive input to device

2022-06-05 18:04:32,549 - nornir.core.task -    ERROR -      start() - Host 'R1': task 'interactive_commands_exmple' failed with traceback:
Traceback (most recent call last):
  File "/home/majid/.local/lib/python3.10/site-packages/nornir/core/task.py", line 99, in start
    r = self.task(self, **self.params)
  File "/home/majid/devnet/pyhton_nornir/4.nornir_scrapli_send_interactive.py", line 17, in interactive_commands_exmple
    task.run(task=send_interactive, interact_events=interact_lists )
  File "/home/majid/.local/lib/python3.10/site-packages/nornir/core/task.py", line 174, in run
    raise NornirSubTaskError(task=run_task, result=r)
nornir.core.exceptions.NornirSubTaskError: Subtask: send_interactive (failed)


2022-06-05 18:04:36,541 -  nornir.core -     INFO -        run() - Running task 'interactive_commands_exmple' with args {} on 1 hosts
2022-06-05 18:05:07,306 - nornir.core.task -    ERROR -      start() - Host 'R1': task 'send_interactive' failed with traceback:
Traceback (most recent call last):
  File "/home/majid/.local/lib/python3.10/site-packages/nornir/core/task.py", line 99, in start
    r = self.task(self, **self.params)
  File "/home/majid/.local/lib/python3.10/site-packages/nornir_scrapli/tasks/core/send_interactive.py", line 80, in send_interactive
    scrapli_response = scrapli_conn.send_interactive(
  File "/home/majid/.local/lib/python3.10/site-packages/scrapli/driver/network/sync_driver.py", line 437, in send_interactive
    response: Response = super().send_interactive(
  File "/home/majid/.local/lib/python3.10/site-packages/scrapli/decorators.py", line 413, in decorate
    result = wrapped_func(*args, **kwargs)
  File "/home/majid/.local/lib/python3.10/site-packages/scrapli/driver/generic/sync_driver.py", line 438, in send_interactive
    raw_response, processed_response = self.channel.send_inputs_interact(
  File "/home/majid/.local/lib/python3.10/site-packages/scrapli/decorators.py", line 280, in decorate
    return self._multiprocessing_timeout(
  File "/home/majid/.local/lib/python3.10/site-packages/scrapli/decorators.py", line 340, in _multiprocessing_timeout
    self._handle_timeout()
  File "/home/majid/.local/lib/python3.10/site-packages/scrapli/decorators.py", line 316, in _handle_timeout
    raise ScrapliTimeout(self.message)
scrapli.exceptions.ScrapliTimeout: timed out sending interactive input to device

2022-06-05 18:05:07,307 - nornir.core.task -    ERROR -      start() - Host 'R1': task 'interactive_commands_exmple' failed with traceback:
Traceback (most recent call last):
  File "/home/majid/.local/lib/python3.10/site-packages/nornir/core/task.py", line 99, in start
    r = self.task(self, **self.params)
  File "/home/majid/devnet/pyhton_nornir/4.nornir_scrapli_send_interactive.py", line 17, in interactive_commands_exmple
    task.run(task=send_interactive, interact_events=interact_lists )
  File "/home/majid/.local/lib/python3.10/site-packages/nornir/core/task.py", line 174, in run
    raise NornirSubTaskError(task=run_task, result=r)
nornir.core.exceptions.NornirSubTaskError: Subtask: send_interactive (failed)


2022-06-05 18:08:33,685 -  nornir.core -     INFO -        run() - Running task 'interactive_commands_exmple' with args {} on 1 hosts
2022-06-05 18:09:04,277 - nornir.core.task -    ERROR -      start() - Host 'R1': task 'send_interactive' failed with traceback:
Traceback (most recent call last):
  File "/home/majid/.local/lib/python3.10/site-packages/nornir/core/task.py", line 99, in start
    r = self.task(self, **self.params)
  File "/home/majid/.local/lib/python3.10/site-packages/nornir_scrapli/tasks/core/send_interactive.py", line 80, in send_interactive
    scrapli_response = scrapli_conn.send_interactive(
  File "/home/majid/.local/lib/python3.10/site-packages/scrapli/driver/network/sync_driver.py", line 437, in send_interactive
    response: Response = super().send_interactive(
  File "/home/majid/.local/lib/python3.10/site-packages/scrapli/decorators.py", line 413, in decorate
    result = wrapped_func(*args, **kwargs)
  File "/home/majid/.local/lib/python3.10/site-packages/scrapli/driver/generic/sync_driver.py", line 438, in send_interactive
    raw_response, processed_response = self.channel.send_inputs_interact(
  File "/home/majid/.local/lib/python3.10/site-packages/scrapli/decorators.py", line 280, in decorate
    return self._multiprocessing_timeout(
  File "/home/majid/.local/lib/python3.10/site-packages/scrapli/decorators.py", line 340, in _multiprocessing_timeout
    self._handle_timeout()
  File "/home/majid/.local/lib/python3.10/site-packages/scrapli/decorators.py", line 316, in _handle_timeout
    raise ScrapliTimeout(self.message)
scrapli.exceptions.ScrapliTimeout: timed out sending interactive input to device

2022-06-05 18:09:04,278 - nornir.core.task -    ERROR -      start() - Host 'R1': task 'interactive_commands_exmple' failed with traceback:
Traceback (most recent call last):
  File "/home/majid/.local/lib/python3.10/site-packages/nornir/core/task.py", line 99, in start
    r = self.task(self, **self.params)
  File "/home/majid/devnet/pyhton_nornir/4.nornir_scrapli_send_interactive.py", line 17, in interactive_commands_exmple
    task.run(task=send_interactive, interact_events=interact_lists )
  File "/home/majid/.local/lib/python3.10/site-packages/nornir/core/task.py", line 174, in run
    raise NornirSubTaskError(task=run_task, result=r)
nornir.core.exceptions.NornirSubTaskError: Subtask: send_interactive (failed)


2022-06-05 18:13:12,740 -  nornir.core -     INFO -        run() - Running task 'interactive_commands_exmple' with args {} on 1 hosts
2022-06-05 18:14:22,894 -  nornir.core -     INFO -        run() - Running task 'interactive_commands_exmple' with args {} on 1 hosts
2022-06-05 18:16:18,499 -  nornir.core -     INFO -        run() - Running task 'interactive_commands_exmple' with args {} on 1 hosts
2022-06-05 18:17:21,877 -  nornir.core -     INFO -        run() - Running task 'interactive_commands_exmple' with args {} on 1 hosts
2022-06-05 18:17:52,447 - nornir.core.task -    ERROR -      start() - Host 'R1': task 'send_interactive' failed with traceback:
Traceback (most recent call last):
  File "/home/majid/.local/lib/python3.10/site-packages/nornir/core/task.py", line 99, in start
    r = self.task(self, **self.params)
  File "/home/majid/.local/lib/python3.10/site-packages/nornir_scrapli/tasks/core/send_interactive.py", line 80, in send_interactive
    scrapli_response = scrapli_conn.send_interactive(
  File "/home/majid/.local/lib/python3.10/site-packages/scrapli/driver/network/sync_driver.py", line 437, in send_interactive
    response: Response = super().send_interactive(
  File "/home/majid/.local/lib/python3.10/site-packages/scrapli/decorators.py", line 413, in decorate
    result = wrapped_func(*args, **kwargs)
  File "/home/majid/.local/lib/python3.10/site-packages/scrapli/driver/generic/sync_driver.py", line 438, in send_interactive
    raw_response, processed_response = self.channel.send_inputs_interact(
  File "/home/majid/.local/lib/python3.10/site-packages/scrapli/decorators.py", line 280, in decorate
    return self._multiprocessing_timeout(
  File "/home/majid/.local/lib/python3.10/site-packages/scrapli/decorators.py", line 340, in _multiprocessing_timeout
    self._handle_timeout()
  File "/home/majid/.local/lib/python3.10/site-packages/scrapli/decorators.py", line 316, in _handle_timeout
    raise ScrapliTimeout(self.message)
scrapli.exceptions.ScrapliTimeout: timed out sending interactive input to device

2022-06-05 18:17:52,448 - nornir.core.task -    ERROR -      start() - Host 'R1': task 'interactive_commands_exmple' failed with traceback:
Traceback (most recent call last):
  File "/home/majid/.local/lib/python3.10/site-packages/nornir/core/task.py", line 99, in start
    r = self.task(self, **self.params)
  File "/home/majid/devnet/pyhton_nornir/4.nornir_scrapli_send_interactive.py", line 19, in interactive_commands_exmple
    task.run(task=send_interactive, interact_events=interact_lists )
  File "/home/majid/.local/lib/python3.10/site-packages/nornir/core/task.py", line 174, in run
    raise NornirSubTaskError(task=run_task, result=r)
nornir.core.exceptions.NornirSubTaskError: Subtask: send_interactive (failed)


2022-06-05 21:11:40,991 -  nornir.core -     INFO -        run() - Running task 'interactive_commands_exmple' with args {} on 1 hosts
2022-06-05 21:12:11,575 - nornir.core.task -    ERROR -      start() - Host 'R1': task 'send_interactive' failed with traceback:
Traceback (most recent call last):
  File "/home/majid/.local/lib/python3.10/site-packages/nornir/core/task.py", line 99, in start
    r = self.task(self, **self.params)
  File "/home/majid/.local/lib/python3.10/site-packages/nornir_scrapli/tasks/core/send_interactive.py", line 80, in send_interactive
    scrapli_response = scrapli_conn.send_interactive(
  File "/home/majid/.local/lib/python3.10/site-packages/scrapli/driver/network/sync_driver.py", line 437, in send_interactive
    response: Response = super().send_interactive(
  File "/home/majid/.local/lib/python3.10/site-packages/scrapli/decorators.py", line 413, in decorate
    result = wrapped_func(*args, **kwargs)
  File "/home/majid/.local/lib/python3.10/site-packages/scrapli/driver/generic/sync_driver.py", line 438, in send_interactive
    raw_response, processed_response = self.channel.send_inputs_interact(
  File "/home/majid/.local/lib/python3.10/site-packages/scrapli/decorators.py", line 280, in decorate
    return self._multiprocessing_timeout(
  File "/home/majid/.local/lib/python3.10/site-packages/scrapli/decorators.py", line 340, in _multiprocessing_timeout
    self._handle_timeout()
  File "/home/majid/.local/lib/python3.10/site-packages/scrapli/decorators.py", line 316, in _handle_timeout
    raise ScrapliTimeout(self.message)
scrapli.exceptions.ScrapliTimeout: timed out sending interactive input to device

2022-06-05 21:12:11,576 - nornir.core.task -    ERROR -      start() - Host 'R1': task 'interactive_commands_exmple' failed with traceback:
Traceback (most recent call last):
  File "/home/majid/.local/lib/python3.10/site-packages/nornir/core/task.py", line 99, in start
    r = self.task(self, **self.params)
  File "/home/majid/devnet/pyhton_nornir/4.nornir_scrapli_send_interactive.py", line 21, in interactive_commands_exmple
    task.run(task=send_interactive, interact_events=interact_lists )
  File "/home/majid/.local/lib/python3.10/site-packages/nornir/core/task.py", line 174, in run
    raise NornirSubTaskError(task=run_task, result=r)
nornir.core.exceptions.NornirSubTaskError: Subtask: send_interactive (failed)


2022-06-05 21:16:34,738 -  nornir.core -     INFO -        run() - Running task 'interactive_commands_exmple' with args {} on 1 hosts
2022-06-05 21:16:34,739 - nornir.core.task -    ERROR -      start() - Host 'R1': task 'interactive_commands_exmple' failed with traceback:
Traceback (most recent call last):
  File "/home/majid/.local/lib/python3.10/site-packages/nornir/core/task.py", line 99, in start
    r = self.task(self, **self.params)
  File "/home/majid/devnet/pyhton_nornir/4.nornir_scrapli_send_interactive.py", line 21, in interactive_commands_exmple
    task.host.connections['scrapli'].connection.channel.timeout_ops = timeout
NameError: name 'timeout' is not defined

2022-06-05 21:16:56,672 -  nornir.core -     INFO -        run() - Running task 'interactive_commands_exmple' with args {} on 1 hosts
2022-06-05 21:16:56,673 - nornir.core.task -    ERROR -      start() - Host 'R1': task 'interactive_commands_exmple' failed with traceback:
Traceback (most recent call last):
  File "/home/majid/.local/lib/python3.10/site-packages/nornir/core/task.py", line 99, in start
    r = self.task(self, **self.params)
  File "/home/majid/devnet/pyhton_nornir/4.nornir_scrapli_send_interactive.py", line 21, in interactive_commands_exmple
    task.host.connections['scrapli'].connection.channel.timeout_ops = timeout
KeyError: 'scrapli'

2022-06-05 21:20:32,522 -  nornir.core -     INFO -        run() - Running task 'interactive_commands_exmple' with args {} on 1 hosts
2022-06-05 21:21:03,132 - nornir.core.task -    ERROR -      start() - Host 'R1': task 'send_interactive' failed with traceback:
Traceback (most recent call last):
  File "/home/majid/.local/lib/python3.10/site-packages/nornir/core/task.py", line 99, in start
    r = self.task(self, **self.params)
  File "/home/majid/.local/lib/python3.10/site-packages/nornir_scrapli/tasks/core/send_interactive.py", line 80, in send_interactive
    scrapli_response = scrapli_conn.send_interactive(
  File "/home/majid/.local/lib/python3.10/site-packages/scrapli/driver/network/sync_driver.py", line 437, in send_interactive
    response: Response = super().send_interactive(
  File "/home/majid/.local/lib/python3.10/site-packages/scrapli/decorators.py", line 421, in decorate
    result = wrapped_func(*args, **kwargs)
  File "/home/majid/.local/lib/python3.10/site-packages/scrapli/driver/generic/sync_driver.py", line 438, in send_interactive
    raw_response, processed_response = self.channel.send_inputs_interact(
  File "/home/majid/.local/lib/python3.10/site-packages/scrapli/decorators.py", line 280, in decorate
    return self._multiprocessing_timeout(
  File "/home/majid/.local/lib/python3.10/site-packages/scrapli/decorators.py", line 341, in _multiprocessing_timeout
    return future.result()
  File "/usr/lib/python3.10/concurrent/futures/_base.py", line 439, in result
    return self.__get_result()
  File "/usr/lib/python3.10/concurrent/futures/_base.py", line 391, in __get_result
    raise self._exception
  File "/usr/lib/python3.10/concurrent/futures/thread.py", line 58, in run
    result = self.fn(*self.args, **self.kwargs)
  File "/home/majid/.local/lib/python3.10/site-packages/scrapli/channel/sync_channel.py", line 646, in send_inputs_interact
    buf += self._read_until_explicit_prompt(prompts=prompts)
  File "/home/majid/.local/lib/python3.10/site-packages/scrapli/channel/sync_channel.py", line 177, in _read_until_explicit_prompt
    read_buf.write(self.read())
  File "/home/majid/.local/lib/python3.10/site-packages/scrapli/channel/sync_channel.py", line 69, in read
    buf = self.transport.read()
  File "/home/majid/.local/lib/python3.10/site-packages/scrapli/decorators.py", line 99, in decorate
    return self._multiprocessing_timeout(
  File "/home/majid/.local/lib/python3.10/site-packages/scrapli/decorators.py", line 176, in _multiprocessing_timeout
    self._handle_timeout()
  File "/home/majid/.local/lib/python3.10/site-packages/scrapli/decorators.py", line 152, in _handle_timeout
    raise ScrapliTimeout(self.message)
scrapli.exceptions.ScrapliTimeout: timed out reading from transport

2022-06-05 21:21:03,133 - nornir.core.task -    ERROR -      start() - Host 'R1': task 'interactive_commands_exmple' failed with traceback:
Traceback (most recent call last):
  File "/home/majid/.local/lib/python3.10/site-packages/nornir/core/task.py", line 99, in start
    r = self.task(self, **self.params)
  File "/home/majid/devnet/pyhton_nornir/4.nornir_scrapli_send_interactive.py", line 22, in interactive_commands_exmple
    task.run(task=send_interactive, interact_events=interact_lists, timeout_ops=200 )
  File "/home/majid/.local/lib/python3.10/site-packages/nornir/core/task.py", line 174, in run
    raise NornirSubTaskError(task=run_task, result=r)
nornir.core.exceptions.NornirSubTaskError: Subtask: send_interactive (failed)


2022-06-06 10:46:57,180 -  nornir.core -     INFO -        run() - Running task 'interactive_commands_exmple' with args {} on 1 hosts
2022-06-06 10:47:09,886 -  nornir.core -     INFO -        run() - Running task 'interactive_commands_exmple' with args {} on 1 hosts
2022-06-06 10:47:46,015 -  nornir.core -     INFO -        run() - Running task 'interactive_commands_exmple' with args {} on 1 hosts
2022-06-06 10:48:05,232 -  nornir.core -     INFO -        run() - Running task 'interactive_commands_exmple' with args {} on 1 hosts
2022-06-06 10:48:26,678 -  nornir.core -     INFO -        run() - Running task 'interactive_commands_exmple' with args {} on 1 hosts
2022-06-06 10:48:39,886 -  nornir.core -     INFO -        run() - Running task 'interactive_commands_exmple' with args {} on 1 hosts
2022-06-06 10:48:48,349 -  nornir.core -     INFO -        run() - Running task 'interactive_commands_exmple' with args {} on 1 hosts
2022-06-06 10:49:00,692 -  nornir.core -     INFO -        run() - Running task 'interactive_commands_exmple' with args {} on 1 hosts
2022-06-06 10:49:12,875 -  nornir.core -     INFO -        run() - Running task 'interactive_commands_exmple' with args {} on 1 hosts
2022-06-06 10:49:48,125 -  nornir.core -     INFO -        run() - Running task 'interactive_commands_exmple' with args {} on 1 hosts
2022-06-06 11:00:54,629 -  nornir.core -     INFO -        run() - Running task 'interactive_commands_exmple' with args {} on 1 hosts
2022-06-06 11:01:41,374 -  nornir.core -     INFO -        run() - Running task 'interactive_commands_exmple' with args {} on 1 hosts
2022-06-06 11:03:17,419 -  nornir.core -     INFO -        run() - Running task 'interactive_commands_exmple' with args {} on 1 hosts
2022-06-06 11:41:32,634 -  nornir.core -     INFO -        run() - Running task 'interactive_commands_exmple' with args {} on 1 hosts
2022-06-06 11:41:48,515 -  nornir.core -     INFO -        run() - Running task 'interactive_commands_exmple' with args {} on 1 hosts
2022-06-06 11:47:26,637 -  nornir.core -     INFO -        run() - Running task 'interactive_commands_exmple' with args {} on 1 hosts
2022-06-06 11:48:10,736 -  nornir.core -     INFO -        run() - Running task 'interactive_commands_exmple' with args {} on 1 hosts
2022-06-06 11:48:56,980 -  nornir.core -     INFO -        run() - Running task 'interactive_commands_exmple' with args {} on 1 hosts
2022-06-06 11:49:46,519 -  nornir.core -     INFO -        run() - Running task 'interactive_commands_exmple' with args {} on 1 hosts
2022-06-06 11:50:46,923 -  nornir.core -     INFO -        run() - Running task 'interactive_commands_exmple' with args {} on 1 hosts
2022-06-06 11:59:37,109 -  nornir.core -     INFO -        run() - Running task 'interactive_commands_exmple' with args {} on 1 hosts
2022-06-06 21:47:53,792 -  nornir.core -     INFO -        run() - Running task 'interactive_commands_exmple' with args {} on 1 hosts
2022-06-06 21:48:03,375 -  nornir.core -     INFO -        run() - Running task 'interactive_commands_exmple' with args {} on 1 hosts
2022-06-06 22:14:41,929 -  nornir.core -     INFO -        run() - Running task 'interactive_commands_exmple' with args {} on 1 hosts
2022-06-06 22:30:53,215 -  nornir.core -     INFO -        run() - Running task 'interactive_commands_exmple' with args {} on 1 hosts
2022-06-06 22:32:49,657 -  nornir.core -     INFO -        run() - Running task 'interactive_commands_exmple' with args {} on 1 hosts
2022-06-09 21:58:01,513 -  nornir.core -     INFO -        run() - Running task 'netmiko_send_command' with args {'command_string': 'show ip int brief | exc unass'} on 1 hosts
2022-06-09 21:58:55,739 -  nornir.core -     INFO -        run() - Running task 'netmiko_send_commands_exmple' with args {} on 1 hosts
2022-06-09 22:00:14,721 -  nornir.core -     INFO -        run() - Running task 'netmiko_send_commands_exmple' with args {} on 1 hosts
2022-06-09 22:12:55,347 -  nornir.core -     INFO -        run() - Running task 'netmiko_send_commands_example' with args {} on 1 hosts
2022-06-09 22:13:04,297 -  nornir.core -     INFO -        run() - Running task 'netmiko_send_commands_example' with args {} on 1 hosts
2022-06-09 22:14:25,534 -  nornir.core -     INFO -        run() - Running task 'netmiko_send_config_exmaple' with args {} on 1 hosts
2022-06-09 22:15:19,951 -  nornir.core -     INFO -        run() - Running task 'netmiko_send_config_exmaple' with args {} on 1 hosts
2022-06-09 22:16:03,960 -  nornir.core -     INFO -        run() - Running task 'netmiko_send_config_exmaple' with args {} on 1 hosts
2022-06-09 22:18:46,766 -  nornir.core -     INFO -        run() - Running task 'netmiko_send_config_exmaple' with args {} on 1 hosts
2022-06-09 22:20:13,560 -  nornir.core -     INFO -        run() - Running task 'netmiko_send_config_exmaple' with args {} on 1 hosts
2022-06-09 22:20:14,398 -  nornir.core -     INFO -        run() - Running task 'netmiko_save_config_exmaple' with args {} on 1 hosts
2022-06-09 22:23:14,359 -  nornir.core -     INFO -        run() - Running task 'netmiko_send_config_exmaple' with args {} on 1 hosts
2022-06-09 22:23:15,216 -  nornir.core -     INFO -        run() - Running task 'netmiko_save_config_exmaple' with args {} on 1 hosts
2022-06-09 22:23:41,806 -  nornir.core -     INFO -        run() - Running task 'netmiko_send_config_exmaple' with args {} on 1 hosts
2022-06-09 22:23:42,612 -  nornir.core -     INFO -        run() - Running task 'netmiko_save_config_exmaple' with args {} on 1 hosts
2022-06-09 22:23:54,544 -  nornir.core -     INFO -        run() - Running task 'netmiko_send_config_exmaple' with args {} on 1 hosts
2022-06-09 22:23:55,382 -  nornir.core -     INFO -        run() - Running task 'netmiko_save_config_exmaple' with args {} on 1 hosts
2022-06-09 22:24:07,952 -  nornir.core -     INFO -        run() - Running task 'netmiko_send_config_exmaple' with args {} on 1 hosts
2022-06-09 22:24:08,778 -  nornir.core -     INFO -        run() - Running task 'netmiko_save_config_exmaple' with args {} on 1 hosts
2022-06-09 22:24:17,350 -  nornir.core -     INFO -        run() - Running task 'netmiko_send_config_exmaple' with args {} on 1 hosts
2022-06-09 22:24:18,170 -  nornir.core -     INFO -        run() - Running task 'netmiko_save_config_exmaple' with args {} on 1 hosts
2022-06-09 22:24:27,558 -  nornir.core -     INFO -        run() - Running task 'netmiko_send_config_exmaple' with args {} on 1 hosts
2022-06-09 22:24:28,376 -  nornir.core -     INFO -        run() - Running task 'netmiko_save_config_exmaple' with args {} on 1 hosts
2022-06-09 22:26:26,484 -  nornir.core -     INFO -        run() - Running task 'netmiko_send_config_exmaple' with args {} on 1 hosts
2022-06-09 22:26:27,104 - nornir.core.task -    ERROR -      start() - Host 'R1': task 'netmiko_send_config' failed with traceback:
Traceback (most recent call last):
  File "/home/majid/.local/lib/python3.10/site-packages/nornir/core/task.py", line 99, in start
    r = self.task(self, **self.params)
  File "/home/majid/.local/lib/python3.10/site-packages/nornir_netmiko/tasks/netmiko_send_config.py", line 40, in netmiko_send_config
    result = net_connect.send_config_from_file(config_file=config_file, **kwargs)
  File "/home/majid/.local/lib/python3.10/site-packages/netmiko/base_connection.py", line 1808, in send_config_from_file
    with io.open(config_file, "rt", encoding="utf-8") as cfg_file:
TypeError: expected str, bytes or os.PathLike object, not list

2022-06-09 22:26:27,104 - nornir.core.task -    ERROR -      start() - Host 'R1': task 'netmiko_send_config_exmaple' failed with traceback:
Traceback (most recent call last):
  File "/home/majid/.local/lib/python3.10/site-packages/nornir/core/task.py", line 99, in start
    r = self.task(self, **self.params)
  File "/home/majid/devnet/pyhton_nornir/5.3.nornir_netmiko_send_config_from_file.py", line 10, in netmiko_send_config_exmaple
    task.run(task=netmiko_send_config, config_file=["config_list"])
  File "/home/majid/.local/lib/python3.10/site-packages/nornir/core/task.py", line 174, in run
    raise NornirSubTaskError(task=run_task, result=r)
nornir.core.exceptions.NornirSubTaskError: Subtask: netmiko_send_config (failed)


2022-06-09 22:26:27,105 -  nornir.core -     INFO -        run() - Running task 'netmiko_save_config_exmaple' with args {} on 1 hosts
2022-06-09 22:27:47,944 -  nornir.core -     INFO -        run() - Running task 'netmiko_send_config_exmaple' with args {} on 1 hosts
2022-06-09 22:28:45,205 -  nornir.core -     INFO -        run() - Running task 'netmiko_send_config_exmaple' with args {} on 1 hosts
2022-06-09 22:29:12,234 -  nornir.core -     INFO -        run() - Running task 'netmiko_send_config_exmaple' with args {} on 1 hosts
2022-06-09 22:29:12,855 - nornir.core.task -    ERROR -      start() - Host 'R1': task 'netmiko_send_config' failed with traceback:
Traceback (most recent call last):
  File "/home/majid/.local/lib/python3.10/site-packages/nornir/core/task.py", line 99, in start
    r = self.task(self, **self.params)
  File "/home/majid/.local/lib/python3.10/site-packages/nornir_netmiko/tasks/netmiko_send_config.py", line 40, in netmiko_send_config
    result = net_connect.send_config_from_file(config_file=config_file, **kwargs)
  File "/home/majid/.local/lib/python3.10/site-packages/netmiko/base_connection.py", line 1808, in send_config_from_file
    with io.open(config_file, "rt", encoding="utf-8") as cfg_file:
TypeError: expected str, bytes or os.PathLike object, not list

2022-06-09 22:29:12,856 - nornir.core.task -    ERROR -      start() - Host 'R1': task 'netmiko_send_config_exmaple' failed with traceback:
Traceback (most recent call last):
  File "/home/majid/.local/lib/python3.10/site-packages/nornir/core/task.py", line 99, in start
    r = self.task(self, **self.params)
  File "/home/majid/devnet/pyhton_nornir/5.3.nornir_netmiko_send_config_from_file.py", line 10, in netmiko_send_config_exmaple
    task.run(task=netmiko_send_config, config_file=["config_list"])
  File "/home/majid/.local/lib/python3.10/site-packages/nornir/core/task.py", line 174, in run
    raise NornirSubTaskError(task=run_task, result=r)
nornir.core.exceptions.NornirSubTaskError: Subtask: netmiko_send_config (failed)


2022-06-09 22:29:12,857 -  nornir.core -     INFO -        run() - Running task 'netmiko_save_config_exmaple' with args {} on 1 hosts
2022-06-09 22:32:45,166 -  nornir.core -     INFO -        run() - Running task 'netmiko_send_config_from_file_exmaple' with args {} on 1 hosts
2022-06-09 22:32:45,807 - nornir.core.task -    ERROR -      start() - Host 'R1': task 'netmiko_send_config' failed with traceback:
Traceback (most recent call last):
  File "/home/majid/.local/lib/python3.10/site-packages/nornir/core/task.py", line 99, in start
    r = self.task(self, **self.params)
  File "/home/majid/.local/lib/python3.10/site-packages/nornir_netmiko/tasks/netmiko_send_config.py", line 40, in netmiko_send_config
    result = net_connect.send_config_from_file(config_file=config_file, **kwargs)
  File "/home/majid/.local/lib/python3.10/site-packages/netmiko/base_connection.py", line 1808, in send_config_from_file
    with io.open(config_file, "rt", encoding="utf-8") as cfg_file:
TypeError: expected str, bytes or os.PathLike object, not list

2022-06-09 22:32:45,808 - nornir.core.task -    ERROR -      start() - Host 'R1': task 'netmiko_send_config_from_file_exmaple' failed with traceback:
Traceback (most recent call last):
  File "/home/majid/.local/lib/python3.10/site-packages/nornir/core/task.py", line 99, in start
    r = self.task(self, **self.params)
  File "/home/majid/devnet/pyhton_nornir/5.3.nornir_netmiko_send_config_from_file.py", line 9, in netmiko_send_config_from_file_exmaple
    task.run(task=netmiko_send_config, config_file=["config_list"])
  File "/home/majid/.local/lib/python3.10/site-packages/nornir/core/task.py", line 174, in run
    raise NornirSubTaskError(task=run_task, result=r)
nornir.core.exceptions.NornirSubTaskError: Subtask: netmiko_send_config (failed)


2022-06-09 22:32:45,809 -  nornir.core -     INFO -        run() - Running task 'netmiko_save_config_exmaple' with args {} on 1 hosts
2022-06-09 22:34:58,837 -  nornir.core -     INFO -        run() - Running task 'netmiko_send_config_from_file_exmaple' with args {} on 1 hosts
2022-06-09 22:34:59,651 -  nornir.core -     INFO -        run() - Running task 'netmiko_save_config_exmaple' with args {} on 1 hosts
2022-06-09 23:15:39,668 -  nornir.core -     INFO -        run() - Running task 'netmiko_send_commands_example' with args {} on 1 hosts
2022-06-09 23:16:20,888 -  nornir.core -     INFO -        run() - Running task 'netmiko_send_commands_example' with args {} on 1 hosts
2022-06-09 23:17:21,439 -  nornir.core -     INFO -        run() - Running task 'netmiko_send_config_exmaple' with args {} on 1 hosts
2022-06-09 23:19:16,317 -  nornir.core -     INFO -        run() - Running task 'netmiko_send_config_from_file_exmaple' with args {} on 1 hosts
2022-06-09 23:19:18,246 -  nornir.core -     INFO -        run() - Running task 'netmiko_save_config_exmaple' with args {} on 1 hosts
2022-06-11 23:40:50,230 -  nornir.core -     INFO -        run() - Running task 'napalm_get_example' with args {} on 1 hosts
2022-06-11 23:42:25,100 -  nornir.core -     INFO -        run() - Running task 'napalm_get_example' with args {} on 1 hosts
2022-06-11 23:42:52,157 -  nornir.core -     INFO -        run() - Running task 'napalm_get_example' with args {} on 1 hosts
2022-06-11 23:43:27,073 -  nornir.core -     INFO -        run() - Running task 'napalm_get_example' with args {} on 1 hosts
2022-06-12 00:20:17,413 -  nornir.core -     INFO -        run() - Running task 'napalm_get_example' with args {} on 1 hosts
2022-06-12 00:36:12,856 -  nornir.core -     INFO -        run() - Running task 'napalm_get_example' with args {} on 1 hosts
2022-06-12 00:40:04,066 -  nornir.core -     INFO -        run() - Running task 'napalm_get_example' with args {} on 1 hosts
2022-06-12 00:40:04,795 - nornir.core.task -    ERROR -      start() - Host 'R1': task 'napalm_get_example' failed with traceback:
Traceback (most recent call last):
  File "/home/majid/.local/lib/python3.10/site-packages/nornir/core/task.py", line 99, in start
    r = self.task(self, **self.params)
  File "/home/majid/devnet/pyhton_nornir/6.1.nornir_napalm_get_result_parsing.py", line 10, in napalm_get_example
    print(interfaces)
NameError: name 'interfaces' is not defined

2022-06-12 00:40:23,421 -  nornir.core -     INFO -        run() - Running task 'napalm_get_example' with args {} on 1 hosts
2022-06-12 00:40:24,128 - nornir.core.task -    ERROR -      start() - Host 'R1': task 'napalm_get_example' failed with traceback:
Traceback (most recent call last):
  File "/home/majid/.local/lib/python3.10/site-packages/nornir/core/task.py", line 99, in start
    r = self.task(self, **self.params)
  File "/home/majid/devnet/pyhton_nornir/6.1.nornir_napalm_get_result_parsing.py", line 10, in napalm_get_example
    print(interfaces)
NameError: name 'interfaces' is not defined

2022-06-12 00:40:40,010 -  nornir.core -     INFO -        run() - Running task 'napalm_get_example' with args {} on 1 hosts
2022-06-12 00:40:59,962 -  nornir.core -     INFO -        run() - Running task 'napalm_get_example' with args {} on 1 hosts
2022-06-12 00:41:00,700 - nornir.core.task -    ERROR -      start() - Host 'R1': task 'napalm_get_example' failed with traceback:
Traceback (most recent call last):
  File "/home/majid/.local/lib/python3.10/site-packages/nornir/core/task.py", line 99, in start
    r = self.task(self, **self.params)
  File "/home/majid/devnet/pyhton_nornir/6.1.nornir_napalm_get_result_parsing.py", line 10, in napalm_get_example
    print("hello"+interfaces)
TypeError: can only concatenate str (not "MultiResult") to str

2022-06-12 01:02:03,168 -  nornir.core -     INFO -        run() - Running task 'napalm_get_example' with args {} on 1 hosts
2022-06-12 01:02:30,555 -  nornir.core -     INFO -        run() - Running task 'napalm_get_example' with args {} on 1 hosts
2022-06-12 01:02:45,689 -  nornir.core -     INFO -        run() - Running task 'napalm_get_example' with args {} on 1 hosts
2022-06-12 01:03:05,197 -  nornir.core -     INFO -        run() - Running task 'napalm_get_example' with args {} on 1 hosts
2022-06-12 01:03:05,893 - nornir.core.task -    ERROR -      start() - Host 'R1': task 'napalm_get_example' failed with traceback:
Traceback (most recent call last):
  File "/home/majid/.local/lib/python3.10/site-packages/nornir/core/task.py", line 99, in start
    r = self.task(self, **self.params)
  File "/home/majid/devnet/pyhton_nornir/6.1.nornir_napalm_get_result_parsing.py", line 10, in napalm_get_example
    print(interfaces.type)
  File "/home/majid/.local/lib/python3.10/site-packages/nornir/core/task.py", line 255, in __getattr__
    return getattr(self[0], name)
AttributeError: 'Result' object has no attribute 'type'

2022-06-12 01:04:20,435 -  nornir.core -     INFO -        run() - Running task 'napalm_get_example' with args {} on 1 hosts
2022-06-12 01:04:21,156 - nornir.core.task -    ERROR -      start() - Host 'R1': task 'napalm_get_example' failed with traceback:
Traceback (most recent call last):
  File "/home/majid/.local/lib/python3.10/site-packages/nornir/core/task.py", line 99, in start
    r = self.task(self, **self.params)
  File "/home/majid/devnet/pyhton_nornir/6.1.nornir_napalm_get_result_parsing.py", line 10, in napalm_get_example
    print(task.host["R1"])
  File "/home/majid/.local/lib/python3.10/site-packages/nornir/core/inventory.py", line 350, in __getitem__
    return self.data[item]
KeyError: 'R1'

2022-06-12 01:04:47,903 -  nornir.core -     INFO -        run() - Running task 'napalm_get_example' with args {} on 1 hosts
2022-06-12 01:05:06,350 -  nornir.core -     INFO -        run() - Running task 'napalm_get_example' with args {} on 1 hosts
2022-06-12 01:05:07,078 - nornir.core.task -    ERROR -      start() - Host 'R1': task 'napalm_get_example' failed with traceback:
Traceback (most recent call last):
  File "/home/majid/.local/lib/python3.10/site-packages/nornir/core/task.py", line 99, in start
    r = self.task(self, **self.params)
  File "/home/majid/devnet/pyhton_nornir/6.1.nornir_napalm_get_result_parsing.py", line 10, in napalm_get_example
    print(task.hosts)
AttributeError: 'Task' object has no attribute 'hosts'

2022-06-12 01:05:17,232 -  nornir.core -     INFO -        run() - Running task 'napalm_get_example' with args {} on 1 hosts
2022-06-12 01:05:17,947 - nornir.core.task -    ERROR -      start() - Host 'R1': task 'napalm_get_example' failed with traceback:
Traceback (most recent call last):
  File "/home/majid/.local/lib/python3.10/site-packages/nornir/core/task.py", line 99, in start
    r = self.task(self, **self.params)
  File "/home/majid/devnet/pyhton_nornir/6.1.nornir_napalm_get_result_parsing.py", line 10, in napalm_get_example
    print(task.hosts["R1"])
AttributeError: 'Task' object has no attribute 'hosts'

2022-06-12 01:06:00,603 -  nornir.core -     INFO -        run() - Running task 'napalm_get_example' with args {} on 1 hosts
2022-06-12 01:06:01,347 - nornir.core.task -    ERROR -      start() - Host 'R1': task 'napalm_get_example' failed with traceback:
Traceback (most recent call last):
  File "/home/majid/.local/lib/python3.10/site-packages/nornir/core/task.py", line 99, in start
    r = self.task(self, **self.params)
  File "/home/majid/devnet/pyhton_nornir/6.1.nornir_napalm_get_result_parsing.py", line 9, in napalm_get_example
    task.host["facts"]=interafces.result
NameError: name 'interafces' is not defined

2022-06-12 01:06:31,700 -  nornir.core -     INFO -        run() - Running task 'napalm_get_example' with args {} on 1 hosts
2022-06-12 01:06:32,422 - nornir.core.task -    ERROR -      start() - Host 'R1': task 'napalm_get_example' failed with traceback:
Traceback (most recent call last):
  File "/home/majid/.local/lib/python3.10/site-packages/nornir/core/task.py", line 99, in start
    r = self.task(self, **self.params)
  File "/home/majid/devnet/pyhton_nornir/6.1.nornir_napalm_get_result_parsing.py", line 9, in napalm_get_example
    task.host["facts"]=interafces.result
NameError: name 'interafces' is not defined

2022-06-12 01:42:16,793 -  nornir.core -     INFO -        run() - Running task 'napalm_get_example' with args {} on 1 hosts
2022-06-12 01:42:17,513 - nornir.core.task -    ERROR -      start() - Host 'R1': task 'napalm_get_example' failed with traceback:
Traceback (most recent call last):
  File "/home/majid/.local/lib/python3.10/site-packages/nornir/core/task.py", line 99, in start
    r = self.task(self, **self.params)
  File "/home/majid/devnet/pyhton_nornir/6.1.nornir_napalm_get_result_parsing.py", line 10, in napalm_get_example
    print(task.host["R1"]["facts"])
  File "/home/majid/.local/lib/python3.10/site-packages/nornir/core/inventory.py", line 350, in __getitem__
    return self.data[item]
KeyError: 'R1'

2022-06-12 01:44:30,729 -  nornir.core -     INFO -        run() - Running task 'napalm_get_example' with args {} on 1 hosts
2022-06-12 01:44:31,452 - nornir.core.task -    ERROR -      start() - Host 'R1': task 'napalm_get_example' failed with traceback:
Traceback (most recent call last):
  File "/home/majid/.local/lib/python3.10/site-packages/nornir/core/task.py", line 99, in start
    r = self.task(self, **self.params)
  File "/home/majid/devnet/pyhton_nornir/6.1.nornir_napalm_get_result_parsing.py", line 11, in napalm_get_example
    rprint(task.host["R1"]["facts"])
  File "/home/majid/.local/lib/python3.10/site-packages/nornir/core/inventory.py", line 350, in __getitem__
    return self.data[item]
KeyError: 'R1'

2022-06-12 01:45:53,464 -  nornir.core -     INFO -        run() - Running task 'napalm_get_example' with args {} on 1 hosts
2022-06-12 01:45:54,249 - nornir.core.task -    ERROR -      start() - Host 'R1': task 'napalm_get_example' failed with traceback:
Traceback (most recent call last):
  File "/home/majid/.local/lib/python3.10/site-packages/nornir/core/task.py", line 99, in start
    r = self.task(self, **self.params)
  File "/home/majid/devnet/pyhton_nornir/6.1.nornir_napalm_get_result_parsing.py", line 12, in napalm_get_example
    rprint(task.host["R1"]["facts"])
  File "/home/majid/.local/lib/python3.10/site-packages/nornir/core/inventory.py", line 350, in __getitem__
    return self.data[item]
KeyError: 'R1'

2022-06-12 01:46:45,909 -  nornir.core -     INFO -        run() - Running task 'napalm_get_example' with args {} on 1 hosts
2022-06-12 01:47:01,552 -  nornir.core -     INFO -        run() - Running task 'napalm_get_example' with args {} on 1 hosts
2022-06-12 01:47:14,141 -  nornir.core -     INFO -        run() - Running task 'napalm_get_example' with args {} on 1 hosts
2022-06-12 01:47:37,220 -  nornir.core -     INFO -        run() - Running task 'napalm_get_example' with args {} on 1 hosts
2022-06-12 01:48:07,230 -  nornir.core -     INFO -        run() - Running task 'napalm_get_example' with args {} on 1 hosts
2022-06-12 01:49:29,729 -  nornir.core -     INFO -        run() - Running task 'napalm_get_example' with args {} on 1 hosts
2022-06-12 01:50:08,779 -  nornir.core -     INFO -        run() - Running task 'napalm_get_example' with args {} on 1 hosts
2022-06-12 01:50:27,055 -  nornir.core -     INFO -        run() - Running task 'napalm_get_example' with args {} on 1 hosts
2022-06-12 01:51:29,188 -  nornir.core -     INFO -        run() - Running task 'napalm_get_example' with args {} on 1 hosts
2022-06-12 01:51:36,957 -  nornir.core -     INFO -        run() - Running task 'napalm_get_example' with args {} on 1 hosts
2022-06-12 01:51:48,858 -  nornir.core -     INFO -        run() - Running task 'napalm_get_example' with args {} on 1 hosts
2022-06-12 01:52:01,730 -  nornir.core -     INFO -        run() - Running task 'napalm_get_example' with args {} on 1 hosts
2022-06-12 01:52:02,462 - nornir.core.task -    ERROR -      start() - Host 'R1': task 'napalm_get_example' failed with traceback:
Traceback (most recent call last):
  File "/home/majid/.local/lib/python3.10/site-packages/nornir/core/task.py", line 99, in start
    r = self.task(self, **self.params)
  File "/home/majid/devnet/pyhton_nornir/6.1.nornir_napalm_get_result_parsing.py", line 11, in napalm_get_example
    print(interfaces.type)
  File "/home/majid/.local/lib/python3.10/site-packages/nornir/core/task.py", line 255, in __getattr__
    return getattr(self[0], name)
AttributeError: 'Result' object has no attribute 'type'

2022-06-12 01:52:21,676 -  nornir.core -     INFO -        run() - Running task 'napalm_get_example' with args {} on 1 hosts
2022-06-12 01:56:48,019 -  nornir.core -     INFO -        run() - Running task 'napalm_get_example' with args {} on 1 hosts
2022-06-12 01:57:31,783 -  nornir.core -     INFO -        run() - Running task 'napalm_get_example' with args {} on 1 hosts
2022-06-12 01:57:49,027 -  nornir.core -     INFO -        run() - Running task 'napalm_get_example' with args {} on 1 hosts
2022-06-12 01:59:09,340 -  nornir.core -     INFO -        run() - Running task 'napalm_get_example' with args {} on 1 hosts
2022-06-12 01:59:18,250 -  nornir.core -     INFO -        run() - Running task 'napalm_get_example' with args {} on 1 hosts
2022-06-12 01:59:44,671 -  nornir.core -     INFO -        run() - Running task 'napalm_get_example' with args {} on 1 hosts
2022-06-12 21:50:28,595 -  nornir.core -     INFO -        run() - Running task 'napalm_cli_commands_example' with args {} on 1 hosts
2022-06-12 21:50:53,572 -  nornir.core -     INFO -        run() - Running task 'napalm_cli_commands_example' with args {} on 1 hosts
2022-06-12 22:22:26,499 -  nornir.core -     INFO -        run() - Running task 'napalm_get_example' with args {} on 1 hosts
2022-06-12 22:26:27,152 -  nornir.core -     INFO -        run() - Running task 'napalm_cli_commands_example' with args {} on 1 hosts
2022-06-12 22:52:01,573 -  nornir.core -     INFO -        run() - Running task 'napalm_get_example' with args {} on 1 hosts
2022-06-12 22:52:02,394 - nornir.core.task -    ERROR -      start() - Host 'R1': task 'napalm_get_example' failed with traceback:
Traceback (most recent call last):
  File "/home/majid/.local/lib/python3.10/site-packages/nornir/core/task.py", line 99, in start
    r = self.task(self, **self.params)
  File "/home/majid/devnet/pyhton_nornir/6.2.nornir_napalm_get_result_parsing.py", line 19, in napalm_get_example
    rprint(config.result["get_config"]["running"])
NameError: name 'config' is not defined

2022-06-12 23:03:21,550 -  nornir.core -     INFO -        run() - Running task 'napalm_get_example' with args {} on 1 hosts
2022-06-12 23:04:51,662 -  nornir.core -     INFO -        run() - Running task 'napalm_get_example' with args {} on 1 hosts
2022-06-12 23:04:52,475 - nornir.core.task -    ERROR -      start() - Host 'R1': task 'napalm_get_example' failed with traceback:
Traceback (most recent call last):
  File "/home/majid/.local/lib/python3.10/site-packages/nornir/core/task.py", line 99, in start
    r = self.task(self, **self.params)
  File "/home/majid/devnet/pyhton_nornir/6.2.nornir_napalm_get_result_parsing.py", line 19, in napalm_get_example
    rprint(config.result["get_config"]["running"])
NameError: name 'config' is not defined

2022-06-12 23:05:22,544 -  nornir.core -     INFO -        run() - Running task 'napalm_get_example' with args {} on 1 hosts
2022-06-12 23:05:23,403 - nornir.core.task -    ERROR -      start() - Host 'R1': task 'napalm_get_example' failed with traceback:
Traceback (most recent call last):
  File "/home/majid/.local/lib/python3.10/site-packages/nornir/core/task.py", line 99, in start
    r = self.task(self, **self.params)
  File "/home/majid/devnet/pyhton_nornir/6.2.nornir_napalm_get_result_parsing.py", line 19, in napalm_get_example
    rprint(config.result["get_config"]["running"])
NameError: name 'config' is not defined

2022-06-12 23:05:54,140 -  nornir.core -     INFO -        run() - Running task 'napalm_get_example' with args {} on 1 hosts
2022-06-12 23:05:55,000 - nornir.core.task -    ERROR -      start() - Host 'R1': task 'napalm_get_example' failed with traceback:
Traceback (most recent call last):
  File "/home/majid/.local/lib/python3.10/site-packages/nornir/core/task.py", line 99, in start
    r = self.task(self, **self.params)
  File "/home/majid/devnet/pyhton_nornir/6.2.nornir_napalm_get_result_parsing.py", line 19, in napalm_get_example
    rprint(config.result["get_config"]["running"])
NameError: name 'config' is not defined

2022-06-12 23:06:07,449 -  nornir.core -     INFO -        run() - Running task 'napalm_get_example' with args {} on 1 hosts
2022-06-12 23:06:08,335 - nornir.core.task -    ERROR -      start() - Host 'R1': task 'napalm_get_example' failed with traceback:
Traceback (most recent call last):
  File "/home/majid/.local/lib/python3.10/site-packages/nornir/core/task.py", line 99, in start
    r = self.task(self, **self.params)
  File "/home/majid/devnet/pyhton_nornir/6.2.nornir_napalm_get_result_parsing.py", line 19, in napalm_get_example
    rprint(config.result["get_config"]["running"])
NameError: name 'config' is not defined

2022-06-12 23:06:41,331 -  nornir.core -     INFO -        run() - Running task 'napalm_get_example' with args {} on 1 hosts
2022-06-12 23:06:42,290 - nornir.core.task -    ERROR -      start() - Host 'R1': task 'napalm_get_example' failed with traceback:
Traceback (most recent call last):
  File "/home/majid/.local/lib/python3.10/site-packages/nornir/core/task.py", line 99, in start
    r = self.task(self, **self.params)
  File "/home/majid/devnet/pyhton_nornir/6.2.nornir_napalm_get_result_parsing.py", line 20, in napalm_get_example
    rprint(config.result["get_config"]["running"])
NameError: name 'config' is not defined

2022-06-12 23:06:52,438 -  nornir.core -     INFO -        run() - Running task 'napalm_get_example' with args {} on 1 hosts
2022-06-12 23:06:53,338 - nornir.core.task -    ERROR -      start() - Host 'R1': task 'napalm_get_example' failed with traceback:
Traceback (most recent call last):
  File "/home/majid/.local/lib/python3.10/site-packages/nornir/core/task.py", line 99, in start
    r = self.task(self, **self.params)
  File "/home/majid/devnet/pyhton_nornir/6.2.nornir_napalm_get_result_parsing.py", line 20, in napalm_get_example
    rprint(config.result["get_config"]["running"])
NameError: name 'config' is not defined

2022-06-12 23:07:15,669 -  nornir.core -     INFO -        run() - Running task 'napalm_get_example' with args {} on 1 hosts
2022-06-12 23:08:03,280 -  nornir.core -     INFO -        run() - Running task 'napalm_get_example' with args {} on 1 hosts
2022-06-15 14:16:16,894 -  nornir.core -     INFO -        run() - Running task 'netmiko_send_config_exmaple' with args {} on 1 hosts
2022-06-15 14:17:20,499 -  nornir.core -     INFO -        run() - Running task 'netmiko_send_config_exmaple' with args {} on 1 hosts
2022-06-15 14:17:34,278 -  nornir.core -     INFO -        run() - Running task 'netmiko_send_config_exmaple' with args {} on 1 hosts
2022-06-15 14:55:45,227 -  nornir.core -     INFO -        run() - Running task 'napalm_send_config_exmaple' with args {} on 1 hosts
2022-06-15 14:55:46,146 - nornir.core.task -    ERROR -      start() - Host 'R1': task 'napalm_configure' failed with traceback:
Traceback (most recent call last):
  File "/home/majid/.local/lib/python3.10/site-packages/nornir/core/task.py", line 99, in start
    r = self.task(self, **self.params)
  File "/home/majid/.local/lib/python3.10/site-packages/nornir_napalm/plugins/tasks/napalm_configure.py", line 35, in napalm_configure
    device.load_merge_candidate(filename=filename, config=configuration)
  File "/home/majid/.local/lib/python3.10/site-packages/napalm/ios/ios.py", line 316, in load_merge_candidate
    return_status, msg = self._load_candidate_wrapper(
  File "/home/majid/.local/lib/python3.10/site-packages/napalm/ios/ios.py", line 283, in _load_candidate_wrapper
    (return_status, msg) = self._scp_file(
  File "/home/majid/.local/lib/python3.10/site-packages/napalm/ios/ios.py", line 626, in _scp_file
    return self._xfer_file(
  File "/home/majid/.local/lib/python3.10/site-packages/napalm/ios/ios.py", line 676, in _xfer_file
    with TransferClass(**kwargs) as transfer:
  File "/home/majid/.local/lib/python3.10/site-packages/netmiko/ssh_dispatcher.py", line 358, in FileTransfer
    return FileTransferClass(*args, **kwargs)
  File "/home/majid/.local/lib/python3.10/site-packages/netmiko/scp_handler.py", line 105, in __init__
    self.source_md5 = self.file_md5(source_file) if hash_supported else None
  File "/home/majid/.local/lib/python3.10/site-packages/netmiko/scp_handler.py", line 311, in file_md5
    with open(file_name, "rb") as f:
FileNotFoundError: [Errno 2] No such file or directory: 'napalm_configure'

2022-06-15 14:55:46,147 - nornir.core.task -    ERROR -      start() - Host 'R1': task 'napalm_send_config_exmaple' failed with traceback:
Traceback (most recent call last):
  File "/home/majid/.local/lib/python3.10/site-packages/nornir/core/task.py", line 99, in start
    r = self.task(self, **self.params)
  File "/home/majid/devnet/pyhton_nornir/6.3.nornir_napalm_send_config.py", line 8, in napalm_send_config_exmaple
    task.run(task=napalm_configure, filename="napalm_configure")
  File "/home/majid/.local/lib/python3.10/site-packages/nornir/core/task.py", line 174, in run
    raise NornirSubTaskError(task=run_task, result=r)
nornir.core.exceptions.NornirSubTaskError: Subtask: napalm_configure (failed)


2022-06-15 14:56:32,475 -  nornir.core -     INFO -        run() - Running task 'napalm_send_config_exmaple' with args {} on 1 hosts
2022-06-15 14:56:34,454 - nornir.core.task -    ERROR -      start() - Host 'R1': task 'napalm_configure' failed with traceback:
Traceback (most recent call last):
  File "/home/majid/.local/lib/python3.10/site-packages/nornir/core/task.py", line 99, in start
    r = self.task(self, **self.params)
  File "/home/majid/.local/lib/python3.10/site-packages/nornir_napalm/plugins/tasks/napalm_configure.py", line 35, in napalm_configure
    device.load_merge_candidate(filename=filename, config=configuration)
  File "/home/majid/.local/lib/python3.10/site-packages/napalm/ios/ios.py", line 316, in load_merge_candidate
    return_status, msg = self._load_candidate_wrapper(
  File "/home/majid/.local/lib/python3.10/site-packages/napalm/ios/ios.py", line 283, in _load_candidate_wrapper
    (return_status, msg) = self._scp_file(
  File "/home/majid/.local/lib/python3.10/site-packages/napalm/ios/ios.py", line 626, in _scp_file
    return self._xfer_file(
  File "/home/majid/.local/lib/python3.10/site-packages/napalm/ios/ios.py", line 695, in _xfer_file
    raise CommandErrorException(msg)
napalm.base.exceptions.CommandErrorException: SCP file transfers are not enabled. Configure 'ip scp server enable' on the device.

2022-06-15 14:56:34,455 - nornir.core.task -    ERROR -      start() - Host 'R1': task 'napalm_send_config_exmaple' failed with traceback:
Traceback (most recent call last):
  File "/home/majid/.local/lib/python3.10/site-packages/nornir/core/task.py", line 99, in start
    r = self.task(self, **self.params)
  File "/home/majid/devnet/pyhton_nornir/6.3.nornir_napalm_send_config.py", line 8, in napalm_send_config_exmaple
    task.run(task=napalm_configure, filename="config_list")
  File "/home/majid/.local/lib/python3.10/site-packages/nornir/core/task.py", line 174, in run
    raise NornirSubTaskError(task=run_task, result=r)
nornir.core.exceptions.NornirSubTaskError: Subtask: napalm_configure (failed)


2022-06-15 14:57:17,906 -  nornir.core -     INFO -        run() - Running task 'napalm_send_config_exmaple' with args {} on 1 hosts
2022-06-15 14:59:33,303 -  nornir.core -     INFO -        run() - Running task 'napalm_send_config_exmaple' with args {} on 1 hosts
2022-06-15 14:59:45,668 -  nornir.core -     INFO -        run() - Running task 'napalm_send_config_exmaple' with args {} on 1 hosts
2022-06-15 15:00:12,099 -  nornir.core -     INFO -        run() - Running task 'napalm_send_config_exmaple' with args {} on 1 hosts
2022-06-15 15:00:52,604 -  nornir.core -     INFO -        run() - Running task 'napalm_send_config_exmaple' with args {} on 1 hosts
2022-06-15 15:00:55,874 - nornir.core.task -    ERROR -      start() - Host 'R1': task 'napalm_configure' failed with traceback:
Traceback (most recent call last):
  File "/home/majid/.local/lib/python3.10/site-packages/nornir/core/task.py", line 99, in start
    r = self.task(self, **self.params)
  File "/home/majid/.local/lib/python3.10/site-packages/nornir_napalm/plugins/tasks/napalm_configure.py", line 43, in napalm_configure
    device.commit_config()
  File "/home/majid/.local/lib/python3.10/site-packages/napalm/ios/ios.py", line 542, in commit_config
    raise ReplaceConfigException(msg)
napalm.base.exceptions.ReplaceConfigException: napalm-ios replace() requires Cisco 'archive' feature to be enabled.

2022-06-15 15:00:55,875 - nornir.core.task -    ERROR -      start() - Host 'R1': task 'napalm_send_config_exmaple' failed with traceback:
Traceback (most recent call last):
  File "/home/majid/.local/lib/python3.10/site-packages/nornir/core/task.py", line 99, in start
    r = self.task(self, **self.params)
  File "/home/majid/devnet/pyhton_nornir/6.3.nornir_napalm_send_config.py", line 9, in napalm_send_config_exmaple
    task.run(task=napalm_configure, filename="config_list", replace=True)
  File "/home/majid/.local/lib/python3.10/site-packages/nornir/core/task.py", line 174, in run
    raise NornirSubTaskError(task=run_task, result=r)
nornir.core.exceptions.NornirSubTaskError: Subtask: napalm_configure (failed)


2022-06-15 15:01:43,677 -  nornir.core -     INFO -        run() - Running task 'napalm_send_config_exmaple' with args {} on 1 hosts
2022-06-15 15:01:46,449 - nornir.core.task -    ERROR -      start() - Host 'R1': task 'napalm_configure' failed with traceback:
Traceback (most recent call last):
  File "/home/majid/.local/lib/python3.10/site-packages/nornir/core/task.py", line 99, in start
    r = self.task(self, **self.params)
  File "/home/majid/.local/lib/python3.10/site-packages/nornir_napalm/plugins/tasks/napalm_configure.py", line 43, in napalm_configure
    device.commit_config()
  File "/home/majid/.local/lib/python3.10/site-packages/napalm/ios/ios.py", line 539, in commit_config
    raise ReplaceConfigException(msg)
napalm.base.exceptions.ReplaceConfigException: Candidate config could not be applied


%The input file is not a valid config file.


2022-06-15 15:01:46,450 - nornir.core.task -    ERROR -      start() - Host 'R1': task 'napalm_send_config_exmaple' failed with traceback:
Traceback (most recent call last):
  File "/home/majid/.local/lib/python3.10/site-packages/nornir/core/task.py", line 99, in start
    r = self.task(self, **self.params)
  File "/home/majid/devnet/pyhton_nornir/6.3.nornir_napalm_send_config.py", line 9, in napalm_send_config_exmaple
    task.run(task=napalm_configure, filename="config_list", replace=True)
  File "/home/majid/.local/lib/python3.10/site-packages/nornir/core/task.py", line 174, in run
    raise NornirSubTaskError(task=run_task, result=r)
nornir.core.exceptions.NornirSubTaskError: Subtask: napalm_configure (failed)


2022-06-15 16:03:45,671 -  nornir.core -     INFO -        run() - Running task 'napalm_send_config_exmaple' with args {} on 1 hosts
2022-06-15 16:11:30,787 -  nornir.core -     INFO -        run() - Running task 'napalm_send_config_exmaple' with args {} on 1 hosts
2022-06-15 16:12:10,916 -  nornir.core -     INFO -        run() - Running task 'napalm_send_config_exmaple' with args {} on 1 hosts
2022-06-15 16:12:59,548 -  nornir.core -     INFO -        run() - Running task 'napalm_send_config_exmaple' with args {} on 1 hosts
2022-06-15 16:13:36,377 -  nornir.core -     INFO -        run() - Running task 'napalm_send_config_exmaple' with args {} on 1 hosts
2022-06-15 16:14:11,827 -  nornir.core -     INFO -        run() - Running task 'napalm_send_config_exmaple' with args {} on 1 hosts
2022-06-15 16:16:01,871 -  nornir.core -     INFO -        run() - Running task 'napalm_send_config_exmaple' with args {} on 1 hosts
2022-06-15 16:16:05,148 - nornir.core.task -    ERROR -      start() - Host 'R1': task 'napalm_configure' failed with traceback:
Traceback (most recent call last):
  File "/home/majid/.local/lib/python3.10/site-packages/nornir/core/task.py", line 99, in start
    r = self.task(self, **self.params)
  File "/home/majid/.local/lib/python3.10/site-packages/nornir_napalm/plugins/tasks/napalm_configure.py", line 43, in napalm_configure
    device.commit_config()
  File "/home/majid/.local/lib/python3.10/site-packages/napalm/ios/ios.py", line 539, in commit_config
    raise ReplaceConfigException(msg)
napalm.base.exceptions.ReplaceConfigException: Candidate config could not be applied

%The input file is not a valid config file.


2022-06-15 16:16:05,149 - nornir.core.task -    ERROR -      start() - Host 'R1': task 'napalm_send_config_exmaple' failed with traceback:
Traceback (most recent call last):
  File "/home/majid/.local/lib/python3.10/site-packages/nornir/core/task.py", line 99, in start
    r = self.task(self, **self.params)
  File "/home/majid/devnet/pyhton_nornir/6.3.nornir_napalm_send_config.py", line 9, in napalm_send_config_exmaple
    task.run(task=napalm_configure, filename="config_list", replace=True)
  File "/home/majid/.local/lib/python3.10/site-packages/nornir/core/task.py", line 174, in run
    raise NornirSubTaskError(task=run_task, result=r)
nornir.core.exceptions.NornirSubTaskError: Subtask: napalm_configure (failed)


2022-06-15 17:04:00,911 -  nornir.core -     INFO -        run() - Running task 'napalm_get_example' with args {} on 1 hosts
2022-06-15 17:29:58,608 -  nornir.core -     INFO -        run() - Running task 'napalm_get_example' with args {} on 1 hosts
2022-06-15 17:29:59,544 - nornir.core.task -    ERROR -      start() - Host 'R1': task 'write_file' failed with traceback:
Traceback (most recent call last):
  File "/home/majid/.local/lib/python3.10/site-packages/nornir/core/task.py", line 99, in start
    r = self.task(self, **self.params)
TypeError: write_file() got an unexpected keyword argument 'content'

2022-06-15 17:29:59,545 - nornir.core.task -    ERROR -      start() - Host 'R1': task 'napalm_get_example' failed with traceback:
Traceback (most recent call last):
  File "/home/majid/.local/lib/python3.10/site-packages/nornir/core/task.py", line 99, in start
    r = self.task(self, **self.params)
  File "/home/majid/devnet/pyhton_nornir/6.4.nornir_utils_write_file.py", line 12, in napalm_get_example
    task.run(task=write_file, content=config, filename=f"{task.host}")
  File "/home/majid/.local/lib/python3.10/site-packages/nornir/core/task.py", line 174, in run
    raise NornirSubTaskError(task=run_task, result=r)
nornir.core.exceptions.NornirSubTaskError: Subtask: write_file (failed)


2022-06-15 17:30:45,529 -  nornir.core -     INFO -        run() - Running task 'napalm_get_example' with args {} on 1 hosts
2022-06-15 17:30:46,443 - nornir.core.task -    ERROR -      start() - Host 'R1': task 'write_file' failed with traceback:
Traceback (most recent call last):
  File "/home/majid/.local/lib/python3.10/site-packages/nornir/core/task.py", line 99, in start
    r = self.task(self, **self.params)
TypeError: write_file() got an unexpected keyword argument 'content'

2022-06-15 17:30:46,444 - nornir.core.task -    ERROR -      start() - Host 'R1': task 'napalm_get_example' failed with traceback:
Traceback (most recent call last):
  File "/home/majid/.local/lib/python3.10/site-packages/nornir/core/task.py", line 99, in start
    r = self.task(self, **self.params)
  File "/home/majid/devnet/pyhton_nornir/6.4.nornir_utils_write_file.py", line 12, in napalm_get_example
    task.run(task=write_file, content=config, filename=f"{task.host}")
  File "/home/majid/.local/lib/python3.10/site-packages/nornir/core/task.py", line 174, in run
    raise NornirSubTaskError(task=run_task, result=r)
nornir.core.exceptions.NornirSubTaskError: Subtask: write_file (failed)


2022-06-15 17:32:05,656 -  nornir.core -     INFO -        run() - Running task 'napalm_get_example' with args {} on 1 hosts
2022-06-15 17:32:06,576 - nornir.core.task -    ERROR -      start() - Host 'R1': task 'write_file' failed with traceback:
Traceback (most recent call last):
  File "/home/majid/.local/lib/python3.10/site-packages/nornir/core/task.py", line 99, in start
    r = self.task(self, **self.params)
TypeError: write_file() got an unexpected keyword argument 'content'

2022-06-15 17:32:06,576 - nornir.core.task -    ERROR -      start() - Host 'R1': task 'napalm_get_example' failed with traceback:
Traceback (most recent call last):
  File "/home/majid/.local/lib/python3.10/site-packages/nornir/core/task.py", line 99, in start
    r = self.task(self, **self.params)
  File "/home/majid/devnet/pyhton_nornir/6.4.nornir_utils_write_file.py", line 12, in napalm_get_example
    task.run(task=write_file, content=running_config, filename=f"{task.host}")
  File "/home/majid/.local/lib/python3.10/site-packages/nornir/core/task.py", line 174, in run
    raise NornirSubTaskError(task=run_task, result=r)
nornir.core.exceptions.NornirSubTaskError: Subtask: write_file (failed)


2022-06-15 17:33:38,670 -  nornir.core -     INFO -        run() - Running task 'napalm_get_example' with args {} on 1 hosts
2022-06-15 17:34:29,710 -  nornir.core -     INFO -        run() - Running task 'napalm_write_file_example' with args {} on 1 hosts
2022-06-15 17:55:02,551 -  nornir.core -     INFO -        run() - Running task 'napalm_send_config_exmaple' with args {} on 1 hosts
2022-06-15 17:58:07,569 -  nornir.core -     INFO -        run() - Running task 'napalm_send_config_exmaple' with args {} on 1 hosts
2022-06-15 17:58:10,880 - nornir.core.task -    ERROR -      start() - Host 'R1': task 'napalm_configure' failed with traceback:
Traceback (most recent call last):
  File "/home/majid/.local/lib/python3.10/site-packages/nornir/core/task.py", line 99, in start
    r = self.task(self, **self.params)
  File "/home/majid/.local/lib/python3.10/site-packages/nornir_napalm/plugins/tasks/napalm_configure.py", line 43, in napalm_configure
    device.commit_config()
  File "/home/majid/.local/lib/python3.10/site-packages/napalm/ios/ios.py", line 539, in commit_config
    raise ReplaceConfigException(msg)
napalm.base.exceptions.ReplaceConfigException: Candidate config could not be applied

%The input file is not a valid config file.


2022-06-15 17:58:10,881 - nornir.core.task -    ERROR -      start() - Host 'R1': task 'napalm_send_config_exmaple' failed with traceback:
Traceback (most recent call last):
  File "/home/majid/.local/lib/python3.10/site-packages/nornir/core/task.py", line 99, in start
    r = self.task(self, **self.params)
  File "/home/majid/devnet/pyhton_nornir/6.5.nornir_napalm_send_config_replace.py", line 9, in napalm_send_config_exmaple
    task.run(task=napalm_configure, filename=f"{task.host}_OSPF", replace=True)
  File "/home/majid/.local/lib/python3.10/site-packages/nornir/core/task.py", line 174, in run
    raise NornirSubTaskError(task=run_task, result=r)
nornir.core.exceptions.NornirSubTaskError: Subtask: napalm_configure (failed)


2022-06-15 18:01:45,578 -  nornir.core -     INFO -        run() - Running task 'napalm_send_config_exmaple' with args {} on 1 hosts
2022-06-15 18:14:55,579 -  nornir.core -     INFO -        run() - Running task 'napalm_send_config_exmaple' with args {} on 1 hosts
2022-06-15 18:14:57,500 - nornir.core.task -    ERROR -      start() - Host 'R1': task 'napalm_configure' failed with traceback:
Traceback (most recent call last):
  File "/home/majid/.local/lib/python3.10/site-packages/nornir/core/task.py", line 99, in start
    r = self.task(self, **self.params)
  File "/home/majid/.local/lib/python3.10/site-packages/nornir_napalm/plugins/tasks/napalm_configure.py", line 35, in napalm_configure
    device.load_merge_candidate(filename=filename, config=configuration)
  File "/home/majid/.local/lib/python3.10/site-packages/napalm/ios/ios.py", line 316, in load_merge_candidate
    return_status, msg = self._load_candidate_wrapper(
  File "/home/majid/.local/lib/python3.10/site-packages/napalm/ios/ios.py", line 283, in _load_candidate_wrapper
    (return_status, msg) = self._scp_file(
  File "/home/majid/.local/lib/python3.10/site-packages/napalm/ios/ios.py", line 626, in _scp_file
    return self._xfer_file(
  File "/home/majid/.local/lib/python3.10/site-packages/napalm/ios/ios.py", line 695, in _xfer_file
    raise CommandErrorException(msg)
napalm.base.exceptions.CommandErrorException: SCP file transfers are not enabled. Configure 'ip scp server enable' on the device.

2022-06-15 18:14:57,500 - nornir.core.task -    ERROR -      start() - Host 'R1': task 'napalm_send_config_exmaple' failed with traceback:
Traceback (most recent call last):
  File "/home/majid/.local/lib/python3.10/site-packages/nornir/core/task.py", line 99, in start
    r = self.task(self, **self.params)
  File "/home/majid/devnet/pyhton_nornir/6.3.nornir_napalm_send_config.py", line 9, in napalm_send_config_exmaple
    task.run(task=napalm_configure, filename="config_list")
  File "/home/majid/.local/lib/python3.10/site-packages/nornir/core/task.py", line 174, in run
    raise NornirSubTaskError(task=run_task, result=r)
nornir.core.exceptions.NornirSubTaskError: Subtask: napalm_configure (failed)


2022-06-15 18:15:24,644 -  nornir.core -     INFO -        run() - Running task 'napalm_send_config_exmaple' with args {} on 1 hosts
2022-06-15 18:15:48,170 -  nornir.core -     INFO -        run() - Running task 'napalm_write_file_example' with args {} on 1 hosts
2022-06-15 18:16:31,329 -  nornir.core -     INFO -        run() - Running task 'napalm_send_config_exmaple' with args {} on 1 hosts
2022-06-15 18:16:59,008 -  nornir.core -     INFO -        run() - Running task 'napalm_send_config_exmaple' with args {} on 1 hosts
2022-06-15 18:17:02,029 - nornir.core.task -    ERROR -      start() - Host 'R1': task 'napalm_configure' failed with traceback:
Traceback (most recent call last):
  File "/home/majid/.local/lib/python3.10/site-packages/nornir/core/task.py", line 99, in start
    r = self.task(self, **self.params)
  File "/home/majid/.local/lib/python3.10/site-packages/nornir_napalm/plugins/tasks/napalm_configure.py", line 43, in napalm_configure
    device.commit_config()
  File "/home/majid/.local/lib/python3.10/site-packages/napalm/ios/ios.py", line 542, in commit_config
    raise ReplaceConfigException(msg)
napalm.base.exceptions.ReplaceConfigException: napalm-ios replace() requires Cisco 'archive' feature to be enabled.

2022-06-15 18:17:02,029 - nornir.core.task -    ERROR -      start() - Host 'R1': task 'napalm_send_config_exmaple' failed with traceback:
Traceback (most recent call last):
  File "/home/majid/.local/lib/python3.10/site-packages/nornir/core/task.py", line 99, in start
    r = self.task(self, **self.params)
  File "/home/majid/devnet/pyhton_nornir/6.5.nornir_napalm_send_config_replace.py", line 9, in napalm_send_config_exmaple
    task.run(task=napalm_configure, filename=f"{task.host}", replace=True)
  File "/home/majid/.local/lib/python3.10/site-packages/nornir/core/task.py", line 174, in run
    raise NornirSubTaskError(task=run_task, result=r)
nornir.core.exceptions.NornirSubTaskError: Subtask: napalm_configure (failed)


2022-06-16 01:48:44,887 -  nornir.core -     INFO -        run() - Running task 'netmiko_send_config_from_file_exmaple' with args {} on 1 hosts
2022-06-16 01:48:47,448 -  nornir.core -     INFO -        run() - Running task 'netmiko_save_config_exmaple' with args {} on 1 hosts
2022-06-16 01:49:25,720 -  nornir.core -     INFO -        run() - Running task 'netmiko_send_config_from_file_exmaple' with args {} on 1 hosts
2022-06-16 01:49:26,956 -  nornir.core -     INFO -        run() - Running task 'netmiko_save_config_exmaple' with args {} on 1 hosts
2022-06-16 02:26:00,090 -  nornir.core -     INFO -        run() - Running task 'napalm_send_config_exmaple' with args {} on 1 hosts
2022-06-16 02:26:43,978 -  nornir.core -     INFO -        run() - Running task 'napalm_send_config_exmaple' with args {} on 1 hosts
2022-06-16 02:27:24,720 -  nornir.core -     INFO -        run() - Running task 'napalm_send_config_exmaple' with args {} on 1 hosts
2022-06-16 02:31:04,073 -  nornir.core -     INFO -        run() - Running task 'napalm_write_file_example' with args {} on 1 hosts
2022-06-16 02:32:01,464 -  nornir.core -     INFO -        run() - Running task 'napalm_send_config_exmaple' with args {} on 1 hosts
2022-06-16 02:32:03,687 - nornir.core.task -    ERROR -      start() - Host 'R1': task 'napalm_configure' failed with traceback:
Traceback (most recent call last):
  File "/home/majid/.local/lib/python3.10/site-packages/nornir/core/task.py", line 99, in start
    r = self.task(self, **self.params)
  File "/home/majid/.local/lib/python3.10/site-packages/nornir_napalm/plugins/tasks/napalm_configure.py", line 35, in napalm_configure
    device.load_merge_candidate(filename=filename, config=configuration)
  File "/home/majid/.local/lib/python3.10/site-packages/napalm/ios/ios.py", line 316, in load_merge_candidate
    return_status, msg = self._load_candidate_wrapper(
  File "/home/majid/.local/lib/python3.10/site-packages/napalm/ios/ios.py", line 283, in _load_candidate_wrapper
    (return_status, msg) = self._scp_file(
  File "/home/majid/.local/lib/python3.10/site-packages/napalm/ios/ios.py", line 626, in _scp_file
    return self._xfer_file(
  File "/home/majid/.local/lib/python3.10/site-packages/napalm/ios/ios.py", line 695, in _xfer_file
    raise CommandErrorException(msg)
napalm.base.exceptions.CommandErrorException: SCP file transfers are not enabled. Configure 'ip scp server enable' on the device.

2022-06-16 02:32:03,687 - nornir.core.task -    ERROR -      start() - Host 'R1': task 'napalm_send_config_exmaple' failed with traceback:
Traceback (most recent call last):
  File "/home/majid/.local/lib/python3.10/site-packages/nornir/core/task.py", line 99, in start
    r = self.task(self, **self.params)
  File "/home/majid/devnet/pyhton_nornir/6.3.nornir_napalm_send_config.py", line 9, in napalm_send_config_exmaple
    task.run(task=napalm_configure, filename="config_list")
  File "/home/majid/.local/lib/python3.10/site-packages/nornir/core/task.py", line 174, in run
    raise NornirSubTaskError(task=run_task, result=r)
nornir.core.exceptions.NornirSubTaskError: Subtask: napalm_configure (failed)


2022-06-16 02:32:39,247 -  nornir.core -     INFO -        run() - Running task 'napalm_send_config_exmaple' with args {} on 1 hosts
2022-06-16 02:33:58,962 -  nornir.core -     INFO -        run() - Running task 'napalm_send_config_exmaple' with args {} on 1 hosts
2022-06-16 02:34:47,270 -  nornir.core -     INFO -        run() - Running task 'napalm_send_config_exmaple' with args {} on 1 hosts
2022-06-16 02:34:50,482 - nornir.core.task -    ERROR -      start() - Host 'R1': task 'napalm_configure' failed with traceback:
Traceback (most recent call last):
  File "/home/majid/.local/lib/python3.10/site-packages/nornir/core/task.py", line 99, in start
    r = self.task(self, **self.params)
  File "/home/majid/.local/lib/python3.10/site-packages/nornir_napalm/plugins/tasks/napalm_configure.py", line 43, in napalm_configure
    device.commit_config()
  File "/home/majid/.local/lib/python3.10/site-packages/napalm/ios/ios.py", line 542, in commit_config
    raise ReplaceConfigException(msg)
napalm.base.exceptions.ReplaceConfigException: napalm-ios replace() requires Cisco 'archive' feature to be enabled.

2022-06-16 02:34:50,483 - nornir.core.task -    ERROR -      start() - Host 'R1': task 'napalm_send_config_exmaple' failed with traceback:
Traceback (most recent call last):
  File "/home/majid/.local/lib/python3.10/site-packages/nornir/core/task.py", line 99, in start
    r = self.task(self, **self.params)
  File "/home/majid/devnet/pyhton_nornir/6.5.nornir_napalm_send_config_replace.py", line 9, in napalm_send_config_exmaple
    task.run(task=napalm_configure, filename=f"{task.host}", replace=True)
  File "/home/majid/.local/lib/python3.10/site-packages/nornir/core/task.py", line 174, in run
    raise NornirSubTaskError(task=run_task, result=r)
nornir.core.exceptions.NornirSubTaskError: Subtask: napalm_configure (failed)


2022-06-16 02:35:39,029 -  nornir.core -     INFO -        run() - Running task 'napalm_send_config_exmaple' with args {} on 1 hosts
2022-06-16 02:36:40,409 -  nornir.core -     INFO -        run() - Running task 'napalm_send_config_exmaple' with args {} on 1 hosts
2022-06-16 02:36:44,296 - nornir.core.task -    ERROR -      start() - Host 'R1': task 'napalm_configure' failed with traceback:
Traceback (most recent call last):
  File "/home/majid/.local/lib/python3.10/site-packages/nornir/core/task.py", line 99, in start
    r = self.task(self, **self.params)
  File "/home/majid/.local/lib/python3.10/site-packages/nornir_napalm/plugins/tasks/napalm_configure.py", line 43, in napalm_configure
    device.commit_config()
  File "/home/majid/.local/lib/python3.10/site-packages/napalm/ios/ios.py", line 539, in commit_config
    raise ReplaceConfigException(msg)
napalm.base.exceptions.ReplaceConfigException: Candidate config could not be applied

%The input file is not a valid config file.


2022-06-16 02:36:44,298 - nornir.core.task -    ERROR -      start() - Host 'R1': task 'napalm_send_config_exmaple' failed with traceback:
Traceback (most recent call last):
  File "/home/majid/.local/lib/python3.10/site-packages/nornir/core/task.py", line 99, in start
    r = self.task(self, **self.params)
  File "/home/majid/devnet/pyhton_nornir/6.3.nornir_napalm_send_config.py", line 9, in napalm_send_config_exmaple
    task.run(task=napalm_configure, filename="config_list", replace=True)
  File "/home/majid/.local/lib/python3.10/site-packages/nornir/core/task.py", line 174, in run
    raise NornirSubTaskError(task=run_task, result=r)
nornir.core.exceptions.NornirSubTaskError: Subtask: napalm_configure (failed)


2022-06-16 02:37:53,643 -  nornir.core -     INFO -        run() - Running task 'napalm_send_config_exmaple' with args {} on 1 hosts
2022-06-17 00:02:55,667 -  nornir.core -     INFO -        run() - Running task 'netmiko_send_commands_example' with args {} on 1 hosts
2022-06-17 00:02:55,994 - nornir.core.task -    ERROR -      start() - Host 'R1': task 'netmiko_send_command' failed with traceback:
Traceback (most recent call last):
  File "/home/majid/.local/lib/python3.10/site-packages/nornir/core/task.py", line 99, in start
    r = self.task(self, **self.params)
  File "/home/majid/.local/lib/python3.10/site-packages/nornir_netmiko/tasks/netmiko_send_command.py", line 26, in netmiko_send_command
    net_connect = task.host.get_connection(CONNECTION_NAME, task.nornir.config)
  File "/home/majid/.local/lib/python3.10/site-packages/nornir/core/inventory.py", line 494, in get_connection
    self.open_connection(
  File "/home/majid/.local/lib/python3.10/site-packages/nornir/core/inventory.py", line 546, in open_connection
    conn_obj.open(
  File "/home/majid/.local/lib/python3.10/site-packages/nornir_netmiko/connections/netmiko.py", line 59, in open
    connection = ConnectHandler(**parameters)
  File "/home/majid/.local/lib/python3.10/site-packages/netmiko/ssh_dispatcher.py", line 326, in ConnectHandler
    return ConnectionClass(*args, **kwargs)
  File "/home/majid/.local/lib/python3.10/site-packages/netmiko/cisco/cisco_ios.py", line 17, in __init__
    return super().__init__(*args, **kwargs)
  File "/home/majid/.local/lib/python3.10/site-packages/netmiko/base_connection.py", line 350, in __init__
    self._open()
  File "/home/majid/.local/lib/python3.10/site-packages/netmiko/base_connection.py", line 355, in _open
    self.establish_connection()
  File "/home/majid/.local/lib/python3.10/site-packages/netmiko/base_connection.py", line 935, in establish_connection
    self.remote_conn_pre.connect(**ssh_connect_params)
  File "/home/majid/.local/lib/python3.10/site-packages/paramiko/client.py", line 435, in connect
    self._auth(
  File "/home/majid/.local/lib/python3.10/site-packages/paramiko/client.py", line 767, in _auth
    raise SSHException("No authentication methods available")
paramiko.ssh_exception.SSHException: No authentication methods available

2022-06-17 00:02:55,995 - nornir.core.task -    ERROR -      start() - Host 'R1': task 'netmiko_send_commands_example' failed with traceback:
Traceback (most recent call last):
  File "/home/majid/.local/lib/python3.10/site-packages/nornir/core/task.py", line 99, in start
    r = self.task(self, **self.params)
  File "/home/majid/devnet/pyhton_nornir/7.nornir_publick_key_authentication.py", line 8, in netmiko_send_commands_example
    task.run(task=netmiko_send_command, command_string="show ip int brief | exc unass")
  File "/home/majid/.local/lib/python3.10/site-packages/nornir/core/task.py", line 174, in run
    raise NornirSubTaskError(task=run_task, result=r)
nornir.core.exceptions.NornirSubTaskError: Subtask: netmiko_send_command (failed)


2022-06-17 00:03:22,676 -  nornir.core -     INFO -        run() - Running task 'netmiko_send_commands_example' with args {} on 1 hosts
2022-06-17 00:09:48,859 -  nornir.core -     INFO -        run() - Running task 'netmiko_send_commands_example' with args {} on 1 hosts
2022-06-17 00:09:49,357 - nornir.core.task -    ERROR -      start() - Host 'R1': task 'netmiko_send_command' failed with traceback:
Traceback (most recent call last):
  File "/home/majid/.local/lib/python3.10/site-packages/nornir/core/task.py", line 99, in start
    r = self.task(self, **self.params)
  File "/home/majid/.local/lib/python3.10/site-packages/nornir_netmiko/tasks/netmiko_send_command.py", line 26, in netmiko_send_command
    net_connect = task.host.get_connection(CONNECTION_NAME, task.nornir.config)
  File "/home/majid/.local/lib/python3.10/site-packages/nornir/core/inventory.py", line 494, in get_connection
    self.open_connection(
  File "/home/majid/.local/lib/python3.10/site-packages/nornir/core/inventory.py", line 546, in open_connection
    conn_obj.open(
  File "/home/majid/.local/lib/python3.10/site-packages/nornir_netmiko/connections/netmiko.py", line 59, in open
    connection = ConnectHandler(**parameters)
  File "/home/majid/.local/lib/python3.10/site-packages/netmiko/ssh_dispatcher.py", line 326, in ConnectHandler
    return ConnectionClass(*args, **kwargs)
  File "/home/majid/.local/lib/python3.10/site-packages/netmiko/cisco/cisco_ios.py", line 17, in __init__
    return super().__init__(*args, **kwargs)
  File "/home/majid/.local/lib/python3.10/site-packages/netmiko/base_connection.py", line 350, in __init__
    self._open()
  File "/home/majid/.local/lib/python3.10/site-packages/netmiko/base_connection.py", line 355, in _open
    self.establish_connection()
  File "/home/majid/.local/lib/python3.10/site-packages/netmiko/base_connection.py", line 935, in establish_connection
    self.remote_conn_pre.connect(**ssh_connect_params)
  File "/home/majid/.local/lib/python3.10/site-packages/paramiko/client.py", line 435, in connect
    self._auth(
  File "/home/majid/.local/lib/python3.10/site-packages/paramiko/client.py", line 753, in _auth
    self._transport.auth_password(username, password)
  File "/home/majid/.local/lib/python3.10/site-packages/paramiko/transport.py", line 1564, in auth_password
    return self.auth_handler.wait_for_response(my_event)
  File "/home/majid/.local/lib/python3.10/site-packages/paramiko/auth_handler.py", line 245, in wait_for_response
    raise e
  File "/home/majid/.local/lib/python3.10/site-packages/paramiko/transport.py", line 2164, in run
    handler(self.auth_handler, m)
  File "/home/majid/.local/lib/python3.10/site-packages/paramiko/auth_handler.py", line 381, in _parse_service_accept
    password = b(self.password)
  File "/home/majid/.local/lib/python3.10/site-packages/paramiko/py3compat.py", line 156, in b
    raise TypeError("Expected unicode or bytes, got {!r}".format(s))
TypeError: Expected unicode or bytes, got <function unix_getpass at 0x7f2a2671bbe0>

2022-06-17 00:09:49,358 - nornir.core.task -    ERROR -      start() - Host 'R1': task 'netmiko_send_commands_example' failed with traceback:
Traceback (most recent call last):
  File "/home/majid/.local/lib/python3.10/site-packages/nornir/core/task.py", line 99, in start
    r = self.task(self, **self.params)
  File "/home/majid/devnet/pyhton_nornir/7.get_password_by_getpass.py", line 10, in netmiko_send_commands_example
    task.run(task=netmiko_send_command, command_string="show ip int brief | exc unass")
  File "/home/majid/.local/lib/python3.10/site-packages/nornir/core/task.py", line 174, in run
    raise NornirSubTaskError(task=run_task, result=r)
nornir.core.exceptions.NornirSubTaskError: Subtask: netmiko_send_command (failed)


2022-06-17 00:10:14,551 -  nornir.core -     INFO -        run() - Running task 'netmiko_send_commands_example' with args {} on 1 hosts
2022-06-17 00:10:15,054 - nornir.core.task -    ERROR -      start() - Host 'R1': task 'netmiko_send_command' failed with traceback:
Traceback (most recent call last):
  File "/home/majid/.local/lib/python3.10/site-packages/nornir/core/task.py", line 99, in start
    r = self.task(self, **self.params)
  File "/home/majid/.local/lib/python3.10/site-packages/nornir_netmiko/tasks/netmiko_send_command.py", line 26, in netmiko_send_command
    net_connect = task.host.get_connection(CONNECTION_NAME, task.nornir.config)
  File "/home/majid/.local/lib/python3.10/site-packages/nornir/core/inventory.py", line 494, in get_connection
    self.open_connection(
  File "/home/majid/.local/lib/python3.10/site-packages/nornir/core/inventory.py", line 546, in open_connection
    conn_obj.open(
  File "/home/majid/.local/lib/python3.10/site-packages/nornir_netmiko/connections/netmiko.py", line 59, in open
    connection = ConnectHandler(**parameters)
  File "/home/majid/.local/lib/python3.10/site-packages/netmiko/ssh_dispatcher.py", line 326, in ConnectHandler
    return ConnectionClass(*args, **kwargs)
  File "/home/majid/.local/lib/python3.10/site-packages/netmiko/cisco/cisco_ios.py", line 17, in __init__
    return super().__init__(*args, **kwargs)
  File "/home/majid/.local/lib/python3.10/site-packages/netmiko/base_connection.py", line 350, in __init__
    self._open()
  File "/home/majid/.local/lib/python3.10/site-packages/netmiko/base_connection.py", line 355, in _open
    self.establish_connection()
  File "/home/majid/.local/lib/python3.10/site-packages/netmiko/base_connection.py", line 935, in establish_connection
    self.remote_conn_pre.connect(**ssh_connect_params)
  File "/home/majid/.local/lib/python3.10/site-packages/paramiko/client.py", line 435, in connect
    self._auth(
  File "/home/majid/.local/lib/python3.10/site-packages/paramiko/client.py", line 753, in _auth
    self._transport.auth_password(username, password)
  File "/home/majid/.local/lib/python3.10/site-packages/paramiko/transport.py", line 1564, in auth_password
    return self.auth_handler.wait_for_response(my_event)
  File "/home/majid/.local/lib/python3.10/site-packages/paramiko/auth_handler.py", line 245, in wait_for_response
    raise e
  File "/home/majid/.local/lib/python3.10/site-packages/paramiko/transport.py", line 2164, in run
    handler(self.auth_handler, m)
  File "/home/majid/.local/lib/python3.10/site-packages/paramiko/auth_handler.py", line 381, in _parse_service_accept
    password = b(self.password)
  File "/home/majid/.local/lib/python3.10/site-packages/paramiko/py3compat.py", line 156, in b
    raise TypeError("Expected unicode or bytes, got {!r}".format(s))
TypeError: Expected unicode or bytes, got <function unix_getpass at 0x7ffb37b5bbe0>

2022-06-17 00:10:15,054 - nornir.core.task -    ERROR -      start() - Host 'R1': task 'netmiko_send_commands_example' failed with traceback:
Traceback (most recent call last):
  File "/home/majid/.local/lib/python3.10/site-packages/nornir/core/task.py", line 99, in start
    r = self.task(self, **self.params)
  File "/home/majid/devnet/pyhton_nornir/7.get_password_by_getpass.py", line 10, in netmiko_send_commands_example
    task.run(task=netmiko_send_command, command_string="show ip int brief | exc unass")
  File "/home/majid/.local/lib/python3.10/site-packages/nornir/core/task.py", line 174, in run
    raise NornirSubTaskError(task=run_task, result=r)
nornir.core.exceptions.NornirSubTaskError: Subtask: netmiko_send_command (failed)


2022-06-17 00:10:32,980 -  nornir.core -     INFO -        run() - Running task 'netmiko_send_commands_example' with args {} on 1 hosts
2022-06-17 00:37:53,372 -  nornir.core -     INFO -        run() - Running task 'netmiko_send_commands_example' with args {} on 1 hosts
2022-06-17 00:48:10,595 -  nornir.core -     INFO -        run() - Running task 'netmiko_send_commands_example' with args {} on 1 hosts
2022-06-17 01:18:58,146 -  nornir.core -     INFO -        run() - Running task 'netmiko_send_commands_example' with args {} on 1 hosts
2022-06-17 01:57:37,624 -  nornir.core -     INFO -        run() - Running task 'netmiko_send_commands_example' with args {} on 1 hosts
2022-06-17 01:59:02,807 -  nornir.core -     INFO -        run() - Running task 'netmiko_send_commands_example' with args {} on 1 hosts
2022-06-17 02:01:07,822 -  nornir.core -     INFO -        run() - Running task 'netmiko_send_commands_example' with args {} on 1 hosts
2022-06-17 02:08:25,281 -  nornir.core -     INFO -        run() - Running task 'netmiko_send_commands_example' with args {} on 1 hosts
2022-06-17 02:08:42,727 -  nornir.core -     INFO -        run() - Running task 'netmiko_send_commands_example' with args {} on 1 hosts
